Workbook

Sheet Resultado consolidado
A1: Item | B1: Descrição | C1: 46235 | D1: 46266 | E1: 46296 | F1: 46327 | G1: 46357 | H1: 46388 | I1: 46419 | J1: 46447 | K1: 46478 | L1: 46508 | M1: 46539 | N1: 46569 | O1: 46600 | P1: 46631 | Q1: 46661 | R1: 46692 | S1: 46722 | T1: Total Acumulado Ano 1 | U1: 46753 | V1: 46784 | W1: 46813 | X1: 46844 | Y1: 46874 | Z1: 46905 | AA1: 46935 | AB1: 46966 | AC1: 46997 | AD1: 47027 | AE1: 47058 | AF1: 47088 | AG1: Total Acumulado Ano 2 | AH1: 47119 | AI1: 47150 | AJ1: 47178 | AK1: 47209 | AL1: 47239 | AM1: 47270 | AN1: 47300 | AO1: 47331 | AP1: 47362 | AQ1: 47392 | AR1: 47423 | AS1: 47453 | AT1: Total Acumulado Ano 3 | AU1: 47484 | AV1: 47515 | AW1: 47543 | AX1: 47574 | AY1: 47604 | AZ1: 47635 | BA1: 47665 | BB1: 47696 | BC1: 47727 | BD1: 47757 | BE1: 47788 | BF1: 47818 | BG1: Total Acumulado Ano 4 | BH1: 47849 | BI1: 47880 | BJ1: 47908 | BK1: 47939 | BL1: 47969 | BM1: 48000 | BN1: 48030 | BO1: 48061 | BP1: 48092 | BQ1: 48122 | BR1: 48153 | BS1: 48183 | BT1: Total Acumulado Ano 5 | BU1: 48214 | BV1: 48245 | BW1: 48274 | BX1: 48305 | BY1: 48335 | BZ1: 48366 | CA1: 48396 | CB1: 48427 | CC1: 48458 | CD1: 48488 | CE1: 48519 | CF1: 48549 | CG1: Total Acumulado Ano 6 | CH1: 48580 | CI1: 48611 | CJ1: 48639 | CK1: 48670 | CL1: 48700 | CM1: 48731 | CN1: 48761 | CO1: 48792 | CP1: 48823 | CQ1: 48853 | CR1: 48884 | CS1: 48914 | CT1: Total Acumulado Ano 7 | CU1: 48945 | CV1: 48976 | CW1: 49004 | CX1: 49035 | CY1: 49065 | CZ1: 49096 | DA1: 49126 | DB1: 49157 | DC1: 49188 | DD1: 49218 | DE1: 49249 | DF1: 49279 | DG1: Total Acumulado Ano 8 | DH1: Total acumulado pós custo capital
B2: Receita total | C2: =IFERROR(INDEX([1]Orçamento!$C$2:$ZZ$2,1,MATCH(C$1,[1]Orçamento!$C$1:$ZZ$1,0)),0) + IFERROR(INDEX([2]Orçamento!$C$2:$ZZ$2,1,MATCH(C$1,[2]Orçamento!$C$1:$ZZ$1,0)),0) + IFERROR(INDEX([3]Orçamento!$C$2:$ZZ$2,1,MATCH(C$1,[3]Orçamento!$C$1:$ZZ$1,0)),0) + IFERROR(INDEX([4]Orçamento!$C$2:$ZZ$2,1,MATCH(C$1,[4]Orçamento!$C$1:$ZZ$1,0)),0) + IFERROR(INDEX([5]Orçamento!$C$2:$ZZ$2,1,MATCH(C$1,[5]Orçamento!$C$1:$ZZ$1,0)),0) + IFERROR(INDEX([6]Orçamento!$C$2:$ZZ$2,1,MATCH(C$1,[6]Orçamento!$C$1:$ZZ$1,0)),0) + IFERROR(INDEX([7]Orçamento!$C$2:$ZZ$2,1,MATCH(C$1,[7]Orçamento!$C$1:$ZZ$1,0)),0) + IFERROR(INDEX([8]Orçamento!$C$2:$ZZ$2,1,MATCH(C$1,[8]Orçamento!$C$1:$ZZ$1,0)),0) -> 0 | D2: =IFERROR(INDEX([1]Orçamento!$C$2:$ZZ$2,1,MATCH(D$1,[1]Orçamento!$C$1:$ZZ$1,0)),0) + IFERROR(INDEX([2]Orçamento!$C$2:$ZZ$2,1,MATCH(D$1,[2]Orçamento!$C$1:$ZZ$1,0)),0) + IFERROR(INDEX([3]Orçamento!$C$2:$ZZ$2,1,MATCH(D$1,[3]Orçamento!$C$1:$ZZ$1,0)),0) + IFERROR(INDEX([4]Orçamento!$C$2:$ZZ$2,1,MATCH(D$1,[4]Orçamento!$C$1:$ZZ$1,0)),0) + IFERROR(INDEX([5]Orçamento!$C$2:$ZZ$2,1,MATCH(D$1,[5]Orçamento!$C$1:$ZZ$1,0)),0) + IFERROR(INDEX([6]Orçamento!$C$2:$ZZ$2,1,MATCH(D$1,[6]Orçamento!$C$1:$ZZ$1,0)),0) + IFERROR(INDEX([7]Orçamento!$C$2:$ZZ$2,1,MATCH(D$1,[7]Orçamento!$C$1:$ZZ$1,0)),0) + IFERROR(INDEX([8]Orçamento!$C$2:$ZZ$2,1,MATCH(D$1,[8]Orçamento!$C$1:$ZZ$1,0)),0) -> 0 | E2: =IFERROR(INDEX([1]Orçamento!$C$2:$ZZ$2,1,MATCH(E$1,[1]Orçamento!$C$1:$ZZ$1,0)),0) + IFERROR(INDEX([2]Orçamento!$C$2:$ZZ$2,1,MATCH(E$1,[2]Orçamento!$C$1:$ZZ$1,0)),0) + IFERROR(INDEX([3]Orçamento!$C$2:$ZZ$2,1,MATCH(E$1,[3]Orçamento!$C$1:$ZZ$1,0)),0) + IFERROR(INDEX([4]Orçamento!$C$2:$ZZ$2,1,MATCH(E$1,[4]Orçamento!$C$1:$ZZ$1,0)),0) + IFERROR(INDEX([5]Orçamento!$C$2:$ZZ$2,1,MATCH(E$1,[5]Orçamento!$C$1:$ZZ$1,0)),0) + IFERROR(INDEX([6]Orçamento!$C$2:$ZZ$2,1,MATCH(E$1,[6]Orçamento!$C$1:$ZZ$1,0)),0) + IFERROR(INDEX([7]Orçamento!$C$2:$ZZ$2,1,MATCH(E$1,[7]Orçamento!$C$1:$ZZ$1,0)),0) + IFERROR(INDEX([8]Orçamento!$C$2:$ZZ$2,1,MATCH(E$1,[8]Orçamento!$C$1:$ZZ$1,0)),0) -> 0 | F2: =IFERROR(INDEX([1]Orçamento!$C$2:$ZZ$2,1,MATCH(F$1,[1]Orçamento!$C$1:$ZZ$1,0)),0) + IFERROR(INDEX([2]Orçamento!$C$2:$ZZ$2,1,MATCH(F$1,[2]Orçamento!$C$1:$ZZ$1,0)),0) + IFERROR(INDEX([3]Orçamento!$C$2:$ZZ$2,1,MATCH(F$1,[3]Orçamento!$C$1:$ZZ$1,0)),0) + IFERROR(INDEX([4]Orçamento!$C$2:$ZZ$2,1,MATCH(F$1,[4]Orçamento!$C$1:$ZZ$1,0)),0) + IFERROR(INDEX([5]Orçamento!$C$2:$ZZ$2,1,MATCH(F$1,[5]Orçamento!$C$1:$ZZ$1,0)),0) + IFERROR(INDEX([6]Orçamento!$C$2:$ZZ$2,1,MATCH(F$1,[6]Orçamento!$C$1:$ZZ$1,0)),0) + IFERROR(INDEX([7]Orçamento!$C$2:$ZZ$2,1,MATCH(F$1,[7]Orçamento!$C$1:$ZZ$1,0)),0) + IFERROR(INDEX([8]Orçamento!$C$2:$ZZ$2,1,MATCH(F$1,[8]Orçamento!$C$1:$ZZ$1,0)),0) -> 2453.8125 | G2: =IFERROR(INDEX([1]Orçamento!$C$2:$ZZ$2,1,MATCH(G$1,[1]Orçamento!$C$1:$ZZ$1,0)),0) + IFERROR(INDEX([2]Orçamento!$C$2:$ZZ$2,1,MATCH(G$1,[2]Orçamento!$C$1:$ZZ$1,0)),0) + IFERROR(INDEX([3]Orçamento!$C$2:$ZZ$2,1,MATCH(G$1,[3]Orçamento!$C$1:$ZZ$1,0)),0) + IFERROR(INDEX([4]Orçamento!$C$2:$ZZ$2,1,MATCH(G$1,[4]Orçamento!$C$1:$ZZ$1,0)),0) + IFERROR(INDEX([5]Orçamento!$C$2:$ZZ$2,1,MATCH(G$1,[5]Orçamento!$C$1:$ZZ$1,0)),0) + IFERROR(INDEX([6]Orçamento!$C$2:$ZZ$2,1,MATCH(G$1,[6]Orçamento!$C$1:$ZZ$1,0)),0) + IFERROR(INDEX([7]Orçamento!$C$2:$ZZ$2,1,MATCH(G$1,[7]Orçamento!$C$1:$ZZ$1,0)),0) + IFERROR(INDEX([8]Orçamento!$C$2:$ZZ$2,1,MATCH(G$1,[8]Orçamento!$C$1:$ZZ$1,0)),0) -> 4907.625 | H2: =IFERROR(INDEX([1]Orçamento!$C$2:$ZZ$2,1,MATCH(H$1,[1]Orçamento!$C$1:$ZZ$1,0)),0) + IFERROR(INDEX([2]Orçamento!$C$2:$ZZ$2,1,MATCH(H$1,[2]Orçamento!$C$1:$ZZ$1,0)),0) + IFERROR(INDEX([3]Orçamento!$C$2:$ZZ$2,1,MATCH(H$1,[3]Orçamento!$C$1:$ZZ$1,0)),0) + IFERROR(INDEX([4]Orçamento!$C$2:$ZZ$2,1,MATCH(H$1,[4]Orçamento!$C$1:$ZZ$1,0)),0) + IFERROR(INDEX([5]Orçamento!$C$2:$ZZ$2,1,MATCH(H$1,[5]Orçamento!$C$1:$ZZ$1,0)),0) + IFERROR(INDEX([6]Orçamento!$C$2:$ZZ$2,1,MATCH(H$1,[6]Orçamento!$C$1:$ZZ$1,0)),0) + IFERROR(INDEX([7]Orçamento!$C$2:$ZZ$2,1,MATCH(H$1,[7]Orçamento!$C$1:$ZZ$1,0)),0) + IFERROR(INDEX([8]Orçamento!$C$2:$ZZ$2,1,MATCH(H$1,[8]Orçamento!$C$1:$ZZ$1,0)),0) -> 26432.75 | I2: =IFERROR(INDEX([1]Orçamento!$C$2:$ZZ$2,1,MATCH(I$1,[1]Orçamento!$C$1:$ZZ$1,0)),0) + IFERROR(INDEX([2]Orçamento!$C$2:$ZZ$2,1,MATCH(I$1,[2]Orçamento!$C$1:$ZZ$1,0)),0) + IFERROR(INDEX([3]Orçamento!$C$2:$ZZ$2,1,MATCH(I$1,[3]Orçamento!$C$1:$ZZ$1,0)),0) + IFERROR(INDEX([4]Orçamento!$C$2:$ZZ$2,1,MATCH(I$1,[4]Orçamento!$C$1:$ZZ$1,0)),0) + IFERROR(INDEX([5]Orçamento!$C$2:$ZZ$2,1,MATCH(I$1,[5]Orçamento!$C$1:$ZZ$1,0)),0) + IFERROR(INDEX([6]Orçamento!$C$2:$ZZ$2,1,MATCH(I$1,[6]Orçamento!$C$1:$ZZ$1,0)),0) + IFERROR(INDEX([7]Orçamento!$C$2:$ZZ$2,1,MATCH(I$1,[7]Orçamento!$C$1:$ZZ$1,0)),0) + IFERROR(INDEX([8]Orçamento!$C$2:$ZZ$2,1,MATCH(I$1,[8]Orçamento!$C$1:$ZZ$1,0)),0) -> 26432.75 | J2: =IFERROR(INDEX([1]Orçamento!$C$2:$ZZ$2,1,MATCH(J$1,[1]Orçamento!$C$1:$ZZ$1,0)),0) + IFERROR(INDEX([2]Orçamento!$C$2:$ZZ$2,1,MATCH(J$1,[2]Orçamento!$C$1:$ZZ$1,0)),0) + IFERROR(INDEX([3]Orçamento!$C$2:$ZZ$2,1,MATCH(J$1,[3]Orçamento!$C$1:$ZZ$1,0)),0) + IFERROR(INDEX([4]Orçamento!$C$2:$ZZ$2,1,MATCH(J$1,[4]Orçamento!$C$1:$ZZ$1,0)),0) + IFERROR(INDEX([5]Orçamento!$C$2:$ZZ$2,1,MATCH(J$1,[5]Orçamento!$C$1:$ZZ$1,0)),0) + IFERROR(INDEX([6]Orçamento!$C$2:$ZZ$2,1,MATCH(J$1,[6]Orçamento!$C$1:$ZZ$1,0)),0) + IFERROR(INDEX([7]Orçamento!$C$2:$ZZ$2,1,MATCH(J$1,[7]Orçamento!$C$1:$ZZ$1,0)),0) + IFERROR(INDEX([8]Orçamento!$C$2:$ZZ$2,1,MATCH(J$1,[8]Orçamento!$C$1:$ZZ$1,0)),0) -> 26432.75 | ... S2: =IFERROR(INDEX([1]Orçamento!$C$2:$ZZ$2,1,MATCH(S$1,[1]Orçamento!$C$1:$ZZ$1,0)),0) + IFERROR(INDEX([2]Orçamento!$C$2:$ZZ$2,1,MATCH(S$1,[2]Orçamento!$C$1:$ZZ$1,0)),0) + IFERROR(INDEX([3]Orçamento!$C$2:$ZZ$2,1,MATCH(S$1,[3]Orçamento!$C$1:$ZZ$1,0)),0) + IFERROR(INDEX([4]Orçamento!$C$2:$ZZ$2,1,MATCH(S$1,[4]Orçamento!$C$1:$ZZ$1,0)),0) + IFERROR(INDEX([5]Orçamento!$C$2:$ZZ$2,1,MATCH(S$1,[5]Orçamento!$C$1:$ZZ$1,0)),0) + IFERROR(INDEX([6]Orçamento!$C$2:$ZZ$2,1,MATCH(S$1,[6]Orçamento!$C$1:$ZZ$1,0)),0) + IFERROR(INDEX([7]Orçamento!$C$2:$ZZ$2,1,MATCH(S$1,[7]Orçamento!$C$1:$ZZ$1,0)),0) + IFERROR(INDEX([8]Orçamento!$C$2:$ZZ$2,1,MATCH(S$1,[8]Orçamento!$C$1:$ZZ$1,0)),0) -> 26432.75 | T2: =SUM(C2:S2) -> 324554.44 | U2: =IFERROR(INDEX([1]Orçamento!$C$2:$ZZ$2,1,MATCH(U$1,[1]Orçamento!$C$1:$ZZ$1,0)),0) + IFERROR(INDEX([2]Orçamento!$C$2:$ZZ$2,1,MATCH(U$1,[2]Orçamento!$C$1:$ZZ$1,0)),0) + IFERROR(INDEX([3]Orçamento!$C$2:$ZZ$2,1,MATCH(U$1,[3]Orçamento!$C$1:$ZZ$1,0)),0) + IFERROR(INDEX([4]Orçamento!$C$2:$ZZ$2,1,MATCH(U$1,[4]Orçamento!$C$1:$ZZ$1,0)),0) + IFERROR(INDEX([5]Orçamento!$C$2:$ZZ$2,1,MATCH(U$1,[5]Orçamento!$C$1:$ZZ$1,0)),0) + IFERROR(INDEX([6]Orçamento!$C$2:$ZZ$2,1,MATCH(U$1,[6]Orçamento!$C$1:$ZZ$1,0)),0) + IFERROR(INDEX([7]Orçamento!$C$2:$ZZ$2,1,MATCH(U$1,[7]Orçamento!$C$1:$ZZ$1,0)),0) + IFERROR(INDEX([8]Orçamento!$C$2:$ZZ$2,1,MATCH(U$1,[8]Orçamento!$C$1:$ZZ$1,0)),0) -> 55271.875 | V2: =IFERROR(INDEX([1]Orçamento!$C$2:$ZZ$2,1,MATCH(V$1,[1]Orçamento!$C$1:$ZZ$1,0)),0) + IFERROR(INDEX([2]Orçamento!$C$2:$ZZ$2,1,MATCH(V$1,[2]Orçamento!$C$1:$ZZ$1,0)),0) + IFERROR(INDEX([3]Orçamento!$C$2:$ZZ$2,1,MATCH(V$1,[3]Orçamento!$C$1:$ZZ$1,0)),0) + IFERROR(INDEX([4]Orçamento!$C$2:$ZZ$2,1,MATCH(V$1,[4]Orçamento!$C$1:$ZZ$1,0)),0) + IFERROR(INDEX([5]Orçamento!$C$2:$ZZ$2,1,MATCH(V$1,[5]Orçamento!$C$1:$ZZ$1,0)),0) + IFERROR(INDEX([6]Orçamento!$C$2:$ZZ$2,1,MATCH(V$1,[6]Orçamento!$C$1:$ZZ$1,0)),0) + IFERROR(INDEX([7]Orçamento!$C$2:$ZZ$2,1,MATCH(V$1,[7]Orçamento!$C$1:$ZZ$1,0)),0) + IFERROR(INDEX([8]Orçamento!$C$2:$ZZ$2,1,MATCH(V$1,[8]Orçamento!$C$1:$ZZ$1,0)),0) -> 55271.875 | W2: =IFERROR(INDEX([1]Orçamento!$C$2:$ZZ$2,1,MATCH(W$1,[1]Orçamento!$C$1:$ZZ$1,0)),0) + IFERROR(INDEX([2]Orçamento!$C$2:$ZZ$2,1,MATCH(W$1,[2]Orçamento!$C$1:$ZZ$1,0)),0) + IFERROR(INDEX([3]Orçamento!$C$2:$ZZ$2,1,MATCH(W$1,[3]Orçamento!$C$1:$ZZ$1,0)),0) + IFERROR(INDEX([4]Orçamento!$C$2:$ZZ$2,1,MATCH(W$1,[4]Orçamento!$C$1:$ZZ$1,0)),0) + IFERROR(INDEX([5]Orçamento!$C$2:$ZZ$2,1,MATCH(W$1,[5]Orçamento!$C$1:$ZZ$1,0)),0) + IFERROR(INDEX([6]Orçamento!$C$2:$ZZ$2,1,MATCH(W$1,[6]Orçamento!$C$1:$ZZ$1,0)),0) + IFERROR(INDEX([7]Orçamento!$C$2:$ZZ$2,1,MATCH(W$1,[7]Orçamento!$C$1:$ZZ$1,0)),0) + IFERROR(INDEX([8]Orçamento!$C$2:$ZZ$2,1,MATCH(W$1,[8]Orçamento!$C$1:$ZZ$1,0)),0) -> 55271.875 | X2: =IFERROR(INDEX([1]Orçamento!$C$2:$ZZ$2,1,MATCH(X$1,[1]Orçamento!$C$1:$ZZ$1,0)),0) + IFERROR(INDEX([2]Orçamento!$C$2:$ZZ$2,1,MATCH(X$1,[2]Orçamento!$C$1:$ZZ$1,0)),0) + IFERROR(INDEX([3]Orçamento!$C$2:$ZZ$2,1,MATCH(X$1,[3]Orçamento!$C$1:$ZZ$1,0)),0) + IFERROR(INDEX([4]Orçamento!$C$2:$ZZ$2,1,MATCH(X$1,[4]Orçamento!$C$1:$ZZ$1,0)),0) + IFERROR(INDEX([5]Orçamento!$C$2:$ZZ$2,1,MATCH(X$1,[5]Orçamento!$C$1:$ZZ$1,0)),0) + IFERROR(INDEX([6]Orçamento!$C$2:$ZZ$2,1,MATCH(X$1,[6]Orçamento!$C$1:$ZZ$1,0)),0) + IFERROR(INDEX([7]Orçamento!$C$2:$ZZ$2,1,MATCH(X$1,[7]Orçamento!$C$1:$ZZ$1,0)),0) + IFERROR(INDEX([8]Orçamento!$C$2:$ZZ$2,1,MATCH(X$1,[8]Orçamento!$C$1:$ZZ$1,0)),0) -> 57725.687 | Y2: =IFERROR(INDEX([1]Orçamento!$C$2:$ZZ$2,1,MATCH(Y$1,[1]Orçamento!$C$1:$ZZ$1,0)),0) + IFERROR(INDEX([2]Orçamento!$C$2:$ZZ$2,1,MATCH(Y$1,[2]Orçamento!$C$1:$ZZ$1,0)),0) + IFERROR(INDEX([3]Orçamento!$C$2:$ZZ$2,1,MATCH(Y$1,[3]Orçamento!$C$1:$ZZ$1,0)),0) + IFERROR(INDEX([4]Orçamento!$C$2:$ZZ$2,1,MATCH(Y$1,[4]Orçamento!$C$1:$ZZ$1,0)),0) + IFERROR(INDEX([5]Orçamento!$C$2:$ZZ$2,1,MATCH(Y$1,[5]Orçamento!$C$1:$ZZ$1,0)),0) + IFERROR(INDEX([6]Orçamento!$C$2:$ZZ$2,1,MATCH(Y$1,[6]Orçamento!$C$1:$ZZ$1,0)),0) + IFERROR(INDEX([7]Orçamento!$C$2:$ZZ$2,1,MATCH(Y$1,[7]Orçamento!$C$1:$ZZ$1,0)),0) + IFERROR(INDEX([8]Orçamento!$C$2:$ZZ$2,1,MATCH(Y$1,[8]Orçamento!$C$1:$ZZ$1,0)),0) -> 60179.5 | Z2: =IFERROR(INDEX([1]Orçamento!$C$2:$ZZ$2,1,MATCH(Z$1,[1]Orçamento!$C$1:$ZZ$1,0)),0) + IFERROR(INDEX([2]Orçamento!$C$2:$ZZ$2,1,MATCH(Z$1,[2]Orçamento!$C$1:$ZZ$1,0)),0) + IFERROR(INDEX([3]Orçamento!$C$2:$ZZ$2,1,MATCH(Z$1,[3]Orçamento!$C$1:$ZZ$1,0)),0) + IFERROR(INDEX([4]Orçamento!$C$2:$ZZ$2,1,MATCH(Z$1,[4]Orçamento!$C$1:$ZZ$1,0)),0) + IFERROR(INDEX([5]Orçamento!$C$2:$ZZ$2,1,MATCH(Z$1,[5]Orçamento!$C$1:$ZZ$1,0)),0) + IFERROR(INDEX([6]Orçamento!$C$2:$ZZ$2,1,MATCH(Z$1,[6]Orçamento!$C$1:$ZZ$1,0)),0) + IFERROR(INDEX([7]Orçamento!$C$2:$ZZ$2,1,MATCH(Z$1,[7]Orçamento!$C$1:$ZZ$1,0)),0) + IFERROR(INDEX([8]Orçamento!$C$2:$ZZ$2,1,MATCH(Z$1,[8]Orçamento!$C$1:$ZZ$1,0)),0) -> 81704.625 | AA2: =IFERROR(INDEX([1]Orçamento!$C$2:$ZZ$2,1,MATCH(AA$1,[1]Orçamento!$C$1:$ZZ$1,0)),0) + IFERROR(INDEX([2]Orçamento!$C$2:$ZZ$2,1,MATCH(AA$1,[2]Orçamento!$C$1:$ZZ$1,0)),0) + IFERROR(INDEX([3]Orçamento!$C$2:$ZZ$2,1,MATCH(AA$1,[3]Orçamento!$C$1:$ZZ$1,0)),0) + IFERROR(INDEX([4]Orçamento!$C$2:$ZZ$2,1,MATCH(AA$1,[4]Orçamento!$C$1:$ZZ$1,0)),0) + IFERROR(INDEX([5]Orçamento!$C$2:$ZZ$2,1,MATCH(AA$1,[5]Orçamento!$C$1:$ZZ$1,0)),0) + IFERROR(INDEX([6]Orçamento!$C$2:$ZZ$2,1,MATCH(AA$1,[6]Orçamento!$C$1:$ZZ$1,0)),0) + IFERROR(INDEX([7]Orçamento!$C$2:$ZZ$2,1,MATCH(AA$1,[7]Orçamento!$C$1:$ZZ$1,0)),0) + IFERROR(INDEX([8]Orçamento!$C$2:$ZZ$2,1,MATCH(AA$1,[8]Orçamento!$C$1:$ZZ$1,0)),0) -> 81704.625 | AB2: =IFERROR(INDEX([1]Orçamento!$C$2:$ZZ$2,1,MATCH(AB$1,[1]Orçamento!$C$1:$ZZ$1,0)),0) + IFERROR(INDEX([2]Orçamento!$C$2:$ZZ$2,1,MATCH(AB$1,[2]Orçamento!$C$1:$ZZ$1,0)),0) + IFERROR(INDEX([3]Orçamento!$C$2:$ZZ$2,1,MATCH(AB$1,[3]Orçamento!$C$1:$ZZ$1,0)),0) + IFERROR(INDEX([4]Orçamento!$C$2:$ZZ$2,1,MATCH(AB$1,[4]Orçamento!$C$1:$ZZ$1,0)),0) + IFERROR(INDEX([5]Orçamento!$C$2:$ZZ$2,1,MATCH(AB$1,[5]Orçamento!$C$1:$ZZ$1,0)),0) + IFERROR(INDEX([6]Orçamento!$C$2:$ZZ$2,1,MATCH(AB$1,[6]Orçamento!$C$1:$ZZ$1,0)),0) + IFERROR(INDEX([7]Orçamento!$C$2:$ZZ$2,1,MATCH(AB$1,[7]Orçamento!$C$1:$ZZ$1,0)),0) + IFERROR(INDEX([8]Orçamento!$C$2:$ZZ$2,1,MATCH(AB$1,[8]Orçamento!$C$1:$ZZ$1,0)),0) -> 81704.625 | ... AF2: =IFERROR(INDEX([1]Orçamento!$C$2:$ZZ$2,1,MATCH(AF$1,[1]Orçamento!$C$1:$ZZ$1,0)),0) + IFERROR(INDEX([2]Orçamento!$C$2:$ZZ$2,1,MATCH(AF$1,[2]Orçamento!$C$1:$ZZ$1,0)),0) + IFERROR(INDEX([3]Orçamento!$C$2:$ZZ$2,1,MATCH(AF$1,[3]Orçamento!$C$1:$ZZ$1,0)),0) + IFERROR(INDEX([4]Orçamento!$C$2:$ZZ$2,1,MATCH(AF$1,[4]Orçamento!$C$1:$ZZ$1,0)),0) + IFERROR(INDEX([5]Orçamento!$C$2:$ZZ$2,1,MATCH(AF$1,[5]Orçamento!$C$1:$ZZ$1,0)),0) + IFERROR(INDEX([6]Orçamento!$C$2:$ZZ$2,1,MATCH(AF$1,[6]Orçamento!$C$1:$ZZ$1,0)),0) + IFERROR(INDEX([7]Orçamento!$C$2:$ZZ$2,1,MATCH(AF$1,[7]Orçamento!$C$1:$ZZ$1,0)),0) + IFERROR(INDEX([8]Orçamento!$C$2:$ZZ$2,1,MATCH(AF$1,[8]Orçamento!$C$1:$ZZ$1,0)),0) -> 86612.25 | AG2: =SUM(T2:AF2) -> 1187569.1 | AH2: =IFERROR(INDEX([1]Orçamento!$C$2:$ZZ$2,1,MATCH(AH$1,[1]Orçamento!$C$1:$ZZ$1,0)),0) + IFERROR(INDEX([2]Orçamento!$C$2:$ZZ$2,1,MATCH(AH$1,[2]Orçamento!$C$1:$ZZ$1,0)),0) + IFERROR(INDEX([3]Orçamento!$C$2:$ZZ$2,1,MATCH(AH$1,[3]Orçamento!$C$1:$ZZ$1,0)),0) + IFERROR(INDEX([4]Orçamento!$C$2:$ZZ$2,1,MATCH(AH$1,[4]Orçamento!$C$1:$ZZ$1,0)),0) + IFERROR(INDEX([5]Orçamento!$C$2:$ZZ$2,1,MATCH(AH$1,[5]Orçamento!$C$1:$ZZ$1,0)),0) + IFERROR(INDEX([6]Orçamento!$C$2:$ZZ$2,1,MATCH(AH$1,[6]Orçamento!$C$1:$ZZ$1,0)),0) + IFERROR(INDEX([7]Orçamento!$C$2:$ZZ$2,1,MATCH(AH$1,[7]Orçamento!$C$1:$ZZ$1,0)),0) + IFERROR(INDEX([8]Orçamento!$C$2:$ZZ$2,1,MATCH(AH$1,[8]Orçamento!$C$1:$ZZ$1,0)),0) -> 170139.62 | AI2: =IFERROR(INDEX([1]Orçamento!$C$2:$ZZ$2,1,MATCH(AI$1,[1]Orçamento!$C$1:$ZZ$1,0)),0) + IFERROR(INDEX([2]Orçamento!$C$2:$ZZ$2,1,MATCH(AI$1,[2]Orçamento!$C$1:$ZZ$1,0)),0) + IFERROR(INDEX([3]Orçamento!$C$2:$ZZ$2,1,MATCH(AI$1,[3]Orçamento!$C$1:$ZZ$1,0)),0) + IFERROR(INDEX([4]Orçamento!$C$2:$ZZ$2,1,MATCH(AI$1,[4]Orçamento!$C$1:$ZZ$1,0)),0) + IFERROR(INDEX([5]Orçamento!$C$2:$ZZ$2,1,MATCH(AI$1,[5]Orçamento!$C$1:$ZZ$1,0)),0) + IFERROR(INDEX([6]Orçamento!$C$2:$ZZ$2,1,MATCH(AI$1,[6]Orçamento!$C$1:$ZZ$1,0)),0) + IFERROR(INDEX([7]Orçamento!$C$2:$ZZ$2,1,MATCH(AI$1,[7]Orçamento!$C$1:$ZZ$1,0)),0) + IFERROR(INDEX([8]Orçamento!$C$2:$ZZ$2,1,MATCH(AI$1,[8]Orçamento!$C$1:$ZZ$1,0)),0) -> 170139.62 | AJ2: =IFERROR(INDEX([1]Orçamento!$C$2:$ZZ$2,1,MATCH(AJ$1,[1]Orçamento!$C$1:$ZZ$1,0)),0) + IFERROR(INDEX([2]Orçamento!$C$2:$ZZ$2,1,MATCH(AJ$1,[2]Orçamento!$C$1:$ZZ$1,0)),0) + IFERROR(INDEX([3]Orçamento!$C$2:$ZZ$2,1,MATCH(AJ$1,[3]Orçamento!$C$1:$ZZ$1,0)),0) + IFERROR(INDEX([4]Orçamento!$C$2:$ZZ$2,1,MATCH(AJ$1,[4]Orçamento!$C$1:$ZZ$1,0)),0) + IFERROR(INDEX([5]Orçamento!$C$2:$ZZ$2,1,MATCH(AJ$1,[5]Orçamento!$C$1:$ZZ$1,0)),0) + IFERROR(INDEX([6]Orçamento!$C$2:$ZZ$2,1,MATCH(AJ$1,[6]Orçamento!$C$1:$ZZ$1,0)),0) + IFERROR(INDEX([7]Orçamento!$C$2:$ZZ$2,1,MATCH(AJ$1,[7]Orçamento!$C$1:$ZZ$1,0)),0) + IFERROR(INDEX([8]Orçamento!$C$2:$ZZ$2,1,MATCH(AJ$1,[8]Orçamento!$C$1:$ZZ$1,0)),0) -> 170139.62 | AK2: =IFERROR(INDEX([1]Orçamento!$C$2:$ZZ$2,1,MATCH(AK$1,[1]Orçamento!$C$1:$ZZ$1,0)),0) + IFERROR(INDEX([2]Orçamento!$C$2:$ZZ$2,1,MATCH(AK$1,[2]Orçamento!$C$1:$ZZ$1,0)),0) + IFERROR(INDEX([3]Orçamento!$C$2:$ZZ$2,1,MATCH(AK$1,[3]Orçamento!$C$1:$ZZ$1,0)),0) + IFERROR(INDEX([4]Orçamento!$C$2:$ZZ$2,1,MATCH(AK$1,[4]Orçamento!$C$1:$ZZ$1,0)),0) + IFERROR(INDEX([5]Orçamento!$C$2:$ZZ$2,1,MATCH(AK$1,[5]Orçamento!$C$1:$ZZ$1,0)),0) + IFERROR(INDEX([6]Orçamento!$C$2:$ZZ$2,1,MATCH(AK$1,[6]Orçamento!$C$1:$ZZ$1,0)),0) + IFERROR(INDEX([7]Orçamento!$C$2:$ZZ$2,1,MATCH(AK$1,[7]Orçamento!$C$1:$ZZ$1,0)),0) + IFERROR(INDEX([8]Orçamento!$C$2:$ZZ$2,1,MATCH(AK$1,[8]Orçamento!$C$1:$ZZ$1,0)),0) -> 172593.44 | AL2: =IFERROR(INDEX([1]Orçamento!$C$2:$ZZ$2,1,MATCH(AL$1,[1]Orçamento!$C$1:$ZZ$1,0)),0) + IFERROR(INDEX([2]Orçamento!$C$2:$ZZ$2,1,MATCH(AL$1,[2]Orçamento!$C$1:$ZZ$1,0)),0) + IFERROR(INDEX([3]Orçamento!$C$2:$ZZ$2,1,MATCH(AL$1,[3]Orçamento!$C$1:$ZZ$1,0)),0) + IFERROR(INDEX([4]Orçamento!$C$2:$ZZ$2,1,MATCH(AL$1,[4]Orçamento!$C$1:$ZZ$1,0)),0) + IFERROR(INDEX([5]Orçamento!$C$2:$ZZ$2,1,MATCH(AL$1,[5]Orçamento!$C$1:$ZZ$1,0)),0) + IFERROR(INDEX([6]Orçamento!$C$2:$ZZ$2,1,MATCH(AL$1,[6]Orçamento!$C$1:$ZZ$1,0)),0) + IFERROR(INDEX([7]Orçamento!$C$2:$ZZ$2,1,MATCH(AL$1,[7]Orçamento!$C$1:$ZZ$1,0)),0) + IFERROR(INDEX([8]Orçamento!$C$2:$ZZ$2,1,MATCH(AL$1,[8]Orçamento!$C$1:$ZZ$1,0)),0) -> 175047.25 | AM2: =IFERROR(INDEX([1]Orçamento!$C$2:$ZZ$2,1,MATCH(AM$1,[1]Orçamento!$C$1:$ZZ$1,0)),0) + IFERROR(INDEX([2]Orçamento!$C$2:$ZZ$2,1,MATCH(AM$1,[2]Orçamento!$C$1:$ZZ$1,0)),0) + IFERROR(INDEX([3]Orçamento!$C$2:$ZZ$2,1,MATCH(AM$1,[3]Orçamento!$C$1:$ZZ$1,0)),0) + IFERROR(INDEX([4]Orçamento!$C$2:$ZZ$2,1,MATCH(AM$1,[4]Orçamento!$C$1:$ZZ$1,0)),0) + IFERROR(INDEX([5]Orçamento!$C$2:$ZZ$2,1,MATCH(AM$1,[5]Orçamento!$C$1:$ZZ$1,0)),0) + IFERROR(INDEX([6]Orçamento!$C$2:$ZZ$2,1,MATCH(AM$1,[6]Orçamento!$C$1:$ZZ$1,0)),0) + IFERROR(INDEX([7]Orçamento!$C$2:$ZZ$2,1,MATCH(AM$1,[7]Orçamento!$C$1:$ZZ$1,0)),0) + IFERROR(INDEX([8]Orçamento!$C$2:$ZZ$2,1,MATCH(AM$1,[8]Orçamento!$C$1:$ZZ$1,0)),0) -> 196572.38 | AN2: =IFERROR(INDEX([1]Orçamento!$C$2:$ZZ$2,1,MATCH(AN$1,[1]Orçamento!$C$1:$ZZ$1,0)),0) + IFERROR(INDEX([2]Orçamento!$C$2:$ZZ$2,1,MATCH(AN$1,[2]Orçamento!$C$1:$ZZ$1,0)),0) + IFERROR(INDEX([3]Orçamento!$C$2:$ZZ$2,1,MATCH(AN$1,[3]Orçamento!$C$1:$ZZ$1,0)),0) + IFERROR(INDEX([4]Orçamento!$C$2:$ZZ$2,1,MATCH(AN$1,[4]Orçamento!$C$1:$ZZ$1,0)),0) + IFERROR(INDEX([5]Orçamento!$C$2:$ZZ$2,1,MATCH(AN$1,[5]Orçamento!$C$1:$ZZ$1,0)),0) + IFERROR(INDEX([6]Orçamento!$C$2:$ZZ$2,1,MATCH(AN$1,[6]Orçamento!$C$1:$ZZ$1,0)),0) + IFERROR(INDEX([7]Orçamento!$C$2:$ZZ$2,1,MATCH(AN$1,[7]Orçamento!$C$1:$ZZ$1,0)),0) + IFERROR(INDEX([8]Orçamento!$C$2:$ZZ$2,1,MATCH(AN$1,[8]Orçamento!$C$1:$ZZ$1,0)),0) -> 196572.38 | AO2: =IFERROR(INDEX([1]Orçamento!$C$2:$ZZ$2,1,MATCH(AO$1,[1]Orçamento!$C$1:$ZZ$1,0)),0) + IFERROR(INDEX([2]Orçamento!$C$2:$ZZ$2,1,MATCH(AO$1,[2]Orçamento!$C$1:$ZZ$1,0)),0) + IFERROR(INDEX([3]Orçamento!$C$2:$ZZ$2,1,MATCH(AO$1,[3]Orçamento!$C$1:$ZZ$1,0)),0) + IFERROR(INDEX([4]Orçamento!$C$2:$ZZ$2,1,MATCH(AO$1,[4]Orçamento!$C$1:$ZZ$1,0)),0) + IFERROR(INDEX([5]Orçamento!$C$2:$ZZ$2,1,MATCH(AO$1,[5]Orçamento!$C$1:$ZZ$1,0)),0) + IFERROR(INDEX([6]Orçamento!$C$2:$ZZ$2,1,MATCH(AO$1,[6]Orçamento!$C$1:$ZZ$1,0)),0) + IFERROR(INDEX([7]Orçamento!$C$2:$ZZ$2,1,MATCH(AO$1,[7]Orçamento!$C$1:$ZZ$1,0)),0) + IFERROR(INDEX([8]Orçamento!$C$2:$ZZ$2,1,MATCH(AO$1,[8]Orçamento!$C$1:$ZZ$1,0)),0) -> 196572.38 | ... AS2: =IFERROR(INDEX([1]Orçamento!$C$2:$ZZ$2,1,MATCH(AS$1,[1]Orçamento!$C$1:$ZZ$1,0)),0) + IFERROR(INDEX([2]Orçamento!$C$2:$ZZ$2,1,MATCH(AS$1,[2]Orçamento!$C$1:$ZZ$1,0)),0) + IFERROR(INDEX([3]Orçamento!$C$2:$ZZ$2,1,MATCH(AS$1,[3]Orçamento!$C$1:$ZZ$1,0)),0) + IFERROR(INDEX([4]Orçamento!$C$2:$ZZ$2,1,MATCH(AS$1,[4]Orçamento!$C$1:$ZZ$1,0)),0) + IFERROR(INDEX([5]Orçamento!$C$2:$ZZ$2,1,MATCH(AS$1,[5]Orçamento!$C$1:$ZZ$1,0)),0) + IFERROR(INDEX([6]Orçamento!$C$2:$ZZ$2,1,MATCH(AS$1,[6]Orçamento!$C$1:$ZZ$1,0)),0) + IFERROR(INDEX([7]Orçamento!$C$2:$ZZ$2,1,MATCH(AS$1,[7]Orçamento!$C$1:$ZZ$1,0)),0) + IFERROR(INDEX([8]Orçamento!$C$2:$ZZ$2,1,MATCH(AS$1,[8]Orçamento!$C$1:$ZZ$1,0)),0) -> 201480 | AT2: =SUM(AG2:AS2) -> 3428996.7 | AU2: =IFERROR(INDEX([1]Orçamento!$C$2:$ZZ$2,1,MATCH(AU$1,[1]Orçamento!$C$1:$ZZ$1,0)),0) + IFERROR(INDEX([2]Orçamento!$C$2:$ZZ$2,1,MATCH(AU$1,[2]Orçamento!$C$1:$ZZ$1,0)),0) + IFERROR(INDEX([3]Orçamento!$C$2:$ZZ$2,1,MATCH(AU$1,[3]Orçamento!$C$1:$ZZ$1,0)),0) + IFERROR(INDEX([4]Orçamento!$C$2:$ZZ$2,1,MATCH(AU$1,[4]Orçamento!$C$1:$ZZ$1,0)),0) + IFERROR(INDEX([5]Orçamento!$C$2:$ZZ$2,1,MATCH(AU$1,[5]Orçamento!$C$1:$ZZ$1,0)),0) + IFERROR(INDEX([6]Orçamento!$C$2:$ZZ$2,1,MATCH(AU$1,[6]Orçamento!$C$1:$ZZ$1,0)),0) + IFERROR(INDEX([7]Orçamento!$C$2:$ZZ$2,1,MATCH(AU$1,[7]Orçamento!$C$1:$ZZ$1,0)),0) + IFERROR(INDEX([8]Orçamento!$C$2:$ZZ$2,1,MATCH(AU$1,[8]Orçamento!$C$1:$ZZ$1,0)),0) -> 335955.25 | AV2: =IFERROR(INDEX([1]Orçamento!$C$2:$ZZ$2,1,MATCH(AV$1,[1]Orçamento!$C$1:$ZZ$1,0)),0) + IFERROR(INDEX([2]Orçamento!$C$2:$ZZ$2,1,MATCH(AV$1,[2]Orçamento!$C$1:$ZZ$1,0)),0) + IFERROR(INDEX([3]Orçamento!$C$2:$ZZ$2,1,MATCH(AV$1,[3]Orçamento!$C$1:$ZZ$1,0)),0) + IFERROR(INDEX([4]Orçamento!$C$2:$ZZ$2,1,MATCH(AV$1,[4]Orçamento!$C$1:$ZZ$1,0)),0) + IFERROR(INDEX([5]Orçamento!$C$2:$ZZ$2,1,MATCH(AV$1,[5]Orçamento!$C$1:$ZZ$1,0)),0) + IFERROR(INDEX([6]Orçamento!$C$2:$ZZ$2,1,MATCH(AV$1,[6]Orçamento!$C$1:$ZZ$1,0)),0) + IFERROR(INDEX([7]Orçamento!$C$2:$ZZ$2,1,MATCH(AV$1,[7]Orçamento!$C$1:$ZZ$1,0)),0) + IFERROR(INDEX([8]Orçamento!$C$2:$ZZ$2,1,MATCH(AV$1,[8]Orçamento!$C$1:$ZZ$1,0)),0) -> 335955.25 | AW2: =IFERROR(INDEX([1]Orçamento!$C$2:$ZZ$2,1,MATCH(AW$1,[1]Orçamento!$C$1:$ZZ$1,0)),0) + IFERROR(INDEX([2]Orçamento!$C$2:$ZZ$2,1,MATCH(AW$1,[2]Orçamento!$C$1:$ZZ$1,0)),0) + IFERROR(INDEX([3]Orçamento!$C$2:$ZZ$2,1,MATCH(AW$1,[3]Orçamento!$C$1:$ZZ$1,0)),0) + IFERROR(INDEX([4]Orçamento!$C$2:$ZZ$2,1,MATCH(AW$1,[4]Orçamento!$C$1:$ZZ$1,0)),0) + IFERROR(INDEX([5]Orçamento!$C$2:$ZZ$2,1,MATCH(AW$1,[5]Orçamento!$C$1:$ZZ$1,0)),0) + IFERROR(INDEX([6]Orçamento!$C$2:$ZZ$2,1,MATCH(AW$1,[6]Orçamento!$C$1:$ZZ$1,0)),0) + IFERROR(INDEX([7]Orçamento!$C$2:$ZZ$2,1,MATCH(AW$1,[7]Orçamento!$C$1:$ZZ$1,0)),0) + IFERROR(INDEX([8]Orçamento!$C$2:$ZZ$2,1,MATCH(AW$1,[8]Orçamento!$C$1:$ZZ$1,0)),0) -> 335955.25 | AX2: =IFERROR(INDEX([1]Orçamento!$C$2:$ZZ$2,1,MATCH(AX$1,[1]Orçamento!$C$1:$ZZ$1,0)),0) + IFERROR(INDEX([2]Orçamento!$C$2:$ZZ$2,1,MATCH(AX$1,[2]Orçamento!$C$1:$ZZ$1,0)),0) + IFERROR(INDEX([3]Orçamento!$C$2:$ZZ$2,1,MATCH(AX$1,[3]Orçamento!$C$1:$ZZ$1,0)),0) + IFERROR(INDEX([4]Orçamento!$C$2:$ZZ$2,1,MATCH(AX$1,[4]Orçamento!$C$1:$ZZ$1,0)),0) + IFERROR(INDEX([5]Orçamento!$C$2:$ZZ$2,1,MATCH(AX$1,[5]Orçamento!$C$1:$ZZ$1,0)),0) + IFERROR(INDEX([6]Orçamento!$C$2:$ZZ$2,1,MATCH(AX$1,[6]Orçamento!$C$1:$ZZ$1,0)),0) + IFERROR(INDEX([7]Orçamento!$C$2:$ZZ$2,1,MATCH(AX$1,[7]Orçamento!$C$1:$ZZ$1,0)),0) + IFERROR(INDEX([8]Orçamento!$C$2:$ZZ$2,1,MATCH(AX$1,[8]Orçamento!$C$1:$ZZ$1,0)),0) -> 338409.06 | AY2: =IFERROR(INDEX([1]Orçamento!$C$2:$ZZ$2,1,MATCH(AY$1,[1]Orçamento!$C$1:$ZZ$1,0)),0) + IFERROR(INDEX([2]Orçamento!$C$2:$ZZ$2,1,MATCH(AY$1,[2]Orçamento!$C$1:$ZZ$1,0)),0) + IFERROR(INDEX([3]Orçamento!$C$2:$ZZ$2,1,MATCH(AY$1,[3]Orçamento!$C$1:$ZZ$1,0)),0) + IFERROR(INDEX([4]Orçamento!$C$2:$ZZ$2,1,MATCH(AY$1,[4]Orçamento!$C$1:$ZZ$1,0)),0) + IFERROR(INDEX([5]Orçamento!$C$2:$ZZ$2,1,MATCH(AY$1,[5]Orçamento!$C$1:$ZZ$1,0)),0) + IFERROR(INDEX([6]Orçamento!$C$2:$ZZ$2,1,MATCH(AY$1,[6]Orçamento!$C$1:$ZZ$1,0)),0) + IFERROR(INDEX([7]Orçamento!$C$2:$ZZ$2,1,MATCH(AY$1,[7]Orçamento!$C$1:$ZZ$1,0)),0) + IFERROR(INDEX([8]Orçamento!$C$2:$ZZ$2,1,MATCH(AY$1,[8]Orçamento!$C$1:$ZZ$1,0)),0) -> 340862.88 | AZ2: =IFERROR(INDEX([1]Orçamento!$C$2:$ZZ$2,1,MATCH(AZ$1,[1]Orçamento!$C$1:$ZZ$1,0)),0) + IFERROR(INDEX([2]Orçamento!$C$2:$ZZ$2,1,MATCH(AZ$1,[2]Orçamento!$C$1:$ZZ$1,0)),0) + IFERROR(INDEX([3]Orçamento!$C$2:$ZZ$2,1,MATCH(AZ$1,[3]Orçamento!$C$1:$ZZ$1,0)),0) + IFERROR(INDEX([4]Orçamento!$C$2:$ZZ$2,1,MATCH(AZ$1,[4]Orçamento!$C$1:$ZZ$1,0)),0) + IFERROR(INDEX([5]Orçamento!$C$2:$ZZ$2,1,MATCH(AZ$1,[5]Orçamento!$C$1:$ZZ$1,0)),0) + IFERROR(INDEX([6]Orçamento!$C$2:$ZZ$2,1,MATCH(AZ$1,[6]Orçamento!$C$1:$ZZ$1,0)),0) + IFERROR(INDEX([7]Orçamento!$C$2:$ZZ$2,1,MATCH(AZ$1,[7]Orçamento!$C$1:$ZZ$1,0)),0) + IFERROR(INDEX([8]Orçamento!$C$2:$ZZ$2,1,MATCH(AZ$1,[8]Orçamento!$C$1:$ZZ$1,0)),0) -> 362388 | BA2: =IFERROR(INDEX([1]Orçamento!$C$2:$ZZ$2,1,MATCH(BA$1,[1]Orçamento!$C$1:$ZZ$1,0)),0) + IFERROR(INDEX([2]Orçamento!$C$2:$ZZ$2,1,MATCH(BA$1,[2]Orçamento!$C$1:$ZZ$1,0)),0) + IFERROR(INDEX([3]Orçamento!$C$2:$ZZ$2,1,MATCH(BA$1,[3]Orçamento!$C$1:$ZZ$1,0)),0) + IFERROR(INDEX([4]Orçamento!$C$2:$ZZ$2,1,MATCH(BA$1,[4]Orçamento!$C$1:$ZZ$1,0)),0) + IFERROR(INDEX([5]Orçamento!$C$2:$ZZ$2,1,MATCH(BA$1,[5]Orçamento!$C$1:$ZZ$1,0)),0) + IFERROR(INDEX([6]Orçamento!$C$2:$ZZ$2,1,MATCH(BA$1,[6]Orçamento!$C$1:$ZZ$1,0)),0) + IFERROR(INDEX([7]Orçamento!$C$2:$ZZ$2,1,MATCH(BA$1,[7]Orçamento!$C$1:$ZZ$1,0)),0) + IFERROR(INDEX([8]Orçamento!$C$2:$ZZ$2,1,MATCH(BA$1,[8]Orçamento!$C$1:$ZZ$1,0)),0) -> 362388 | BB2: =IFERROR(INDEX([1]Orçamento!$C$2:$ZZ$2,1,MATCH(BB$1,[1]Orçamento!$C$1:$ZZ$1,0)),0) + IFERROR(INDEX([2]Orçamento!$C$2:$ZZ$2,1,MATCH(BB$1,[2]Orçamento!$C$1:$ZZ$1,0)),0) + IFERROR(INDEX([3]Orçamento!$C$2:$ZZ$2,1,MATCH(BB$1,[3]Orçamento!$C$1:$ZZ$1,0)),0) + IFERROR(INDEX([4]Orçamento!$C$2:$ZZ$2,1,MATCH(BB$1,[4]Orçamento!$C$1:$ZZ$1,0)),0) + IFERROR(INDEX([5]Orçamento!$C$2:$ZZ$2,1,MATCH(BB$1,[5]Orçamento!$C$1:$ZZ$1,0)),0) + IFERROR(INDEX([6]Orçamento!$C$2:$ZZ$2,1,MATCH(BB$1,[6]Orçamento!$C$1:$ZZ$1,0)),0) + IFERROR(INDEX([7]Orçamento!$C$2:$ZZ$2,1,MATCH(BB$1,[7]Orçamento!$C$1:$ZZ$1,0)),0) + IFERROR(INDEX([8]Orçamento!$C$2:$ZZ$2,1,MATCH(BB$1,[8]Orçamento!$C$1:$ZZ$1,0)),0) -> 362388 | ... BF2: =IFERROR(INDEX([1]Orçamento!$C$2:$ZZ$2,1,MATCH(BF$1,[1]Orçamento!$C$1:$ZZ$1,0)),0) + IFERROR(INDEX([2]Orçamento!$C$2:$ZZ$2,1,MATCH(BF$1,[2]Orçamento!$C$1:$ZZ$1,0)),0) + IFERROR(INDEX([3]Orçamento!$C$2:$ZZ$2,1,MATCH(BF$1,[3]Orçamento!$C$1:$ZZ$1,0)),0) + IFERROR(INDEX([4]Orçamento!$C$2:$ZZ$2,1,MATCH(BF$1,[4]Orçamento!$C$1:$ZZ$1,0)),0) + IFERROR(INDEX([5]Orçamento!$C$2:$ZZ$2,1,MATCH(BF$1,[5]Orçamento!$C$1:$ZZ$1,0)),0) + IFERROR(INDEX([6]Orçamento!$C$2:$ZZ$2,1,MATCH(BF$1,[6]Orçamento!$C$1:$ZZ$1,0)),0) + IFERROR(INDEX([7]Orçamento!$C$2:$ZZ$2,1,MATCH(BF$1,[7]Orçamento!$C$1:$ZZ$1,0)),0) + IFERROR(INDEX([8]Orçamento!$C$2:$ZZ$2,1,MATCH(BF$1,[8]Orçamento!$C$1:$ZZ$1,0)),0) -> 367295.62 | BG2: =SUM(AT2:BF2) -> 7660211.8 | BH2: =IFERROR(INDEX([1]Orçamento!$C$2:$ZZ$2,1,MATCH(BH$1,[1]Orçamento!$C$1:$ZZ$1,0)),0) + IFERROR(INDEX([2]Orçamento!$C$2:$ZZ$2,1,MATCH(BH$1,[2]Orçamento!$C$1:$ZZ$1,0)),0) + IFERROR(INDEX([3]Orçamento!$C$2:$ZZ$2,1,MATCH(BH$1,[3]Orçamento!$C$1:$ZZ$1,0)),0) + IFERROR(INDEX([4]Orçamento!$C$2:$ZZ$2,1,MATCH(BH$1,[4]Orçamento!$C$1:$ZZ$1,0)),0) + IFERROR(INDEX([5]Orçamento!$C$2:$ZZ$2,1,MATCH(BH$1,[5]Orçamento!$C$1:$ZZ$1,0)),0) + IFERROR(INDEX([6]Orçamento!$C$2:$ZZ$2,1,MATCH(BH$1,[6]Orçamento!$C$1:$ZZ$1,0)),0) + IFERROR(INDEX([7]Orçamento!$C$2:$ZZ$2,1,MATCH(BH$1,[7]Orçamento!$C$1:$ZZ$1,0)),0) + IFERROR(INDEX([8]Orçamento!$C$2:$ZZ$2,1,MATCH(BH$1,[8]Orçamento!$C$1:$ZZ$1,0)),0) -> 557042.75 | BI2: =IFERROR(INDEX([1]Orçamento!$C$2:$ZZ$2,1,MATCH(BI$1,[1]Orçamento!$C$1:$ZZ$1,0)),0) + IFERROR(INDEX([2]Orçamento!$C$2:$ZZ$2,1,MATCH(BI$1,[2]Orçamento!$C$1:$ZZ$1,0)),0) + IFERROR(INDEX([3]Orçamento!$C$2:$ZZ$2,1,MATCH(BI$1,[3]Orçamento!$C$1:$ZZ$1,0)),0) + IFERROR(INDEX([4]Orçamento!$C$2:$ZZ$2,1,MATCH(BI$1,[4]Orçamento!$C$1:$ZZ$1,0)),0) + IFERROR(INDEX([5]Orçamento!$C$2:$ZZ$2,1,MATCH(BI$1,[5]Orçamento!$C$1:$ZZ$1,0)),0) + IFERROR(INDEX([6]Orçamento!$C$2:$ZZ$2,1,MATCH(BI$1,[6]Orçamento!$C$1:$ZZ$1,0)),0) + IFERROR(INDEX([7]Orçamento!$C$2:$ZZ$2,1,MATCH(BI$1,[7]Orçamento!$C$1:$ZZ$1,0)),0) + IFERROR(INDEX([8]Orçamento!$C$2:$ZZ$2,1,MATCH(BI$1,[8]Orçamento!$C$1:$ZZ$1,0)),0) -> 557042.75 | BJ2: =IFERROR(INDEX([1]Orçamento!$C$2:$ZZ$2,1,MATCH(BJ$1,[1]Orçamento!$C$1:$ZZ$1,0)),0) + IFERROR(INDEX([2]Orçamento!$C$2:$ZZ$2,1,MATCH(BJ$1,[2]Orçamento!$C$1:$ZZ$1,0)),0) + IFERROR(INDEX([3]Orçamento!$C$2:$ZZ$2,1,MATCH(BJ$1,[3]Orçamento!$C$1:$ZZ$1,0)),0) + IFERROR(INDEX([4]Orçamento!$C$2:$ZZ$2,1,MATCH(BJ$1,[4]Orçamento!$C$1:$ZZ$1,0)),0) + IFERROR(INDEX([5]Orçamento!$C$2:$ZZ$2,1,MATCH(BJ$1,[5]Orçamento!$C$1:$ZZ$1,0)),0) + IFERROR(INDEX([6]Orçamento!$C$2:$ZZ$2,1,MATCH(BJ$1,[6]Orçamento!$C$1:$ZZ$1,0)),0) + IFERROR(INDEX([7]Orçamento!$C$2:$ZZ$2,1,MATCH(BJ$1,[7]Orçamento!$C$1:$ZZ$1,0)),0) + IFERROR(INDEX([8]Orçamento!$C$2:$ZZ$2,1,MATCH(BJ$1,[8]Orçamento!$C$1:$ZZ$1,0)),0) -> 557042.75 | BK2: =IFERROR(INDEX([1]Orçamento!$C$2:$ZZ$2,1,MATCH(BK$1,[1]Orçamento!$C$1:$ZZ$1,0)),0) + IFERROR(INDEX([2]Orçamento!$C$2:$ZZ$2,1,MATCH(BK$1,[2]Orçamento!$C$1:$ZZ$1,0)),0) + IFERROR(INDEX([3]Orçamento!$C$2:$ZZ$2,1,MATCH(BK$1,[3]Orçamento!$C$1:$ZZ$1,0)),0) + IFERROR(INDEX([4]Orçamento!$C$2:$ZZ$2,1,MATCH(BK$1,[4]Orçamento!$C$1:$ZZ$1,0)),0) + IFERROR(INDEX([5]Orçamento!$C$2:$ZZ$2,1,MATCH(BK$1,[5]Orçamento!$C$1:$ZZ$1,0)),0) + IFERROR(INDEX([6]Orçamento!$C$2:$ZZ$2,1,MATCH(BK$1,[6]Orçamento!$C$1:$ZZ$1,0)),0) + IFERROR(INDEX([7]Orçamento!$C$2:$ZZ$2,1,MATCH(BK$1,[7]Orçamento!$C$1:$ZZ$1,0)),0) + IFERROR(INDEX([8]Orçamento!$C$2:$ZZ$2,1,MATCH(BK$1,[8]Orçamento!$C$1:$ZZ$1,0)),0) -> 559496.56 | BL2: =IFERROR(INDEX([1]Orçamento!$C$2:$ZZ$2,1,MATCH(BL$1,[1]Orçamento!$C$1:$ZZ$1,0)),0) + IFERROR(INDEX([2]Orçamento!$C$2:$ZZ$2,1,MATCH(BL$1,[2]Orçamento!$C$1:$ZZ$1,0)),0) + IFERROR(INDEX([3]Orçamento!$C$2:$ZZ$2,1,MATCH(BL$1,[3]Orçamento!$C$1:$ZZ$1,0)),0) + IFERROR(INDEX([4]Orçamento!$C$2:$ZZ$2,1,MATCH(BL$1,[4]Orçamento!$C$1:$ZZ$1,0)),0) + IFERROR(INDEX([5]Orçamento!$C$2:$ZZ$2,1,MATCH(BL$1,[5]Orçamento!$C$1:$ZZ$1,0)),0) + IFERROR(INDEX([6]Orçamento!$C$2:$ZZ$2,1,MATCH(BL$1,[6]Orçamento!$C$1:$ZZ$1,0)),0) + IFERROR(INDEX([7]Orçamento!$C$2:$ZZ$2,1,MATCH(BL$1,[7]Orçamento!$C$1:$ZZ$1,0)),0) + IFERROR(INDEX([8]Orçamento!$C$2:$ZZ$2,1,MATCH(BL$1,[8]Orçamento!$C$1:$ZZ$1,0)),0) -> 561950.37 | BM2: =IFERROR(INDEX([1]Orçamento!$C$2:$ZZ$2,1,MATCH(BM$1,[1]Orçamento!$C$1:$ZZ$1,0)),0) + IFERROR(INDEX([2]Orçamento!$C$2:$ZZ$2,1,MATCH(BM$1,[2]Orçamento!$C$1:$ZZ$1,0)),0) + IFERROR(INDEX([3]Orçamento!$C$2:$ZZ$2,1,MATCH(BM$1,[3]Orçamento!$C$1:$ZZ$1,0)),0) + IFERROR(INDEX([4]Orçamento!$C$2:$ZZ$2,1,MATCH(BM$1,[4]Orçamento!$C$1:$ZZ$1,0)),0) + IFERROR(INDEX([5]Orçamento!$C$2:$ZZ$2,1,MATCH(BM$1,[5]Orçamento!$C$1:$ZZ$1,0)),0) + IFERROR(INDEX([6]Orçamento!$C$2:$ZZ$2,1,MATCH(BM$1,[6]Orçamento!$C$1:$ZZ$1,0)),0) + IFERROR(INDEX([7]Orçamento!$C$2:$ZZ$2,1,MATCH(BM$1,[7]Orçamento!$C$1:$ZZ$1,0)),0) + IFERROR(INDEX([8]Orçamento!$C$2:$ZZ$2,1,MATCH(BM$1,[8]Orçamento!$C$1:$ZZ$1,0)),0) -> 495040.5 | BN2: =IFERROR(INDEX([1]Orçamento!$C$2:$ZZ$2,1,MATCH(BN$1,[1]Orçamento!$C$1:$ZZ$1,0)),0) + IFERROR(INDEX([2]Orçamento!$C$2:$ZZ$2,1,MATCH(BN$1,[2]Orçamento!$C$1:$ZZ$1,0)),0) + IFERROR(INDEX([3]Orçamento!$C$2:$ZZ$2,1,MATCH(BN$1,[3]Orçamento!$C$1:$ZZ$1,0)),0) + IFERROR(INDEX([4]Orçamento!$C$2:$ZZ$2,1,MATCH(BN$1,[4]Orçamento!$C$1:$ZZ$1,0)),0) + IFERROR(INDEX([5]Orçamento!$C$2:$ZZ$2,1,MATCH(BN$1,[5]Orçamento!$C$1:$ZZ$1,0)),0) + IFERROR(INDEX([6]Orçamento!$C$2:$ZZ$2,1,MATCH(BN$1,[6]Orçamento!$C$1:$ZZ$1,0)),0) + IFERROR(INDEX([7]Orçamento!$C$2:$ZZ$2,1,MATCH(BN$1,[7]Orçamento!$C$1:$ZZ$1,0)),0) + IFERROR(INDEX([8]Orçamento!$C$2:$ZZ$2,1,MATCH(BN$1,[8]Orçamento!$C$1:$ZZ$1,0)),0) -> 583475.5 | BO2: =IFERROR(INDEX([1]Orçamento!$C$2:$ZZ$2,1,MATCH(BO$1,[1]Orçamento!$C$1:$ZZ$1,0)),0) + IFERROR(INDEX([2]Orçamento!$C$2:$ZZ$2,1,MATCH(BO$1,[2]Orçamento!$C$1:$ZZ$1,0)),0) + IFERROR(INDEX([3]Orçamento!$C$2:$ZZ$2,1,MATCH(BO$1,[3]Orçamento!$C$1:$ZZ$1,0)),0) + IFERROR(INDEX([4]Orçamento!$C$2:$ZZ$2,1,MATCH(BO$1,[4]Orçamento!$C$1:$ZZ$1,0)),0) + IFERROR(INDEX([5]Orçamento!$C$2:$ZZ$2,1,MATCH(BO$1,[5]Orçamento!$C$1:$ZZ$1,0)),0) + IFERROR(INDEX([6]Orçamento!$C$2:$ZZ$2,1,MATCH(BO$1,[6]Orçamento!$C$1:$ZZ$1,0)),0) + IFERROR(INDEX([7]Orçamento!$C$2:$ZZ$2,1,MATCH(BO$1,[7]Orçamento!$C$1:$ZZ$1,0)),0) + IFERROR(INDEX([8]Orçamento!$C$2:$ZZ$2,1,MATCH(BO$1,[8]Orçamento!$C$1:$ZZ$1,0)),0) -> 583475.5 | ... BS2: =IFERROR(INDEX([1]Orçamento!$C$2:$ZZ$2,1,MATCH(BS$1,[1]Orçamento!$C$1:$ZZ$1,0)),0) + IFERROR(INDEX([2]Orçamento!$C$2:$ZZ$2,1,MATCH(BS$1,[2]Orçamento!$C$1:$ZZ$1,0)),0) + IFERROR(INDEX([3]Orçamento!$C$2:$ZZ$2,1,MATCH(BS$1,[3]Orçamento!$C$1:$ZZ$1,0)),0) + IFERROR(INDEX([4]Orçamento!$C$2:$ZZ$2,1,MATCH(BS$1,[4]Orçamento!$C$1:$ZZ$1,0)),0) + IFERROR(INDEX([5]Orçamento!$C$2:$ZZ$2,1,MATCH(BS$1,[5]Orçamento!$C$1:$ZZ$1,0)),0) + IFERROR(INDEX([6]Orçamento!$C$2:$ZZ$2,1,MATCH(BS$1,[6]Orçamento!$C$1:$ZZ$1,0)),0) + IFERROR(INDEX([7]Orçamento!$C$2:$ZZ$2,1,MATCH(BS$1,[7]Orçamento!$C$1:$ZZ$1,0)),0) + IFERROR(INDEX([8]Orçamento!$C$2:$ZZ$2,1,MATCH(BS$1,[8]Orçamento!$C$1:$ZZ$1,0)),0) -> 583475.5 | BT2: =SUM(BG2:BS2) -> 14448680 | BU2: =IFERROR(INDEX([1]Orçamento!$C$2:$ZZ$2,1,MATCH(BU$1,[1]Orçamento!$C$1:$ZZ$1,0)),0) + IFERROR(INDEX([2]Orçamento!$C$2:$ZZ$2,1,MATCH(BU$1,[2]Orçamento!$C$1:$ZZ$1,0)),0) + IFERROR(INDEX([3]Orçamento!$C$2:$ZZ$2,1,MATCH(BU$1,[3]Orçamento!$C$1:$ZZ$1,0)),0) + IFERROR(INDEX([4]Orçamento!$C$2:$ZZ$2,1,MATCH(BU$1,[4]Orçamento!$C$1:$ZZ$1,0)),0) + IFERROR(INDEX([5]Orçamento!$C$2:$ZZ$2,1,MATCH(BU$1,[5]Orçamento!$C$1:$ZZ$1,0)),0) + IFERROR(INDEX([6]Orçamento!$C$2:$ZZ$2,1,MATCH(BU$1,[6]Orçamento!$C$1:$ZZ$1,0)),0) + IFERROR(INDEX([7]Orçamento!$C$2:$ZZ$2,1,MATCH(BU$1,[7]Orçamento!$C$1:$ZZ$1,0)),0) + IFERROR(INDEX([8]Orçamento!$C$2:$ZZ$2,1,MATCH(BU$1,[8]Orçamento!$C$1:$ZZ$1,0)),0) -> 795915 | BV2: =IFERROR(INDEX([1]Orçamento!$C$2:$ZZ$2,1,MATCH(BV$1,[1]Orçamento!$C$1:$ZZ$1,0)),0) + IFERROR(INDEX([2]Orçamento!$C$2:$ZZ$2,1,MATCH(BV$1,[2]Orçamento!$C$1:$ZZ$1,0)),0) + IFERROR(INDEX([3]Orçamento!$C$2:$ZZ$2,1,MATCH(BV$1,[3]Orçamento!$C$1:$ZZ$1,0)),0) + IFERROR(INDEX([4]Orçamento!$C$2:$ZZ$2,1,MATCH(BV$1,[4]Orçamento!$C$1:$ZZ$1,0)),0) + IFERROR(INDEX([5]Orçamento!$C$2:$ZZ$2,1,MATCH(BV$1,[5]Orçamento!$C$1:$ZZ$1,0)),0) + IFERROR(INDEX([6]Orçamento!$C$2:$ZZ$2,1,MATCH(BV$1,[6]Orçamento!$C$1:$ZZ$1,0)),0) + IFERROR(INDEX([7]Orçamento!$C$2:$ZZ$2,1,MATCH(BV$1,[7]Orçamento!$C$1:$ZZ$1,0)),0) + IFERROR(INDEX([8]Orçamento!$C$2:$ZZ$2,1,MATCH(BV$1,[8]Orçamento!$C$1:$ZZ$1,0)),0) -> 795915 | BW2: =IFERROR(INDEX([1]Orçamento!$C$2:$ZZ$2,1,MATCH(BW$1,[1]Orçamento!$C$1:$ZZ$1,0)),0) + IFERROR(INDEX([2]Orçamento!$C$2:$ZZ$2,1,MATCH(BW$1,[2]Orçamento!$C$1:$ZZ$1,0)),0) + IFERROR(INDEX([3]Orçamento!$C$2:$ZZ$2,1,MATCH(BW$1,[3]Orçamento!$C$1:$ZZ$1,0)),0) + IFERROR(INDEX([4]Orçamento!$C$2:$ZZ$2,1,MATCH(BW$1,[4]Orçamento!$C$1:$ZZ$1,0)),0) + IFERROR(INDEX([5]Orçamento!$C$2:$ZZ$2,1,MATCH(BW$1,[5]Orçamento!$C$1:$ZZ$1,0)),0) + IFERROR(INDEX([6]Orçamento!$C$2:$ZZ$2,1,MATCH(BW$1,[6]Orçamento!$C$1:$ZZ$1,0)),0) + IFERROR(INDEX([7]Orçamento!$C$2:$ZZ$2,1,MATCH(BW$1,[7]Orçamento!$C$1:$ZZ$1,0)),0) + IFERROR(INDEX([8]Orçamento!$C$2:$ZZ$2,1,MATCH(BW$1,[8]Orçamento!$C$1:$ZZ$1,0)),0) -> 795915 | BX2: =IFERROR(INDEX([1]Orçamento!$C$2:$ZZ$2,1,MATCH(BX$1,[1]Orçamento!$C$1:$ZZ$1,0)),0) + IFERROR(INDEX([2]Orçamento!$C$2:$ZZ$2,1,MATCH(BX$1,[2]Orçamento!$C$1:$ZZ$1,0)),0) + IFERROR(INDEX([3]Orçamento!$C$2:$ZZ$2,1,MATCH(BX$1,[3]Orçamento!$C$1:$ZZ$1,0)),0) + IFERROR(INDEX([4]Orçamento!$C$2:$ZZ$2,1,MATCH(BX$1,[4]Orçamento!$C$1:$ZZ$1,0)),0) + IFERROR(INDEX([5]Orçamento!$C$2:$ZZ$2,1,MATCH(BX$1,[5]Orçamento!$C$1:$ZZ$1,0)),0) + IFERROR(INDEX([6]Orçamento!$C$2:$ZZ$2,1,MATCH(BX$1,[6]Orçamento!$C$1:$ZZ$1,0)),0) + IFERROR(INDEX([7]Orçamento!$C$2:$ZZ$2,1,MATCH(BX$1,[7]Orçamento!$C$1:$ZZ$1,0)),0) + IFERROR(INDEX([8]Orçamento!$C$2:$ZZ$2,1,MATCH(BX$1,[8]Orçamento!$C$1:$ZZ$1,0)),0) -> 795915 | BY2: =IFERROR(INDEX([1]Orçamento!$C$2:$ZZ$2,1,MATCH(BY$1,[1]Orçamento!$C$1:$ZZ$1,0)),0) + IFERROR(INDEX([2]Orçamento!$C$2:$ZZ$2,1,MATCH(BY$1,[2]Orçamento!$C$1:$ZZ$1,0)),0) + IFERROR(INDEX([3]Orçamento!$C$2:$ZZ$2,1,MATCH(BY$1,[3]Orçamento!$C$1:$ZZ$1,0)),0) + IFERROR(INDEX([4]Orçamento!$C$2:$ZZ$2,1,MATCH(BY$1,[4]Orçamento!$C$1:$ZZ$1,0)),0) + IFERROR(INDEX([5]Orçamento!$C$2:$ZZ$2,1,MATCH(BY$1,[5]Orçamento!$C$1:$ZZ$1,0)),0) + IFERROR(INDEX([6]Orçamento!$C$2:$ZZ$2,1,MATCH(BY$1,[6]Orçamento!$C$1:$ZZ$1,0)),0) + IFERROR(INDEX([7]Orçamento!$C$2:$ZZ$2,1,MATCH(BY$1,[7]Orçamento!$C$1:$ZZ$1,0)),0) + IFERROR(INDEX([8]Orçamento!$C$2:$ZZ$2,1,MATCH(BY$1,[8]Orçamento!$C$1:$ZZ$1,0)),0) -> 795915 | BZ2: =IFERROR(INDEX([1]Orçamento!$C$2:$ZZ$2,1,MATCH(BZ$1,[1]Orçamento!$C$1:$ZZ$1,0)),0) + IFERROR(INDEX([2]Orçamento!$C$2:$ZZ$2,1,MATCH(BZ$1,[2]Orçamento!$C$1:$ZZ$1,0)),0) + IFERROR(INDEX([3]Orçamento!$C$2:$ZZ$2,1,MATCH(BZ$1,[3]Orçamento!$C$1:$ZZ$1,0)),0) + IFERROR(INDEX([4]Orçamento!$C$2:$ZZ$2,1,MATCH(BZ$1,[4]Orçamento!$C$1:$ZZ$1,0)),0) + IFERROR(INDEX([5]Orçamento!$C$2:$ZZ$2,1,MATCH(BZ$1,[5]Orçamento!$C$1:$ZZ$1,0)),0) + IFERROR(INDEX([6]Orçamento!$C$2:$ZZ$2,1,MATCH(BZ$1,[6]Orçamento!$C$1:$ZZ$1,0)),0) + IFERROR(INDEX([7]Orçamento!$C$2:$ZZ$2,1,MATCH(BZ$1,[7]Orçamento!$C$1:$ZZ$1,0)),0) + IFERROR(INDEX([8]Orçamento!$C$2:$ZZ$2,1,MATCH(BZ$1,[8]Orçamento!$C$1:$ZZ$1,0)),0) -> 795915 | CA2: =IFERROR(INDEX([1]Orçamento!$C$2:$ZZ$2,1,MATCH(CA$1,[1]Orçamento!$C$1:$ZZ$1,0)),0) + IFERROR(INDEX([2]Orçamento!$C$2:$ZZ$2,1,MATCH(CA$1,[2]Orçamento!$C$1:$ZZ$1,0)),0) + IFERROR(INDEX([3]Orçamento!$C$2:$ZZ$2,1,MATCH(CA$1,[3]Orçamento!$C$1:$ZZ$1,0)),0) + IFERROR(INDEX([4]Orçamento!$C$2:$ZZ$2,1,MATCH(CA$1,[4]Orçamento!$C$1:$ZZ$1,0)),0) + IFERROR(INDEX([5]Orçamento!$C$2:$ZZ$2,1,MATCH(CA$1,[5]Orçamento!$C$1:$ZZ$1,0)),0) + IFERROR(INDEX([6]Orçamento!$C$2:$ZZ$2,1,MATCH(CA$1,[6]Orçamento!$C$1:$ZZ$1,0)),0) + IFERROR(INDEX([7]Orçamento!$C$2:$ZZ$2,1,MATCH(CA$1,[7]Orçamento!$C$1:$ZZ$1,0)),0) + IFERROR(INDEX([8]Orçamento!$C$2:$ZZ$2,1,MATCH(CA$1,[8]Orçamento!$C$1:$ZZ$1,0)),0) -> 795915 | CB2: =IFERROR(INDEX([1]Orçamento!$C$2:$ZZ$2,1,MATCH(CB$1,[1]Orçamento!$C$1:$ZZ$1,0)),0) + IFERROR(INDEX([2]Orçamento!$C$2:$ZZ$2,1,MATCH(CB$1,[2]Orçamento!$C$1:$ZZ$1,0)),0) + IFERROR(INDEX([3]Orçamento!$C$2:$ZZ$2,1,MATCH(CB$1,[3]Orçamento!$C$1:$ZZ$1,0)),0) + IFERROR(INDEX([4]Orçamento!$C$2:$ZZ$2,1,MATCH(CB$1,[4]Orçamento!$C$1:$ZZ$1,0)),0) + IFERROR(INDEX([5]Orçamento!$C$2:$ZZ$2,1,MATCH(CB$1,[5]Orçamento!$C$1:$ZZ$1,0)),0) + IFERROR(INDEX([6]Orçamento!$C$2:$ZZ$2,1,MATCH(CB$1,[6]Orçamento!$C$1:$ZZ$1,0)),0) + IFERROR(INDEX([7]Orçamento!$C$2:$ZZ$2,1,MATCH(CB$1,[7]Orçamento!$C$1:$ZZ$1,0)),0) + IFERROR(INDEX([8]Orçamento!$C$2:$ZZ$2,1,MATCH(CB$1,[8]Orçamento!$C$1:$ZZ$1,0)),0) -> 795915 | ... CF2: =IFERROR(INDEX([1]Orçamento!$C$2:$ZZ$2,1,MATCH(CF$1,[1]Orçamento!$C$1:$ZZ$1,0)),0) + IFERROR(INDEX([2]Orçamento!$C$2:$ZZ$2,1,MATCH(CF$1,[2]Orçamento!$C$1:$ZZ$1,0)),0) + IFERROR(INDEX([3]Orçamento!$C$2:$ZZ$2,1,MATCH(CF$1,[3]Orçamento!$C$1:$ZZ$1,0)),0) + IFERROR(INDEX([4]Orçamento!$C$2:$ZZ$2,1,MATCH(CF$1,[4]Orçamento!$C$1:$ZZ$1,0)),0) + IFERROR(INDEX([5]Orçamento!$C$2:$ZZ$2,1,MATCH(CF$1,[5]Orçamento!$C$1:$ZZ$1,0)),0) + IFERROR(INDEX([6]Orçamento!$C$2:$ZZ$2,1,MATCH(CF$1,[6]Orçamento!$C$1:$ZZ$1,0)),0) + IFERROR(INDEX([7]Orçamento!$C$2:$ZZ$2,1,MATCH(CF$1,[7]Orçamento!$C$1:$ZZ$1,0)),0) + IFERROR(INDEX([8]Orçamento!$C$2:$ZZ$2,1,MATCH(CF$1,[8]Orçamento!$C$1:$ZZ$1,0)),0) -> 795915 | CG2: =SUM(BT2:CF2) -> 23999660 | CH2: =IFERROR(INDEX([1]Orçamento!$C$2:$ZZ$2,1,MATCH(CH$1,[1]Orçamento!$C$1:$ZZ$1,0)),0) + IFERROR(INDEX([2]Orçamento!$C$2:$ZZ$2,1,MATCH(CH$1,[2]Orçamento!$C$1:$ZZ$1,0)),0) + IFERROR(INDEX([3]Orçamento!$C$2:$ZZ$2,1,MATCH(CH$1,[3]Orçamento!$C$1:$ZZ$1,0)),0) + IFERROR(INDEX([4]Orçamento!$C$2:$ZZ$2,1,MATCH(CH$1,[4]Orçamento!$C$1:$ZZ$1,0)),0) + IFERROR(INDEX([5]Orçamento!$C$2:$ZZ$2,1,MATCH(CH$1,[5]Orçamento!$C$1:$ZZ$1,0)),0) + IFERROR(INDEX([6]Orçamento!$C$2:$ZZ$2,1,MATCH(CH$1,[6]Orçamento!$C$1:$ZZ$1,0)),0) + IFERROR(INDEX([7]Orçamento!$C$2:$ZZ$2,1,MATCH(CH$1,[7]Orçamento!$C$1:$ZZ$1,0)),0) + IFERROR(INDEX([8]Orçamento!$C$2:$ZZ$2,1,MATCH(CH$1,[8]Orçamento!$C$1:$ZZ$1,0)),0) -> 972785 | CI2: =IFERROR(INDEX([1]Orçamento!$C$2:$ZZ$2,1,MATCH(CI$1,[1]Orçamento!$C$1:$ZZ$1,0)),0) + IFERROR(INDEX([2]Orçamento!$C$2:$ZZ$2,1,MATCH(CI$1,[2]Orçamento!$C$1:$ZZ$1,0)),0) + IFERROR(INDEX([3]Orçamento!$C$2:$ZZ$2,1,MATCH(CI$1,[3]Orçamento!$C$1:$ZZ$1,0)),0) + IFERROR(INDEX([4]Orçamento!$C$2:$ZZ$2,1,MATCH(CI$1,[4]Orçamento!$C$1:$ZZ$1,0)),0) + IFERROR(INDEX([5]Orçamento!$C$2:$ZZ$2,1,MATCH(CI$1,[5]Orçamento!$C$1:$ZZ$1,0)),0) + IFERROR(INDEX([6]Orçamento!$C$2:$ZZ$2,1,MATCH(CI$1,[6]Orçamento!$C$1:$ZZ$1,0)),0) + IFERROR(INDEX([7]Orçamento!$C$2:$ZZ$2,1,MATCH(CI$1,[7]Orçamento!$C$1:$ZZ$1,0)),0) + IFERROR(INDEX([8]Orçamento!$C$2:$ZZ$2,1,MATCH(CI$1,[8]Orçamento!$C$1:$ZZ$1,0)),0) -> 972785 | CJ2: =IFERROR(INDEX([1]Orçamento!$C$2:$ZZ$2,1,MATCH(CJ$1,[1]Orçamento!$C$1:$ZZ$1,0)),0) + IFERROR(INDEX([2]Orçamento!$C$2:$ZZ$2,1,MATCH(CJ$1,[2]Orçamento!$C$1:$ZZ$1,0)),0) + IFERROR(INDEX([3]Orçamento!$C$2:$ZZ$2,1,MATCH(CJ$1,[3]Orçamento!$C$1:$ZZ$1,0)),0) + IFERROR(INDEX([4]Orçamento!$C$2:$ZZ$2,1,MATCH(CJ$1,[4]Orçamento!$C$1:$ZZ$1,0)),0) + IFERROR(INDEX([5]Orçamento!$C$2:$ZZ$2,1,MATCH(CJ$1,[5]Orçamento!$C$1:$ZZ$1,0)),0) + IFERROR(INDEX([6]Orçamento!$C$2:$ZZ$2,1,MATCH(CJ$1,[6]Orçamento!$C$1:$ZZ$1,0)),0) + IFERROR(INDEX([7]Orçamento!$C$2:$ZZ$2,1,MATCH(CJ$1,[7]Orçamento!$C$1:$ZZ$1,0)),0) + IFERROR(INDEX([8]Orçamento!$C$2:$ZZ$2,1,MATCH(CJ$1,[8]Orçamento!$C$1:$ZZ$1,0)),0) -> 972785 | CK2: =IFERROR(INDEX([1]Orçamento!$C$2:$ZZ$2,1,MATCH(CK$1,[1]Orçamento!$C$1:$ZZ$1,0)),0) + IFERROR(INDEX([2]Orçamento!$C$2:$ZZ$2,1,MATCH(CK$1,[2]Orçamento!$C$1:$ZZ$1,0)),0) + IFERROR(INDEX([3]Orçamento!$C$2:$ZZ$2,1,MATCH(CK$1,[3]Orçamento!$C$1:$ZZ$1,0)),0) + IFERROR(INDEX([4]Orçamento!$C$2:$ZZ$2,1,MATCH(CK$1,[4]Orçamento!$C$1:$ZZ$1,0)),0) + IFERROR(INDEX([5]Orçamento!$C$2:$ZZ$2,1,MATCH(CK$1,[5]Orçamento!$C$1:$ZZ$1,0)),0) + IFERROR(INDEX([6]Orçamento!$C$2:$ZZ$2,1,MATCH(CK$1,[6]Orçamento!$C$1:$ZZ$1,0)),0) + IFERROR(INDEX([7]Orçamento!$C$2:$ZZ$2,1,MATCH(CK$1,[7]Orçamento!$C$1:$ZZ$1,0)),0) + IFERROR(INDEX([8]Orçamento!$C$2:$ZZ$2,1,MATCH(CK$1,[8]Orçamento!$C$1:$ZZ$1,0)),0) -> 972785 | CL2: =IFERROR(INDEX([1]Orçamento!$C$2:$ZZ$2,1,MATCH(CL$1,[1]Orçamento!$C$1:$ZZ$1,0)),0) + IFERROR(INDEX([2]Orçamento!$C$2:$ZZ$2,1,MATCH(CL$1,[2]Orçamento!$C$1:$ZZ$1,0)),0) + IFERROR(INDEX([3]Orçamento!$C$2:$ZZ$2,1,MATCH(CL$1,[3]Orçamento!$C$1:$ZZ$1,0)),0) + IFERROR(INDEX([4]Orçamento!$C$2:$ZZ$2,1,MATCH(CL$1,[4]Orçamento!$C$1:$ZZ$1,0)),0) + IFERROR(INDEX([5]Orçamento!$C$2:$ZZ$2,1,MATCH(CL$1,[5]Orçamento!$C$1:$ZZ$1,0)),0) + IFERROR(INDEX([6]Orçamento!$C$2:$ZZ$2,1,MATCH(CL$1,[6]Orçamento!$C$1:$ZZ$1,0)),0) + IFERROR(INDEX([7]Orçamento!$C$2:$ZZ$2,1,MATCH(CL$1,[7]Orçamento!$C$1:$ZZ$1,0)),0) + IFERROR(INDEX([8]Orçamento!$C$2:$ZZ$2,1,MATCH(CL$1,[8]Orçamento!$C$1:$ZZ$1,0)),0) -> 972785 | CM2: =IFERROR(INDEX([1]Orçamento!$C$2:$ZZ$2,1,MATCH(CM$1,[1]Orçamento!$C$1:$ZZ$1,0)),0) + IFERROR(INDEX([2]Orçamento!$C$2:$ZZ$2,1,MATCH(CM$1,[2]Orçamento!$C$1:$ZZ$1,0)),0) + IFERROR(INDEX([3]Orçamento!$C$2:$ZZ$2,1,MATCH(CM$1,[3]Orçamento!$C$1:$ZZ$1,0)),0) + IFERROR(INDEX([4]Orçamento!$C$2:$ZZ$2,1,MATCH(CM$1,[4]Orçamento!$C$1:$ZZ$1,0)),0) + IFERROR(INDEX([5]Orçamento!$C$2:$ZZ$2,1,MATCH(CM$1,[5]Orçamento!$C$1:$ZZ$1,0)),0) + IFERROR(INDEX([6]Orçamento!$C$2:$ZZ$2,1,MATCH(CM$1,[6]Orçamento!$C$1:$ZZ$1,0)),0) + IFERROR(INDEX([7]Orçamento!$C$2:$ZZ$2,1,MATCH(CM$1,[7]Orçamento!$C$1:$ZZ$1,0)),0) + IFERROR(INDEX([8]Orçamento!$C$2:$ZZ$2,1,MATCH(CM$1,[8]Orçamento!$C$1:$ZZ$1,0)),0) -> 928567.5 | CN2: =IFERROR(INDEX([1]Orçamento!$C$2:$ZZ$2,1,MATCH(CN$1,[1]Orçamento!$C$1:$ZZ$1,0)),0) + IFERROR(INDEX([2]Orçamento!$C$2:$ZZ$2,1,MATCH(CN$1,[2]Orçamento!$C$1:$ZZ$1,0)),0) + IFERROR(INDEX([3]Orçamento!$C$2:$ZZ$2,1,MATCH(CN$1,[3]Orçamento!$C$1:$ZZ$1,0)),0) + IFERROR(INDEX([4]Orçamento!$C$2:$ZZ$2,1,MATCH(CN$1,[4]Orçamento!$C$1:$ZZ$1,0)),0) + IFERROR(INDEX([5]Orçamento!$C$2:$ZZ$2,1,MATCH(CN$1,[5]Orçamento!$C$1:$ZZ$1,0)),0) + IFERROR(INDEX([6]Orçamento!$C$2:$ZZ$2,1,MATCH(CN$1,[6]Orçamento!$C$1:$ZZ$1,0)),0) + IFERROR(INDEX([7]Orçamento!$C$2:$ZZ$2,1,MATCH(CN$1,[7]Orçamento!$C$1:$ZZ$1,0)),0) + IFERROR(INDEX([8]Orçamento!$C$2:$ZZ$2,1,MATCH(CN$1,[8]Orçamento!$C$1:$ZZ$1,0)),0) -> 972785 | CO2: =IFERROR(INDEX([1]Orçamento!$C$2:$ZZ$2,1,MATCH(CO$1,[1]Orçamento!$C$1:$ZZ$1,0)),0) + IFERROR(INDEX([2]Orçamento!$C$2:$ZZ$2,1,MATCH(CO$1,[2]Orçamento!$C$1:$ZZ$1,0)),0) + IFERROR(INDEX([3]Orçamento!$C$2:$ZZ$2,1,MATCH(CO$1,[3]Orçamento!$C$1:$ZZ$1,0)),0) + IFERROR(INDEX([4]Orçamento!$C$2:$ZZ$2,1,MATCH(CO$1,[4]Orçamento!$C$1:$ZZ$1,0)),0) + IFERROR(INDEX([5]Orçamento!$C$2:$ZZ$2,1,MATCH(CO$1,[5]Orçamento!$C$1:$ZZ$1,0)),0) + IFERROR(INDEX([6]Orçamento!$C$2:$ZZ$2,1,MATCH(CO$1,[6]Orçamento!$C$1:$ZZ$1,0)),0) + IFERROR(INDEX([7]Orçamento!$C$2:$ZZ$2,1,MATCH(CO$1,[7]Orçamento!$C$1:$ZZ$1,0)),0) + IFERROR(INDEX([8]Orçamento!$C$2:$ZZ$2,1,MATCH(CO$1,[8]Orçamento!$C$1:$ZZ$1,0)),0) -> 972785 | ... CS2: =IFERROR(INDEX([1]Orçamento!$C$2:$ZZ$2,1,MATCH(CS$1,[1]Orçamento!$C$1:$ZZ$1,0)),0) + IFERROR(INDEX([2]Orçamento!$C$2:$ZZ$2,1,MATCH(CS$1,[2]Orçamento!$C$1:$ZZ$1,0)),0) + IFERROR(INDEX([3]Orçamento!$C$2:$ZZ$2,1,MATCH(CS$1,[3]Orçamento!$C$1:$ZZ$1,0)),0) + IFERROR(INDEX([4]Orçamento!$C$2:$ZZ$2,1,MATCH(CS$1,[4]Orçamento!$C$1:$ZZ$1,0)),0) + IFERROR(INDEX([5]Orçamento!$C$2:$ZZ$2,1,MATCH(CS$1,[5]Orçamento!$C$1:$ZZ$1,0)),0) + IFERROR(INDEX([6]Orçamento!$C$2:$ZZ$2,1,MATCH(CS$1,[6]Orçamento!$C$1:$ZZ$1,0)),0) + IFERROR(INDEX([7]Orçamento!$C$2:$ZZ$2,1,MATCH(CS$1,[7]Orçamento!$C$1:$ZZ$1,0)),0) + IFERROR(INDEX([8]Orçamento!$C$2:$ZZ$2,1,MATCH(CS$1,[8]Orçamento!$C$1:$ZZ$1,0)),0) -> 972785 | CT2: =SUM(CG2:CS2) -> 35628863 | CU2: =IFERROR(INDEX([1]Orçamento!$C$2:$ZZ$2,1,MATCH(CU$1,[1]Orçamento!$C$1:$ZZ$1,0)),0) + IFERROR(INDEX([2]Orçamento!$C$2:$ZZ$2,1,MATCH(CU$1,[2]Orçamento!$C$1:$ZZ$1,0)),0) + IFERROR(INDEX([3]Orçamento!$C$2:$ZZ$2,1,MATCH(CU$1,[3]Orçamento!$C$1:$ZZ$1,0)),0) + IFERROR(INDEX([4]Orçamento!$C$2:$ZZ$2,1,MATCH(CU$1,[4]Orçamento!$C$1:$ZZ$1,0)),0) + IFERROR(INDEX([5]Orçamento!$C$2:$ZZ$2,1,MATCH(CU$1,[5]Orçamento!$C$1:$ZZ$1,0)),0) + IFERROR(INDEX([6]Orçamento!$C$2:$ZZ$2,1,MATCH(CU$1,[6]Orçamento!$C$1:$ZZ$1,0)),0) + IFERROR(INDEX([7]Orçamento!$C$2:$ZZ$2,1,MATCH(CU$1,[7]Orçamento!$C$1:$ZZ$1,0)),0) + IFERROR(INDEX([8]Orçamento!$C$2:$ZZ$2,1,MATCH(CU$1,[8]Orçamento!$C$1:$ZZ$1,0)),0) -> 961730.62 | CV2: =IFERROR(INDEX([1]Orçamento!$C$2:$ZZ$2,1,MATCH(CV$1,[1]Orçamento!$C$1:$ZZ$1,0)),0) + IFERROR(INDEX([2]Orçamento!$C$2:$ZZ$2,1,MATCH(CV$1,[2]Orçamento!$C$1:$ZZ$1,0)),0) + IFERROR(INDEX([3]Orçamento!$C$2:$ZZ$2,1,MATCH(CV$1,[3]Orçamento!$C$1:$ZZ$1,0)),0) + IFERROR(INDEX([4]Orçamento!$C$2:$ZZ$2,1,MATCH(CV$1,[4]Orçamento!$C$1:$ZZ$1,0)),0) + IFERROR(INDEX([5]Orçamento!$C$2:$ZZ$2,1,MATCH(CV$1,[5]Orçamento!$C$1:$ZZ$1,0)),0) + IFERROR(INDEX([6]Orçamento!$C$2:$ZZ$2,1,MATCH(CV$1,[6]Orçamento!$C$1:$ZZ$1,0)),0) + IFERROR(INDEX([7]Orçamento!$C$2:$ZZ$2,1,MATCH(CV$1,[7]Orçamento!$C$1:$ZZ$1,0)),0) + IFERROR(INDEX([8]Orçamento!$C$2:$ZZ$2,1,MATCH(CV$1,[8]Orçamento!$C$1:$ZZ$1,0)),0) -> 961730.62 | CW2: =IFERROR(INDEX([1]Orçamento!$C$2:$ZZ$2,1,MATCH(CW$1,[1]Orçamento!$C$1:$ZZ$1,0)),0) + IFERROR(INDEX([2]Orçamento!$C$2:$ZZ$2,1,MATCH(CW$1,[2]Orçamento!$C$1:$ZZ$1,0)),0) + IFERROR(INDEX([3]Orçamento!$C$2:$ZZ$2,1,MATCH(CW$1,[3]Orçamento!$C$1:$ZZ$1,0)),0) + IFERROR(INDEX([4]Orçamento!$C$2:$ZZ$2,1,MATCH(CW$1,[4]Orçamento!$C$1:$ZZ$1,0)),0) + IFERROR(INDEX([5]Orçamento!$C$2:$ZZ$2,1,MATCH(CW$1,[5]Orçamento!$C$1:$ZZ$1,0)),0) + IFERROR(INDEX([6]Orçamento!$C$2:$ZZ$2,1,MATCH(CW$1,[6]Orçamento!$C$1:$ZZ$1,0)),0) + IFERROR(INDEX([7]Orçamento!$C$2:$ZZ$2,1,MATCH(CW$1,[7]Orçamento!$C$1:$ZZ$1,0)),0) + IFERROR(INDEX([8]Orçamento!$C$2:$ZZ$2,1,MATCH(CW$1,[8]Orçamento!$C$1:$ZZ$1,0)),0) -> 961730.62 | CX2: =IFERROR(INDEX([1]Orçamento!$C$2:$ZZ$2,1,MATCH(CX$1,[1]Orçamento!$C$1:$ZZ$1,0)),0) + IFERROR(INDEX([2]Orçamento!$C$2:$ZZ$2,1,MATCH(CX$1,[2]Orçamento!$C$1:$ZZ$1,0)),0) + IFERROR(INDEX([3]Orçamento!$C$2:$ZZ$2,1,MATCH(CX$1,[3]Orçamento!$C$1:$ZZ$1,0)),0) + IFERROR(INDEX([4]Orçamento!$C$2:$ZZ$2,1,MATCH(CX$1,[4]Orçamento!$C$1:$ZZ$1,0)),0) + IFERROR(INDEX([5]Orçamento!$C$2:$ZZ$2,1,MATCH(CX$1,[5]Orçamento!$C$1:$ZZ$1,0)),0) + IFERROR(INDEX([6]Orçamento!$C$2:$ZZ$2,1,MATCH(CX$1,[6]Orçamento!$C$1:$ZZ$1,0)),0) + IFERROR(INDEX([7]Orçamento!$C$2:$ZZ$2,1,MATCH(CX$1,[7]Orçamento!$C$1:$ZZ$1,0)),0) + IFERROR(INDEX([8]Orçamento!$C$2:$ZZ$2,1,MATCH(CX$1,[8]Orçamento!$C$1:$ZZ$1,0)),0) -> 961730.62 | CY2: =IFERROR(INDEX([1]Orçamento!$C$2:$ZZ$2,1,MATCH(CY$1,[1]Orçamento!$C$1:$ZZ$1,0)),0) + IFERROR(INDEX([2]Orçamento!$C$2:$ZZ$2,1,MATCH(CY$1,[2]Orçamento!$C$1:$ZZ$1,0)),0) + IFERROR(INDEX([3]Orçamento!$C$2:$ZZ$2,1,MATCH(CY$1,[3]Orçamento!$C$1:$ZZ$1,0)),0) + IFERROR(INDEX([4]Orçamento!$C$2:$ZZ$2,1,MATCH(CY$1,[4]Orçamento!$C$1:$ZZ$1,0)),0) + IFERROR(INDEX([5]Orçamento!$C$2:$ZZ$2,1,MATCH(CY$1,[5]Orçamento!$C$1:$ZZ$1,0)),0) + IFERROR(INDEX([6]Orçamento!$C$2:$ZZ$2,1,MATCH(CY$1,[6]Orçamento!$C$1:$ZZ$1,0)),0) + IFERROR(INDEX([7]Orçamento!$C$2:$ZZ$2,1,MATCH(CY$1,[7]Orçamento!$C$1:$ZZ$1,0)),0) + IFERROR(INDEX([8]Orçamento!$C$2:$ZZ$2,1,MATCH(CY$1,[8]Orçamento!$C$1:$ZZ$1,0)),0) -> 961730.62 | CZ2: =IFERROR(INDEX([1]Orçamento!$C$2:$ZZ$2,1,MATCH(CZ$1,[1]Orçamento!$C$1:$ZZ$1,0)),0) + IFERROR(INDEX([2]Orçamento!$C$2:$ZZ$2,1,MATCH(CZ$1,[2]Orçamento!$C$1:$ZZ$1,0)),0) + IFERROR(INDEX([3]Orçamento!$C$2:$ZZ$2,1,MATCH(CZ$1,[3]Orçamento!$C$1:$ZZ$1,0)),0) + IFERROR(INDEX([4]Orçamento!$C$2:$ZZ$2,1,MATCH(CZ$1,[4]Orçamento!$C$1:$ZZ$1,0)),0) + IFERROR(INDEX([5]Orçamento!$C$2:$ZZ$2,1,MATCH(CZ$1,[5]Orçamento!$C$1:$ZZ$1,0)),0) + IFERROR(INDEX([6]Orçamento!$C$2:$ZZ$2,1,MATCH(CZ$1,[6]Orçamento!$C$1:$ZZ$1,0)),0) + IFERROR(INDEX([7]Orçamento!$C$2:$ZZ$2,1,MATCH(CZ$1,[7]Orçamento!$C$1:$ZZ$1,0)),0) + IFERROR(INDEX([8]Orçamento!$C$2:$ZZ$2,1,MATCH(CZ$1,[8]Orçamento!$C$1:$ZZ$1,0)),0) -> 961730.62 | DA2: =IFERROR(INDEX([1]Orçamento!$C$2:$ZZ$2,1,MATCH(DA$1,[1]Orçamento!$C$1:$ZZ$1,0)),0) + IFERROR(INDEX([2]Orçamento!$C$2:$ZZ$2,1,MATCH(DA$1,[2]Orçamento!$C$1:$ZZ$1,0)),0) + IFERROR(INDEX([3]Orçamento!$C$2:$ZZ$2,1,MATCH(DA$1,[3]Orçamento!$C$1:$ZZ$1,0)),0) + IFERROR(INDEX([4]Orçamento!$C$2:$ZZ$2,1,MATCH(DA$1,[4]Orçamento!$C$1:$ZZ$1,0)),0) + IFERROR(INDEX([5]Orçamento!$C$2:$ZZ$2,1,MATCH(DA$1,[5]Orçamento!$C$1:$ZZ$1,0)),0) + IFERROR(INDEX([6]Orçamento!$C$2:$ZZ$2,1,MATCH(DA$1,[6]Orçamento!$C$1:$ZZ$1,0)),0) + IFERROR(INDEX([7]Orçamento!$C$2:$ZZ$2,1,MATCH(DA$1,[7]Orçamento!$C$1:$ZZ$1,0)),0) + IFERROR(INDEX([8]Orçamento!$C$2:$ZZ$2,1,MATCH(DA$1,[8]Orçamento!$C$1:$ZZ$1,0)),0) -> 961730.62 | DB2: =IFERROR(INDEX([1]Orçamento!$C$2:$ZZ$2,1,MATCH(DB$1,[1]Orçamento!$C$1:$ZZ$1,0)),0) + IFERROR(INDEX([2]Orçamento!$C$2:$ZZ$2,1,MATCH(DB$1,[2]Orçamento!$C$1:$ZZ$1,0)),0) + IFERROR(INDEX([3]Orçamento!$C$2:$ZZ$2,1,MATCH(DB$1,[3]Orçamento!$C$1:$ZZ$1,0)),0) + IFERROR(INDEX([4]Orçamento!$C$2:$ZZ$2,1,MATCH(DB$1,[4]Orçamento!$C$1:$ZZ$1,0)),0) + IFERROR(INDEX([5]Orçamento!$C$2:$ZZ$2,1,MATCH(DB$1,[5]Orçamento!$C$1:$ZZ$1,0)),0) + IFERROR(INDEX([6]Orçamento!$C$2:$ZZ$2,1,MATCH(DB$1,[6]Orçamento!$C$1:$ZZ$1,0)),0) + IFERROR(INDEX([7]Orçamento!$C$2:$ZZ$2,1,MATCH(DB$1,[7]Orçamento!$C$1:$ZZ$1,0)),0) + IFERROR(INDEX([8]Orçamento!$C$2:$ZZ$2,1,MATCH(DB$1,[8]Orçamento!$C$1:$ZZ$1,0)),0) -> 961730.62 | ... DF2: =IFERROR(INDEX([1]Orçamento!$C$2:$ZZ$2,1,MATCH(DF$1,[1]Orçamento!$C$1:$ZZ$1,0)),0) + IFERROR(INDEX([2]Orçamento!$C$2:$ZZ$2,1,MATCH(DF$1,[2]Orçamento!$C$1:$ZZ$1,0)),0) + IFERROR(INDEX([3]Orçamento!$C$2:$ZZ$2,1,MATCH(DF$1,[3]Orçamento!$C$1:$ZZ$1,0)),0) + IFERROR(INDEX([4]Orçamento!$C$2:$ZZ$2,1,MATCH(DF$1,[4]Orçamento!$C$1:$ZZ$1,0)),0) + IFERROR(INDEX([5]Orçamento!$C$2:$ZZ$2,1,MATCH(DF$1,[5]Orçamento!$C$1:$ZZ$1,0)),0) + IFERROR(INDEX([6]Orçamento!$C$2:$ZZ$2,1,MATCH(DF$1,[6]Orçamento!$C$1:$ZZ$1,0)),0) + IFERROR(INDEX([7]Orçamento!$C$2:$ZZ$2,1,MATCH(DF$1,[7]Orçamento!$C$1:$ZZ$1,0)),0) + IFERROR(INDEX([8]Orçamento!$C$2:$ZZ$2,1,MATCH(DF$1,[8]Orçamento!$C$1:$ZZ$1,0)),0) -> 961730.62 | DG2: =SUM(CT2:DF2) -> 47169630
B5: Resultado | C5: =C2-C8 -> -19000 | D5: =D2-D8 -> -56530.25 | E5: =E2-E8 -> -21480 | F5: =F2-F8 -> -41914.983 | G5: =G2-G8 -> -39608.399 | H5: =H2-H8 -> -20216.561 | I5: =I2-I8 -> -20216.561 | J5: =J2-J8 -> -20216.561 | ... S5: =S2-S8 -> -20516.561 | T5: =SUM(C5:S5) -> -423532.37 | U5: =U2-U8 -> -17529.653 | V5: =V2-V8 -> -17529.653 | W5: =W2-W8 -> -825144.9 | X5: =X2-X8 -> -31961.221 | Y5: =Y2-Y8 -> -29654.637 | Z5: =Z2-Z8 -> -10262.799 | AA5: =AA2-AA8 -> -10262.799 | AB5: =AB2-AB8 -> -29262.799 | ... AF5: =AF2-AF8 -> -35978.198 | AG5: =SUM(T5:AF5) -> -2330135.1 | AH5: =AH2-AH8 -> 8849.1951 | AI5: =AI2-AI8 -> 8849.1951 | AJ5: =AJ2-AJ8 -> -798766.05 | AK5: =AK2-AK8 -> -5582.3727 | AL5: =AL2-AL8 -> -3575.7889 | AM5: =AM2-AM8 -> 15816.049 | AN5: =AN2-AN8 -> 15816.049 | AO5: =AO2-AO8 -> -3183.9508 | ... AS5: =AS2-AS8 -> -9899.3502 | AT5: =SUM(AG5:AS5) -> -3922591.6 | AU5: =AU2-AU8 -> 72348.303 | AV5: =AV2-AV8 -> 72348.303 | AW5: =AW2-AW8 -> -740976.53 | AX5: =AX2-AX8 -> 52207.151 | AY5: =AY2-AY8 -> 54213.735 | AZ5: =AZ2-AZ8 -> 73605.573 | BA5: =BA2-BA8 -> 73605.573 | BB5: =BB2-BB8 -> 54605.573 | ... BF5: =BF2-BF8 -> 47890.173 | BG5: =SUM(AT5:BF5) -> -4810154.7 | BH5: =BH2-BH8 -> 165784.04 | BI5: =BI2-BI8 -> 165784.04 | BJ5: =BJ2-BJ8 -> -647540.79 | BK5: =BK2-BK8 -> 145642.89 | BL5: =BL2-BL8 -> 147649.47 | BM5: =BM2-BM8 -> 133127.67 | BN5: =BN2-BN8 -> 167041.31 | BO5: =BO2-BO8 -> 167041.31 | ... BS5: =BS2-BS8 -> 166741.31 | BT5: =SUM(BG5:BS5) -> -3698359.5 | BU5: =BU2-BU8 -> 312770.2 | BV5: =BV2-BV8 -> 312770.2 | BW5: =BW2-BW8 -> 301351.03 | BX5: =BX2-BX8 -> 301351.03 | BY5: =BY2-BY8 -> 301351.03 | BZ5: =BZ2-BZ8 -> 301351.03 | CA5: =CA2-CA8 -> 301351.03 | CB5: =CB2-CB8 -> 301351.03 | ... CF5: =CF2-CF8 -> 301351.03 | CG5: =SUM(BT5:CF5) -> -59308.818 | CH5: =CH2-CH8 -> 410666.09 | CI5: =CI2-CI8 -> 410666.09 | CJ5: =CJ2-CJ8 -> 410666.09 | CK5: =CK2-CK8 -> 410666.09 | CL5: =CL2-CL8 -> 410666.09 | CM5: =CM2-CM8 -> 383334.05 | CN5: =CN2-CN8 -> 410666.09 | CO5: =CO2-CO8 -> 410666.09 | ... CS5: =CS2-CS8 -> 410666.09 | CT5: =SUM(CG5:CS5) -> 4841352.3 | CU5: =CU2-CU8 -> 420790.99 | CV5: =CV2-CV8 -> 420790.99 | CW5: =CW2-CW8 -> 420790.99 | CX5: =CX2-CX8 -> 420790.99 | CY5: =CY2-CY8 -> 420790.99 | CZ5: =CZ2-CZ8 -> 420790.99 | DA5: =DA2-DA8 -> 420790.99 | DB5: =DB2-DB8 -> 420790.99 | ... DF5: =DF2-DF8 -> 420790.99 | DG5: =SUM(CT5:DF5) -> 9890844.1 | DH5: ='Capex Total '!B11 -> 3029888.1
B6: Margem | F6: =F5/F2 -> -17.081575 | G6: =G5/G2 -> -8.0707877 | H6: =H5/H2 -> -0.76483004 | I6: =I5/I2 -> -0.76483004 | J6: =J5/J2 -> -0.76483004 | K6: =K5/K2 -> -0.76483004 | L6: =L5/L2 -> -0.7761796 | M6: =M5/M2 -> -0.7761796 | ... DG6: =DG5/DG2 -> 0.2096867
