Workbook

Sheet Unidades
A1: Unidade | B1: Tipo | C1: Ano abertura
A2: Lab | B2: Lab | C2: 2026
A3: U2 | B3: Par | C3: 2028
A4: U3 | B4: Impar | C4: 2028
A5: U4 | B5: Par | C5: 2029
A6: U5 | B6: Impar | C6: 2029
A7: U6 | B7: Par | C7: 2030
A8: U7 | B8: Impar | C8: 2030
A9: U8 | B9: Par | C9: 2031

Sheet Base financeira
A1: Unidade | B1: Ano | C1: Receita | D1: Custos fixos | E1: Custos variáveis | F1: Resultado operacional | G1: Custos financeiros | H1: Lucro líquido | I1: Margem líquida | J1: Ocupação projetada | K1: Professores necessários (cenário médio)
A2: Lab | B2: 2026 | C2: =SUM([1]Orçamento!$F$2:$G$2) -> 7361.4375 | D2: =SUM([1]Orçamento!$C$10:$G$10)-SUM([1]Orçamento!$C$51:$G$51) -> 156494 | E2: =C2*'[1]Ocupação e unit economics 2.0'!$K$5 -> 699.33656 | F2: =C2-D2-E2 -> -149831.9 | G2: 0 | H2: =F2-G2 -> -149831.9 | I2: =H2/C2 -> -20.35362 | J2: 0.03 | K2: =ROUNDUP(('[1]Ocupação e unit economics 2.0'!$B$33*0.03)/'[1]Ocupação e unit economics 2.0'!$B$85,1) -> 8.9
A3: Lab | B3: 2027 | C3: =SUM([1]Orçamento!$H$2:$S$2) -> 317193 | D3: =SUM([1]Orçamento!$H$10:$S$10)-SUM([1]Orçamento!$H$51:$S$51) -> 530484 | E3: =C3*'[1]Ocupação e unit economics 2.0'!$K$5 -> 30133.335 | F3: =C3-D3-E3 -> -243424.34 | G3: 0 | H3: =F3-G3 -> -243424.34 | I3: =H3/C3 -> -0.76743287 | J3: 0.12 | K3: ='[1]Ocupação e unit economics 2.0'!$B$102 -> 36
A4: Lab | B4: 2028 | C4: =SUM([1]Orçamento!$U$2:$AF$2) -> 663262.5 | D4: =SUM([1]Orçamento!$U$10:$AF$10)-SUM([1]Orçamento!$U$51:$AF$51) -> 579699.6 | E4: =C4*'[1]Ocupação e unit economics 2.0'!$L$5 -> 131524.95 | F4: =C4-D4-E4 -> -47962.054 | G4: 0 | H4: =F4-G4 -> -47962.054 | I4: =H4/C4 -> -0.072312325 | J4: 0.25 | K4: ='[1]Ocupação e unit economics 2.0'!$C$102 -> 74
A5: Lab | B5: 2029 | C5: =SUM([1]Orçamento!$AH$2:$AS$2) -> 1061220 | D5: =SUM([1]Orçamento!$AH$10:$AS$10)-SUM([1]Orçamento!$AH$51:$AS$51) -> 638827.56 | E5: =C5*'[1]Ocupação e unit economics 2.0'!$L$5 -> 210439.93 | F5: =C5-D5-E5 -> 211952.51 | G5: 0 | H5: =F5-G5 -> 211952.51 | I5: =H5/C5 -> 0.19972533 | J5: 0.4 | K5: ='[1]Ocupação e unit economics 2.0'!$D$102 -> 119
A6: Lab | B6: 2030 | C6: =SUM([1]Orçamento!$AU$2:$BF$2) -> 1326525 | D6: =SUM([1]Orçamento!$AU$10:$BF$10)-SUM([1]Orçamento!$AU$51:$BF$51) -> 694382.32 | E6: =C6*'[1]Ocupação e unit economics 2.0'!$L$5 -> 263049.91 | F6: =C6-D6-E6 -> 369092.78 | G6: 0 | H6: =F6-G6 -> 369092.78 | I6: =H6/C6 -> 0.27824035 | J6: 0.5 | K6: ='[1]Ocupação e unit economics 2.0'!$E$102 -> 148
A7: Lab | B7: 2031 | C7: =SUM([1]Orçamento!$BH$2:$BS$2) -> 1591830 | D7: =SUM([1]Orçamento!$BH$10:$BS$10)-SUM([1]Orçamento!$BH$51:$BS$51) -> 768005.95 | E7: =C7*'[1]Ocupação e unit economics 2.0'!$L$5 -> 315659.89 | F7: =C7-D7-E7 -> 508164.16 | G7: 0 | H7: =F7-G7 -> 508164.16 | I7: =H7/C7 -> 0.31923268 | J7: 0.6 | K7: ='[1]Ocupação e unit economics 2.0'!$F$102 -> 178
A8: Lab | B8: 2032 | C8: =SUM([1]Orçamento!$BU$2:$CF$2) -> 1857135 | D8: =SUM([1]Orçamento!$BU$10:$CF$10)-SUM([1]Orçamento!$BU$51:$CF$51) -> 827337.4 | E8: =C8*'[1]Ocupação e unit economics 2.0'!$L$5 -> 368269.87 | F8: =C8-D8-E8 -> 661527.73 | G8: 0 | H8: =F8-G8 -> 661527.73 | I8: =H8/C8 -> 0.35620874 | J8: 0.7 | K8: ='[1]Ocupação e unit economics 2.0'!$G$102 -> 208
A9: Lab | B9: 2033 | C9: =SUM([1]Orçamento!$CH$2:$CS$2) -> 1857135 | D9: =SUM([1]Orçamento!$CH$10:$CS$10)-SUM([1]Orçamento!$CH$51:$CS$51) -> 892908.08 | E9: =C9*'[1]Ocupação e unit economics 2.0'!$L$5 -> 368269.87 | F9: =C9-D9-E9 -> 595957.05 | G9: 0 | H9: =F9-G9 -> 595957.05 | I9: =H9/C9 -> 0.32090131 | J9: 0.7 | K9: ='[1]Ocupação e unit economics 2.0'!$G$102 -> 208
A10: Lab | B10: 2034 | C10: =SUM([1]Orçamento!$CU$2:$DF$2) -> 1989787.5 | D10: =SUM([1]Orçamento!$CU$10:$DF$10)-SUM([1]Orçamento!$CU$51:$DF$51) -> 966535.83 | E10: =C10*'[1]Ocupação e unit economics 2.0'!$L$5 -> 394574.86 | F10: =C10-D10-E10 -> 628676.81 | G10: 0 | H10: =F10-G10 -> 628676.81 | I10: =H10/C10 -> 0.31595173 | J10: 0.75 | K10: ='[1]Ocupação e unit economics 2.0'!$H$102 -> 222
A11: U2 | B11: 2028 | C11: =SUM([2]Orçamento!$C$2:$N$2) -> 166859.25 | D11: =SUM([2]Orçamento!$C$10:$N$10)-SUM([2]Orçamento!$F$51:$N$51) -> 338763 | E11: =C11*'[1]Ocupação e unit economics 2.0'!$L$5 -> 33088.189 | F11: =C11-D11-E11 -> -204991.94 | G11: =('[3]Capex Total '!$C$2)*12 -> 184414.44 | H11: =F11-G11 -> -389406.38 | I11: =H11/C11 -> -2.3337416 | J11: 0.12 | K11: ='[1]Ocupação e unit economics 2.0'!$B$102 -> 36
A12: U2 | B12: 2029 | C12: =SUM([2]Orçamento!$U$2:$AF$2) -> 660818.75 | D12: =SUM([2]Orçamento!$U$10:$AF$10)-SUM([2]Orçamento!$U$51:$AF$51) -> 416739.6 | E12: =C12*'[1]Ocupação e unit economics 2.0'!$L$5 -> 131040.36 | F12: =C12-D12-E12 -> 113038.79 | G12: =G11 -> 184414.44 | H12: =F12-G12 -> -71375.648 | I12: =H12/C12 -> -0.10801093 | J12: 0.25 | K12: ='[1]Ocupação e unit economics 2.0'!$C$102 -> 74
A13: U2 | B13: 2030 | C13: =SUM([2]Orçamento!$AH$2:$AS$2) -> 1061220 | D13: =SUM([2]Orçamento!$AH$10:$AS$10)-SUM([2]Orçamento!$AH$51:$AS$51) -> 459571.56 | E13: =C13*'[1]Ocupação e unit economics 2.0'!$L$5 -> 210439.93 | F13: =C13-D13-E13 -> 391208.51 | G13: =G12 -> 184414.44 | H13: =F13-G13 -> 206794.07 | I13: =H13/C13 -> 0.19486447 | J13: 0.4 | K13: ='[1]Ocupação e unit economics 2.0'!$D$102 -> 119
A14: U2 | B14: 2031 | C14: =SUM([2]Orçamento!$AU$2:$BF$2) -> 1326525 | D14: =SUM([2]Orçamento!$AU$10:$BF$10)-SUM([2]Orçamento!$AU$51:$BF$51) -> 503800.72 | E14: =C14*'[1]Ocupação e unit economics 2.0'!$L$5 -> 263049.91 | F14: =C14-D14-E14 -> 559674.38 | G14: =G13 -> 184414.44 | H14: =F14-G14 -> 375259.94 | I14: =H14/C14 -> 0.28288946 | J14: 0.5 | K14: ='[1]Ocupação e unit economics 2.0'!$E$102 -> 148
A15: U2 | B15: 2032 | C15: =SUM([2]Orçamento!$BH$2:$BS$2) -> 1591830 | D15: =SUM([2]Orçamento!$BH$10:$BS$10)-SUM([2]Orçamento!$BH$51:$BS$51) -> 552008.79 | E15: =C15*'[1]Ocupação e unit economics 2.0'!$L$5 -> 315659.89 | F15: =C15-D15-E15 -> 724161.32 | G15: =G14 -> 184414.44 | H15: =F15-G15 -> 539746.88 | I15: =H15/C15 -> 0.33907319 | J15: 0.6 | K15: ='[1]Ocupação e unit economics 2.0'!$F$102 -> 178
A16: U2 | B16: 2033 | C16: =SUM([2]Orçamento!$BU$2:$CF$2) -> 1857135 | D16: =SUM([2]Orçamento!$BU$10:$CF$10)-SUM([2]Orçamento!$BU$51:$CF$51) -> 604593.67 | E16: =C16*'[1]Ocupação e unit economics 2.0'!$L$5 -> 368269.87 | F16: =C16-D16-E16 -> 884271.46 | G16: =G15 -> 184414.44 | H16: =F16-G16 -> 699857.02 | I16: =H16/C16 -> 0.37684768 | J16: 0.7 | K16: ='[1]Ocupação e unit economics 2.0'!$G$102 -> 208
A17: U2 | B17: 2034 | C17: =SUM([2]Orçamento!$CH$2:$CS$2) -> 1989787.5 | D17: =SUM([2]Orçamento!$CH$10:$CS$10)-SUM([2]Orçamento!$CH$51:$CS$51) -> 659773.03 | E17: =C17*'[1]Ocupação e unit economics 2.0'!$L$5 -> 394574.86 | F17: =C17-D17-E17 -> 935439.61 | G17: =G16 -> 184414.44 | H17: =F17-G17 -> 751025.17 | I17: =H17/C17 -> 0.37743989 | J17: 0.75 | K17: ='[1]Ocupação e unit economics 2.0'!$H$102 -> 222
A18: U3 | B18: 2028 | C18: =SUM([4]Orçamento!$C$2:$G$2) -> 7361.4375 | D18: =SUM([4]Orçamento!$C$10:$G$10)-SUM([4]Orçamento!$D$51:$G$51) -> 119414 | E18: =C18*'[1]Ocupação e unit economics 2.0'!$L$5 -> 1459.7731 | F18: =C18-D18-E18 -> -113512.34 | G18: =5*'[3]Capex Total '!$C$3 -> 74267.4 | H18: =F18-G18 -> -187779.74 | I18: =H18/C18 -> -25.508569 | J18: 0.03 | K18: =ROUNDUP(('[1]Ocupação e unit economics 2.0'!$B$33*0.03)/'[1]Ocupação e unit economics 2.0'!$B$85,1) -> 8.9
A19: U3 | B19: 2029 | C19: =SUM([4]Orçamento!$H$2:$S$2) -> 317193 | D19: =SUM([4]Orçamento!$H$10:$S$10)-SUM([4]Orçamento!$H$51:$S$51) -> 376884 | E19: =C19*'[1]Ocupação e unit economics 2.0'!$L$5 -> 62899.372 | F19: =C19-D19-E19 -> -122590.37 | G19: =12*'[3]Capex Total '!$C$3 -> 178241.76 | H19: =F19-G19 -> -300832.13 | I19: =H19/C19 -> -0.94841983 | J19: 0.12 | K19: ='[1]Ocupação e unit economics 2.0'!$B$102 -> 36
A20: U3 | B20: 2030 | C20: =SUM([4]Orçamento!$U$2:$AF$2) -> 663262.5 | D20: =SUM([4]Orçamento!$U$10:$AF$10)-SUM([4]Orçamento!$U$51:$AF$51) -> 416739.6 | E20: =C20*'[1]Ocupação e unit economics 2.0'!$L$5 -> 131524.95 | F20: =C20-D20-E20 -> 114997.95 | G20: =G19 -> 178241.76 | H20: =F20-G20 -> -63243.814 | I20: =H20/C20 -> -0.095352615 | J20: 0.25 | K20: ='[1]Ocupação e unit economics 2.0'!$C$102 -> 74
A21: U3 | B21: 2031 | C21: =SUM([4]Orçamento!$AH$2:$AS$2) -> 1061220 | D21: =SUM([4]Orçamento!$AH$10:$AS$10)-SUM([4]Orçamento!$AH$51:$AS$51) -> 459571.56 | E21: =C21*'[1]Ocupação e unit economics 2.0'!$L$5 -> 210439.93 | F21: =C21-D21-E21 -> 391208.51 | G21: =G20 -> 178241.76 | H21: =F21-G21 -> 212966.75 | I21: =H21/C21 -> 0.20068106 | J21: 0.4 | K21: ='[1]Ocupação e unit economics 2.0'!$D$102 -> 119
A22: U3 | B22: 2032 | C22: =SUM([4]Orçamento!$AU$2:$BF$2) -> 1326525 | D22: =SUM([4]Orçamento!$AU$10:$BF$10)-SUM([4]Orçamento!$AU$51:$BF$51) -> 503800.72 | E22: =C22*'[1]Ocupação e unit economics 2.0'!$L$5 -> 263049.91 | F22: =C22-D22-E22 -> 559674.38 | G22: =G21 -> 178241.76 | H22: =F22-G22 -> 381432.62 | I22: =H22/C22 -> 0.28754273 | J22: 0.5 | K22: ='[1]Ocupação e unit economics 2.0'!$E$102 -> 148
A23: U3 | B23: 2033 | C23: =SUM([4]Orçamento!$BH$2:$BS$2) -> 1591830 | D23: =SUM([4]Orçamento!$BH$10:$BS$10)-SUM([4]Orçamento!$BH$51:$BS$51) -> 552008.79 | E23: =C23*'[1]Ocupação e unit economics 2.0'!$L$5 -> 315659.89 | F23: =C23-D23-E23 -> 724161.32 | G23: =G22 -> 178241.76 | H23: =F23-G23 -> 545919.56 | I23: =H23/C23 -> 0.34295092 | J23: 0.6 | K23: ='[1]Ocupação e unit economics 2.0'!$F$102 -> 178
A24: U3 | B24: 2034 | C24: =SUM([4]Orçamento!$BU$2:$CF$2) -> 1857135 | D24: =SUM([4]Orçamento!$BU$10:$CF$10)-SUM([4]Orçamento!$BU$51:$CF$51) -> 604593.67 | E24: =C24*'[1]Ocupação e unit economics 2.0'!$L$5 -> 368269.87 | F24: =C24-D24-E24 -> 884271.46 | G24: =G23 -> 178241.76 | H24: =F24-G24 -> 706029.7 | I24: =H24/C24 -> 0.38017145 | J24: 0.7 | K24: ='[1]Ocupação e unit economics 2.0'!$G$102 -> 208
A25: U4 | B25: 2029 | C25: =SUM([5]Orçamento!$C$2:$N$2) -> 192390.69 | D25: =SUM([5]Orçamento!$C$10:$N$10)-SUM([5]Orçamento!$D$51:$N$51) -> 338763 | E25: =C25*'[1]Ocupação e unit economics 2.0'!$L$5 -> 38151.073 | F25: =C25-D25-E25 -> -184523.39 | G25: =12*'[3]Capex Total '!$C$4 -> 178241.76 | H25: =F25-G25 -> -362765.15 | I25: =H25/C25 -> -1.885565 | J25: 0.12 | K25: ='[1]Ocupação e unit economics 2.0'!$B$102 -> 36
A26: U4 | B26: 2030 | C26: =SUM([5]Orçamento!$U$2:$AF$2) -> 663262.5 | D26: =SUM([5]Orçamento!$U$10:$AF$10)-SUM([5]Orçamento!$U$51:$AF$51) -> 416739.6 | E26: =C26*'[1]Ocupação e unit economics 2.0'!$L$5 -> 131524.95 | F26: =C26-D26-E26 -> 114997.95 | G26: =G25 -> 178241.76 | H26: =F26-G26 -> -63243.814 | I26: =H26/C26 -> -0.095352615 | J26: 0.25 | K26: ='[1]Ocupação e unit economics 2.0'!$C$102 -> 74
A27: U4 | B27: 2031 | C27: =SUM([5]Orçamento!$AH$2:$AS$2) -> 1061220 | D27: =SUM([5]Orçamento!$AH$10:$AS$10)-SUM([5]Orçamento!$AH$51:$AS$51) -> 459571.56 | E27: =C27*'[1]Ocupação e unit economics 2.0'!$L$5 -> 210439.93 | F27: =C27-D27-E27 -> 391208.51 | G27: =G26 -> 178241.76 | H27: =F27-G27 -> 212966.75 | I27: =H27/C27 -> 0.20068106 | J27: 0.4 | K27: ='[1]Ocupação e unit economics 2.0'!$D$102 -> 119
A28: U4 | B28: 2032 | C28: =SUM([5]Orçamento!$AU$2:$BF$2) -> 1326525 | D28: =SUM([5]Orçamento!$AU$10:$BF$10)-SUM([5]Orçamento!$AU$51:$BF$51) -> 503800.72 | E28: =C28*'[1]Ocupação e unit economics 2.0'!$L$5 -> 263049.91 | F28: =C28-D28-E28 -> 559674.38 | G28: =G27 -> 178241.76 | H28: =F28-G28 -> 381432.62 | I28: =H28/C28 -> 0.28754273 | J28: 0.5 | K28: ='[1]Ocupação e unit economics 2.0'!$E$102 -> 148
A29: U4 | B29: 2033 | C29: =SUM([5]Orçamento!$BH$2:$BS$2) -> 1591830 | D29: =SUM([5]Orçamento!$BH$10:$BS$10)-SUM([5]Orçamento!$BH$51:$BS$51) -> 552008.79 | E29: =C29*'[1]Ocupação e unit economics 2.0'!$L$5 -> 315659.89 | F29: =C29-D29-E29 -> 724161.32 | G29: =G28 -> 178241.76 | H29: =F29-G29 -> 545919.56 | I29: =H29/C29 -> 0.34295092 | J29: 0.6 | K29: ='[1]Ocupação e unit economics 2.0'!$F$102 -> 178
A30: U4 | B30: 2034 | C30: =SUM([5]Orçamento!$BU$2:$CF$2) -> 1857135 | D30: =SUM([5]Orçamento!$BU$10:$CF$10)-SUM([5]Orçamento!$BU$51:$CF$51) -> 604593.67 | E30: =C30*'[1]Ocupação e unit economics 2.0'!$L$5 -> 368269.87 | F30: =C30-D30-E30 -> 884271.46 | G30: =G29 -> 178241.76 | H30: =F30-G30 -> 706029.7 | I30: =H30/C30 -> 0.38017145 | J30: 0.7 | K30: ='[1]Ocupação e unit economics 2.0'!$G$102 -> 208
A31: U5 | B31: 2029 | C31: =SUM([6]Orçamento!$C$2:$G$2) -> 7361.4375 | D31: =SUM([6]Orçamento!$C$10:$G$10)-SUM([6]Orçamento!$C$51:$G$51) -> 119414 | E31: =C31*'[1]Ocupação e unit economics 2.0'!$L$5 -> 1459.7731 | F31: =C31-D31-E31 -> -113512.34 | G31: =5*'[3]Capex Total '!$C$5 -> 74267.4 | H31: =F31-G31 -> -187779.74 | I31: =H31/C31 -> -25.508569 | J31: 0.03 | K31: =ROUNDUP(('[1]Ocupação e unit economics 2.0'!$B$33*0.03)/'[1]Ocupação e unit economics 2.0'!$B$85,1) -> 8.9
A32: U5 | B32: 2030 | C32: =SUM([6]Orçamento!$H$2:$S$2) -> 317193 | D32: =SUM([6]Orçamento!$H$10:$S$10)-SUM([6]Orçamento!$H$51:$S$51) -> 376884 | E32: =C32*'[1]Ocupação e unit economics 2.0'!$L$5 -> 62899.372 | F32: =C32-D32-E32 -> -122590.37 | G32: =12*'[3]Capex Total '!$C$5 -> 178241.76 | H32: =F32-G32 -> -300832.13 | I32: =H32/C32 -> -0.94841983 | J32: 0.12 | K32: ='[1]Ocupação e unit economics 2.0'!$B$102 -> 36
A33: U5 | B33: 2031 | C33: =SUM([6]Orçamento!$U$2:$AF$2) -> 663262.5 | D33: =SUM([6]Orçamento!$U$10:$AF$10)-SUM([6]Orçamento!$U$51:$AF$51) -> 416739.6 | E33: =C33*'[1]Ocupação e unit economics 2.0'!$L$5 -> 131524.95 | F33: =C33-D33-E33 -> 114997.95 | G33: =G32 -> 178241.76 | H33: =F33-G33 -> -63243.814 | I33: =H33/C33 -> -0.095352615 | J33: 0.25 | K33: ='[1]Ocupação e unit economics 2.0'!$C$102 -> 74
A34: U5 | B34: 2032 | C34: =SUM([6]Orçamento!$AH$2:$AS$2) -> 1061220 | D34: =SUM([6]Orçamento!$AH$10:$AS$10)-SUM([6]Orçamento!$AH$51:$AS$51) -> 459571.56 | E34: =C34*'[1]Ocupação e unit economics 2.0'!$L$5 -> 210439.93 | F34: =C34-D34-E34 -> 391208.51 | G34: =G33 -> 178241.76 | H34: =F34-G34 -> 212966.75 | I34: =H34/C34 -> 0.20068106 | J34: 0.4 | K34: ='[1]Ocupação e unit economics 2.0'!$D$102 -> 119
A35: U5 | B35: 2033 | C35: =SUM([6]Orçamento!$AU$2:$BF$2) -> 1326525 | D35: =SUM([6]Orçamento!$AU$10:$BF$10)-SUM([6]Orçamento!$AU$51:$BF$51) -> 503800.72 | E35: =C35*'[1]Ocupação e unit economics 2.0'!$L$5 -> 263049.91 | F35: =C35-D35-E35 -> 559674.38 | G35: =G34 -> 178241.76 | H35: =F35-G35 -> 381432.62 | I35: =H35/C35 -> 0.28754273 | J35: 0.5 | K35: ='[1]Ocupação e unit economics 2.0'!$E$102 -> 148
A36: U5 | B36: 2034 | C36: =SUM([6]Orçamento!$BH$2:$BS$2) -> 1591830 | D36: =SUM([6]Orçamento!$BH$10:$BS$10)-SUM([6]Orçamento!$BH$51:$BS$51) -> 552008.79 | E36: =C36*'[1]Ocupação e unit economics 2.0'!$L$5 -> 315659.89 | F36: =C36-D36-E36 -> 724161.32 | G36: =G35 -> 178241.76 | H36: =F36-G36 -> 545919.56 | I36: =H36/C36 -> 0.34295092 | J36: 0.6 | K36: ='[1]Ocupação e unit economics 2.0'!$F$102 -> 178
A37: U6 | B37: 2030 | C37: =SUM([7]Orçamento!$C$2:$N$2) -> 192390.69 | D37: =SUM([7]Orçamento!$C$10:$N$10)-SUM([7]Orçamento!$F$51:$N$51) -> 338763 | E37: =C37*'[1]Ocupação e unit economics 2.0'!$L$5 -> 38151.073 | F37: =C37-D37-E37 -> -184523.39 | G37: =12*'[3]Capex Total '!$C$6 -> 178241.76 | H37: =F37-G37 -> -362765.15 | I37: =H37/C37 -> -1.885565 | J37: 0.12 | K37: ='[1]Ocupação e unit economics 2.0'!$B$102 -> 36
A38: U6 | B38: 2031 | C38: =SUM([7]Orçamento!$U$2:$AF$2) -> 663262.5 | D38: =SUM([7]Orçamento!$U$10:$AF$10)-SUM([7]Orçamento!$U$51:$AF$51) -> 416739.6 | E38: =C38*'[1]Ocupação e unit economics 2.0'!$L$5 -> 131524.95 | F38: =C38-D38-E38 -> 114997.95 | G38: =G37 -> 178241.76 | H38: =F38-G38 -> -63243.814 | I38: =H38/C38 -> -0.095352615 | J38: 0.25 | K38: ='[1]Ocupação e unit economics 2.0'!$C$102 -> 74
A39: U6 | B39: 2032 | C39: =SUM([7]Orçamento!$AH$2:$AS$2) -> 1061220 | D39: =SUM([7]Orçamento!$AH$10:$AS$10)-SUM([7]Orçamento!$AH$51:$AS$51) -> 459571.56 | E39: =C39*'[1]Ocupação e unit economics 2.0'!$L$5 -> 210439.93 | F39: =C39-D39-E39 -> 391208.51 | G39: =G38 -> 178241.76 | H39: =F39-G39 -> 212966.75 | I39: =H39/C39 -> 0.20068106 | J39: 0.4 | K39: ='[1]Ocupação e unit economics 2.0'!$D$102 -> 119
A40: U6 | B40: 3033 | C40: =SUM([7]Orçamento!$AU$2:$BF$2) -> 1326525 | D40: =SUM([7]Orçamento!$AU$10:$BF$10)-SUM([7]Orçamento!$AU$51:$BF$51) -> 503800.72 | E40: =C40*'[1]Ocupação e unit economics 2.0'!$L$5 -> 263049.91 | F40: =C40-D40-E40 -> 559674.38 | G40: =G39 -> 178241.76 | H40: =F40-G40 -> 381432.62 | I40: =H40/C40 -> 0.28754273 | J40: 0.5 | K40: ='[1]Ocupação e unit economics 2.0'!$E$102 -> 148
...

Sheet Unit economics anual
A1: Ano | B1: Métrica | C1: Valor
A2: 1 | B2: Margem de contribuição | C2: ='[1]Ocupação e unit economics 2.0'!$B$70 -> 0.905
A3: 2 | B3: Margem de contribuição | C3: ='[1]Ocupação e unit economics 2.0'!$C$70 -> 0.8017
A4: 3 | B4: Margem de contribuição | C4: ='[1]Ocupação e unit economics 2.0'!$D$70 -> 0.8017
A5: 4 | B5: Margem de contribuição | C5: ='[1]Ocupação e unit economics 2.0'!$E$70 -> 0.8017
A6: 5 | B6: Margem de contribuição | C6: ='[1]Ocupação e unit economics 2.0'!$F$70 -> 0.8017
A7: 6 | B7: Margem de contribuição | C7: ='[1]Ocupação e unit economics 2.0'!$G$70 -> 0.8017
A8: 7 | B8: Margem de contribuição | C8: ='[1]Ocupação e unit economics 2.0'!$G$70 -> 0.8017
A9: 8 | B9: Margem de contribuição | C9: ='[1]Ocupação e unit economics 2.0'!$H$70 -> 0.8017
A10: 1 | B10: Ponto de equilíbrio | C10: ='[1]Ocupação e unit economics 2.0'!$B$71 -> 48771.492
A11: 2 | B11: Ponto de equilíbrio | C11: ='[1]Ocupação e unit economics 2.0'!$C$71 -> 60148.06
A12: 3 | B12: Ponto de equilíbrio | C12: ='[1]Ocupação e unit economics 2.0'!$D$71 -> 66415.405
A13: 4 | B13: Ponto de equilíbrio | C13: ='[1]Ocupação e unit economics 2.0'!$E$71 -> 72259.814
A14: 5 | B14: Ponto de equilíbrio | C14: ='[1]Ocupação e unit economics 2.0'!$F$71 -> 79259.427
A15: 6 | B15: Ponto de equilíbrio | C15: ='[1]Ocupação e unit economics 2.0'!$G$71 -> 86210.092
A16: 7 | B16: Ponto de equilíbrio | C16: ='[1]Ocupação e unit economics 2.0'!$G$71 -> 86210.092
A17: 8 | B17: Ponto de equilíbrio | C17: ='[1]Ocupação e unit economics 2.0'!$H$71 -> 94268.422
A18: 1 | B18: Ocupação necessária para breakeven | C18: ='[1]Ocupação e unit economics 2.0'!$B$73 -> 0.22059814
A19: 2 | B19: Ocupação necessária para breakeven | C19: ='[1]Ocupação e unit economics 2.0'!$C$73 -> 0.27205545
A20: 3 | B20: Ocupação necessária para breakeven | C20: ='[1]Ocupação e unit economics 2.0'!$D$73 -> 0.30040326
A21: 4 | B21: Ocupação necessária para breakeven | C21: ='[1]Ocupação e unit economics 2.0'!$E$73 -> 0.32683808
A22: 5 | B22: Ocupação necessária para breakeven | C22: ='[1]Ocupação e unit economics 2.0'!$F$73 -> 0.358498
A23: 6 | B23: Ocupação necessária para breakeven | C23: ='[1]Ocupação e unit economics 2.0'!$G$73 -> 0.38993653
A24: 7 | B24: Ocupação necessária para breakeven | C24: ='[1]Ocupação e unit economics 2.0'!$G$73 -> 0.38993653
A25: 8 | B25: Ocupação necessária para breakeven | C25: ='[1]Ocupação e unit economics 2.0'!$H$73 -> 0.42638513
A26: 1 | B26: Aulas vendidas necessárias para breakeven | C26: ='[1]Ocupação e unit economics 2.0'!$B$72 -> 848.19986
A27: 2 | B27: Aulas vendidas necessárias para breakeven | C27: ='[1]Ocupação e unit economics 2.0'!$C$72 -> 1046.0532
A28: 3 | B28: Aulas vendidas necessárias para breakeven | C28: ='[1]Ocupação e unit economics 2.0'!$D$72 -> 1155.0505
A29: 4 | B29: Aulas vendidas necessárias para breakeven | C29: ='[1]Ocupação e unit economics 2.0'!$E$72 -> 1256.6924
A30: 5 | B30: Aulas vendidas necessárias para breakeven | C30: ='[1]Ocupação e unit economics 2.0'!$F$72 -> 1378.4248
A31: 6 | B31: Aulas vendidas necessárias para breakeven | C31: ='[1]Ocupação e unit economics 2.0'!$G$72 -> 1499.3059
A32: 7 | B32: Aulas vendidas necessárias para breakeven | C32: ='[1]Ocupação e unit economics 2.0'!$G$72 -> 1499.3059
A33: 8 | B33: Aulas vendidas necessárias para breakeven | C33: ='[1]Ocupação e unit economics 2.0'!$H$72 -> 1639.4508
A34: 1 | B34: Professores necessários para breakeven (média) | C34: ='[1]Ocupação e unit economics 2.0'!$B$91 -> 66
A35: 2 | B35: Professores necessários para breakeven (média) | C35: ='[1]Ocupação e unit economics 2.0'!$C$91 -> 81
A36: 3 | B36: Professores necessários para breakeven (média) | C36: ='[1]Ocupação e unit economics 2.0'!$D$91 -> 89
A37: 4 | B37: Professores necessários para breakeven (média) | C37: ='[1]Ocupação e unit economics 2.0'!$E$91 -> 97
A38: 5 | B38: Professores necessários para breakeven (média) | C38: ='[1]Ocupação e unit economics 2.0'!$F$91 -> 107
A39: 6 | B39: Professores necessários para breakeven (média) | C39: ='[1]Ocupação e unit economics 2.0'!$G$91 -> 116
A40: 7 | B40: Professores necessários para breakeven (média) | C40: ='[1]Ocupação e unit economics 2.0'!$G$91 -> 116
...

Sheet Unit economics (fixos)
A1: Métricas | B1: Valores
A2: Capacidade de aulas por mês | B2: ='[1]Ocupação e unit economics 2.0'!$B$33 -> 3845
A3: Preço médio por aula | B3: ='[1]Ocupação e unit economics 2.0'!$B$63 -> 57.5
A4: Capacidade de receita mensal | B4: =B2*B3 -> 221087.5
A5: Capacidade de receita anual | B5: =12*B4 -> 2653050
A6: Capacidade mensal de aulas por professor (média) | B6: ='[1]Ocupação e unit economics 2.0'!$B$85 -> 12.99
A7: Alunos por professor (média) | B7: ='[1]Ocupação e unit economics 2.0'!$B$81 -> 1.5
