Workbook

Sheet Orçamento
A1: Item | B1: Receita | C1: 46235 | D1: 46266 | E1: 46296 | F1: 46327 | G1: 46357 | H1: 46388 | I1: 46419 | J1: 46447 | K1: 46478 | L1: 46508 | M1: 46539 | N1: 46569 | O1: 46600 | P1: 46631 | Q1: 46661 | R1: 46692 | S1: 46722 | T1: Total Acumulado Ano 1 | U1: 46753 | V1: 46784 | W1: 46813 | X1: 46844 | Y1: 46874 | Z1: 46905 | AA1: 46935 | AB1: 46966 | AC1: 46997 | AD1: 47027 | AE1: 47058 | AF1: 47088 | AG1: Total Acumulado Ano 2 | AH1: 47119 | AI1: 47150 | AJ1: 47178 | AK1: 47209 | AL1: 47239 | AM1: 47270 | AN1: 47300 | AO1: 47331 | AP1: 47362 | AQ1: 47392 | AR1: 47423 | AS1: 47453 | AT1: Total Acumulado Ano 3 | AU1: 47484 | AV1: 47515 | AW1: 47543 | AX1: 47574 | AY1: 47604 | AZ1: 47635 | BA1: 47665 | BB1: 47696 | BC1: 47727 | BD1: 47757 | BE1: 47788 | BF1: 47818 | BG1: Total Acumulado Ano 4 | BH1: 47849 | BI1: 47880 | BJ1: 47908 | BK1: 47939 | BL1: 47969 | BM1: 48000 | BN1: 48030 | BO1: 48061 | BP1: 48092 | BQ1: 48122 | BR1: 48153 | BS1: 48183 | BT1: Total Acumulado Ano 5 | BU1: 48214 | BV1: 48245 | BW1: 48274 | BX1: 48305 | BY1: 48335 | BZ1: 48366 | CA1: 48396 | CB1: 48427 | CC1: 48458 | CD1: 48488 | CE1: 48519 | CF1: 48549 | CG1: Total Acumulado Ano 6 | CH1: 48580 | CI1: 48611 | CJ1: 48639 | CK1: 48670 | CL1: 48700 | CM1: 48731 | CN1: 48761 | CO1: 48792 | CP1: 48823 | CQ1: 48853 | CR1: 48884 | CS1: 48914 | CT1: Total Acumulado Ano 7 | CU1: 48945 | CV1: 48976 | CW1: 49004 | CX1: 49035 | CY1: 49065 | CZ1: 49096 | DA1: 49126 | DB1: 49157 | DC1: 49188 | DD1: 49218 | DE1: 49249 | DF1: 49279 | DG1: Total Acumulado Ano 8
A2: 1 | B2: RECEITATtOTAL | C2: 0 | D2: 0 | E2: 0 | F2: =('Cálcul. trabalhado'!I3)/2 -> 2453.8125 | G2: =F2*2 -> 4907.625 | H2: ='Cálcul. trabalhado'!I4 -> 26432.75 | I2: =H2 -> 26432.75 | J2: =I2 -> 26432.75 | K2: =J2 -> 26432.75 | L2: =K2 -> 26432.75 | M2: =L2 -> 26432.75 | N2: =M2 -> 26432.75 | O2: =N2 -> 26432.75 | P2: =O2 -> 26432.75 | ... S2: =R2 -> 26432.75 | T2: =SUM(F2:S2) -> 324554.44 | U2: ='Cálcul. trabalhado'!I5 -> 55271.875 | V2: =U2 -> 55271.875 | W2: =V2 -> 55271.875 | X2: =W2 -> 55271.875 | Y2: =X2 -> 55271.875 | Z2: =Y2 -> 55271.875 | AA2: =Z2 -> 55271.875 | AB2: =AA2 -> 55271.875 | AC2: =AB2 -> 55271.875 | ... AF2: =AE2 -> 55271.875 | AG2: =SUM(T2:AF2) -> 987816.94 | AH2: ='Cálcul. trabalhado'!I6 -> 88435 | AI2: =AH2 -> 88435 | AJ2: =AI2 -> 88435 | AK2: =AJ2 -> 88435 | AL2: =AK2 -> 88435 | AM2: =AL2 -> 88435 | AN2: =AM2 -> 88435 | AO2: =AN2 -> 88435 | AP2: =AO2 -> 88435 | ... AS2: =AR2 -> 88435 | AT2: =SUM(AG2:AS2) -> 2049036.9 | AU2: ='Cálcul. trabalhado'!I7 -> 110543.75 | AV2: =AU2 -> 110543.75 | AW2: =AV2 -> 110543.75 | AX2: =AW2 -> 110543.75 | AY2: =AX2 -> 110543.75 | AZ2: =AY2 -> 110543.75 | BA2: =AZ2 -> 110543.75 | BB2: =BA2 -> 110543.75 | BC2: =BB2 -> 110543.75 | ... BF2: =BE2 -> 110543.75 | BG2: =SUM(AT2:BF2) -> 3375561.9 | BH2: ='Cálcul. trabalhado'!I8 -> 132652.5 | BI2: =BH2 -> 132652.5 | BJ2: =BI2 -> 132652.5 | BK2: =BJ2 -> 132652.5 | BL2: =BK2 -> 132652.5 | BM2: =BL2 -> 132652.5 | BN2: =BM2 -> 132652.5 | BO2: =BN2 -> 132652.5 | BP2: =BO2 -> 132652.5 | ... BS2: =BR2 -> 132652.5 | BT2: =SUM(BG2:BS2) -> 4967391.9 | BU2: ='Cálcul. trabalhado'!I9 -> 154761.25 | BV2: =BU2 -> 154761.25 | BW2: =BV2 -> 154761.25 | BX2: =BW2 -> 154761.25 | BY2: =BX2 -> 154761.25 | BZ2: =BY2 -> 154761.25 | CA2: =BZ2 -> 154761.25 | CB2: =CA2 -> 154761.25 | CC2: =CB2 -> 154761.25 | ... CF2: =CE2 -> 154761.25 | CG2: =SUM(BT2:CF2) -> 6824526.9 | CH2: ='Cálcul. trabalhado'!I9 -> 154761.25 | CI2: =CH2 -> 154761.25 | CJ2: =CI2 -> 154761.25 | CK2: =CJ2 -> 154761.25 | CL2: =CK2 -> 154761.25 | CM2: =CL2 -> 154761.25 | CN2: =CM2 -> 154761.25 | CO2: =CN2 -> 154761.25 | CP2: =CO2 -> 154761.25 | ... CS2: =CR2 -> 154761.25 | CT2: =SUM(CG2:CS2) -> 8681661.9 | CU2: ='Cálcul. trabalhado'!I10 -> 165815.62 | CV2: =CU2 -> 165815.62 | CW2: =CV2 -> 165815.62 | CX2: =CW2 -> 165815.62 | CY2: =CX2 -> 165815.62 | CZ2: =CY2 -> 165815.62 | DA2: =CZ2 -> 165815.62 | DB2: =DA2 -> 165815.62 | DC2: =DB2 -> 165815.62 | ... DF2: =DE2 -> 165815.62 | DG2: =SUM(CT2:DF2) -> 10671449
B5: Resultado | C5: =C2-C8 -> -19000 | D5: =D2-D8 -> -28000 | E5: =E2-E8 -> -21480 | F5: =F2-F8 -> -41914.983 | G5: =G2-G8 -> -39608.399 | H5: =H2-H8 -> -20216.561 | I5: =I2-I8 -> -20216.561 | J5: =J2-J8 -> -20216.561 | ... S5: =S2-S8 -> -20516.561 | T5: =SUM(C5:S5) -> -395002.12 | U5: =U2-U8 -> 1470.3469 | V5: =V2-V8 -> 1470.3469 | W5: =W2-W8 -> -4239.2378 | X5: =X2-X8 -> -4239.2378 | Y5: =Y2-Y8 -> -4239.2378 | Z5: =Z2-Z8 -> -4239.2378 | AA5: =AA2-AA8 -> -4239.2378 | AB5: =AB2-AB8 -> -4239.2378 | ... AF5: =AF2-AF8 -> -4239.2378 | AG5: =SUM(T5:AF5) -> -434453.8 | AH5: =AH2-AH8 -> 17290.109 | AI5: =AI2-AI8 -> 17290.109 | AJ5: =AJ2-AJ8 -> 17290.109 | AK5: =AK2-AK8 -> 17290.109 | AL5: =AL2-AL8 -> 17290.109 | AM5: =AM2-AM8 -> 17290.109 | AN5: =AN2-AN8 -> 17290.109 | AO5: =AO2-AO8 -> 17290.109 | ... AS5: =AS2-AS8 -> 17290.109 | AT5: =SUM(AG5:AS5) -> -226972.49 | AU5: =AU2-AU8 -> 30292.931 | AV5: =AV2-AV8 -> 30292.931 | AW5: =AW2-AW8 -> 30292.931 | AX5: =AX2-AX8 -> 30292.931 | AY5: =AY2-AY8 -> 30292.931 | AZ5: =AZ2-AZ8 -> 30292.931 | BA5: =BA2-BA8 -> 30292.931 | BB5: =BB2-BB8 -> 30292.931 | ... BF5: =BF2-BF8 -> 30292.931 | BG5: =SUM(AT5:BF5) -> 136542.69 | BH5: =BH2-BH8 -> 41786.213 | BI5: =BI2-BI8 -> 41786.213 | BJ5: =BJ2-BJ8 -> 41786.213 | BK5: =BK2-BK8 -> 41786.213 | BL5: =BL2-BL8 -> 41786.213 | BM5: =BM2-BM8 -> 41786.213 | BN5: =BN2-BN8 -> 41786.213 | BO5: =BO2-BO8 -> 41786.213 | ... BS5: =BS2-BS8 -> 41786.213 | BT5: =SUM(BG5:BS5) -> 637977.25 | BU5: =BU2-BU8 -> 54474.311 | BV5: =BV2-BV8 -> 54474.311 | BW5: =BW2-BW8 -> 54474.311 | BX5: =BX2-BX8 -> 54474.311 | BY5: =BY2-BY8 -> 54474.311 | BZ5: =BZ2-BZ8 -> 54474.311 | CA5: =CA2-CA8 -> 54474.311 | CB5: =CB2-CB8 -> 54474.311 | ... CF5: =CF2-CF8 -> 54474.311 | CG5: =SUM(BT5:CF5) -> 1291669 | CH5: =CH2-CH8 -> 49010.087 | CI5: =CI2-CI8 -> 49010.087 | CJ5: =CJ2-CJ8 -> 49010.087 | CK5: =CK2-CK8 -> 49010.087 | CL5: =CL2-CL8 -> 49010.087 | CM5: =CM2-CM8 -> 49010.087 | CN5: =CN2-CN8 -> 49010.087 | CO5: =CO2-CO8 -> 49010.087 | ... CS5: =CS2-CS8 -> 49010.087 | CT5: =SUM(CG5:CS5) -> 1879790 | CU5: =CU2-CU8 -> 51682.534 | CV5: =CV2-CV8 -> 51682.534 | CW5: =CW2-CW8 -> 51682.534 | CX5: =CX2-CX8 -> 51682.534 | CY5: =CY2-CY8 -> 51682.534 | CZ5: =CZ2-CZ8 -> 51682.534 | DA5: =DA2-DA8 -> 51682.534 | DB5: =DB2-DB8 -> 51682.534 | ... DF5: =DF2-DF8 -> 51682.534 | DG5: =SUM(CT5:DF5) -> 2499980.4
B6: Margem | F6: =F5/F2 -> -17.081575 | G6: =G5/G2 -> -8.0707877 | H6: =H5/H2 -> -0.76483004 | I6: =I5/I2 -> -0.76483004 | J6: =J5/J2 -> -0.76483004 | K6: =K5/K2 -> -0.76483004 | L6: =L5/L2 -> -0.7761796 | M6: =M5/M2 -> -0.7761796 | ... S6: =S5/S2 -> -0.7761796 | U6: =U5/U2 -> 0.026602081 | V6: =V5/V2 -> 0.026602081 | W6: =W5/W2 -> -0.076697919 | X6: =X5/X2 -> -0.076697919 | Y6: =Y5/Y2 -> -0.076697919 | Z6: =Z5/Z2 -> -0.076697919 | AA6: =AA5/AA2 -> -0.076697919 | AB6: =AB5/AB2 -> -0.076697919 | ... AF6: =AF5/AF2 -> -0.076697919 | AH6: =AH5/AH2 -> 0.19551207 | AI6: =AI5/AI2 -> 0.19551207 | AJ6: =AJ5/AJ2 -> 0.19551207 | AK6: =AK5/AK2 -> 0.19551207 | AL6: =AL5/AL2 -> 0.19551207 | AM6: =AM5/AM2 -> 0.19551207 | AN6: =AN5/AN2 -> 0.19551207 | AO6: =AO5/AO2 -> 0.19551207 | ... AS6: =AS5/AS2 -> 0.19551207 | AU6: =AU5/AU2 -> 0.27403568 | AV6: =AV5/AV2 -> 0.27403568 | AW6: =AW5/AW2 -> 0.27403568 | AX6: =AX5/AX2 -> 0.27403568 | AY6: =AY5/AY2 -> 0.27403568 | AZ6: =AZ5/AZ2 -> 0.27403568 | BA6: =BA5/BA2 -> 0.27403568 | BB6: =BB5/BB2 -> 0.27403568 | ... BF6: =BF5/BF2 -> 0.27403568 | BH6: =BH5/BH2 -> 0.31500509 | BI6: =BI5/BI2 -> 0.31500509 | BJ6: =BJ5/BJ2 -> 0.31500509 | BK6: =BK5/BK2 -> 0.31500509 | BL6: =BL5/BL2 -> 0.31500509 | BM6: =BM5/BM2 -> 0.31500509 | BN6: =BN5/BN2 -> 0.31500509 | BO6: =BO5/BO2 -> 0.31500509 | ... BS6: =BS5/BS2 -> 0.31500509 | BU6: =BU5/BU2 -> 0.35198934 | BV6: =BV5/BV2 -> 0.35198934 | BW6: =BW5/BW2 -> 0.35198934 | BX6: =BX5/BX2 -> 0.35198934 | BY6: =BY5/BY2 -> 0.35198934 | BZ6: =BZ5/BZ2 -> 0.35198934 | CA6: =CA5/CA2 -> 0.35198934 | CB6: =CB5/CB2 -> 0.35198934 | ... CF6: =CF5/CF2 -> 0.35198934 | CH6: =CH5/CH2 -> 0.3166819 | CI6: =CI5/CI2 -> 0.3166819 | CJ6: =CJ5/CJ2 -> 0.3166819 | CK6: =CK5/CK2 -> 0.3166819 | CL6: =CL5/CL2 -> 0.3166819 | CM6: =CM5/CM2 -> 0.3166819 | CN6: =CN5/CN2 -> 0.3166819 | CO6: =CO5/CO2 -> 0.3166819 | ... CS6: =CS5/CS2 -> 0.3166819 | CU6: =CU5/CU2 -> 0.31168675 | CV6: =CV5/CV2 -> 0.31168675 | CW6: =CW5/CW2 -> 0.31168675 | CX6: =CX5/CX2 -> 0.31168675 | CY6: =CY5/CY2 -> 0.31168675 | CZ6: =CZ5/CZ2 -> 0.31168675 | DA6: =DA5/DA2 -> 0.31168675 | DB6: =DB5/DB2 -> 0.31168675 | ... DF6: =DF5/DF2 -> 0.31168675
B8: Total Fixo + Variável | C8: =C10+C53 -> 19000 | D8: =D10+D53 -> 28000 | E8: =E10+E53 -> 21480 | F8: =F10+F53 -> 44368.796 | G8: =G10+G53 -> 44516.024 | H8: =H10+H53 -> 46649.311 | I8: =I10+I53 -> 46649.311 | J8: =J10+J53 -> 46649.311 | ... S8: =S10+S53 -> 46949.311 | U8: =U10+U53 -> 53801.528 | V8: =V10+V53 -> 53801.528 | W8: =W10+W53 -> 59511.113 | X8: =X10+X53 -> 59511.113 | Y8: =Y10+Y53 -> 59511.113 | Z8: =Z10+Z53 -> 59511.113 | AA8: =AA10+AA53 -> 59511.113 | AB8: =AB10+AB53 -> 59511.113 | ... AF8: =AF10+AF53 -> 59511.113 | AH8: =AH10+AH53 -> 71144.891 | AI8: =AI10+AI53 -> 71144.891 | AJ8: =AJ10+AJ53 -> 71144.891 | AK8: =AK10+AK53 -> 71144.891 | AL8: =AL10+AL53 -> 71144.891 | AM8: =AM10+AM53 -> 71144.891 | AN8: =AN10+AN53 -> 71144.891 | AO8: =AO10+AO53 -> 71144.891 | ... AS8: =AS10+AS53 -> 71144.891 | AU8: =AU10+AU53 -> 80250.819 | AV8: =AV10+AV53 -> 80250.819 | AW8: =AW10+AW53 -> 80250.819 | AX8: =AX10+AX53 -> 80250.819 | AY8: =AY10+AY53 -> 80250.819 | AZ8: =AZ10+AZ53 -> 80250.819 | BA8: =BA10+BA53 -> 80250.819 | BB8: =BB10+BB53 -> 80250.819 | ... BF8: =BF10+BF53 -> 80250.819 | BH8: =BH10+BH53 -> 90866.287 | BI8: =BI10+BI53 -> 90866.287 | BJ8: =BJ10+BJ53 -> 90866.287 | BK8: =BK10+BK53 -> 90866.287 | BL8: =BL10+BL53 -> 90866.287 | BM8: =BM10+BM53 -> 90866.287 | BN8: =BN10+BN53 -> 90866.287 | BO8: =BO10+BO53 -> 90866.287 | ... BS8: =BS10+BS53 -> 90866.287 | BU8: =BU10+BU53 -> 100286.94 | BV8: =BV10+BV53 -> 100286.94 | BW8: =BW10+BW53 -> 100286.94 | BX8: =BX10+BX53 -> 100286.94 | BY8: =BY10+BY53 -> 100286.94 | BZ8: =BZ10+BZ53 -> 100286.94 | CA8: =CA10+CA53 -> 100286.94 | CB8: =CB10+CB53 -> 100286.94 | ... CF8: =CF10+CF53 -> 100286.94 | CH8: =CH10+CH53 -> 105751.16 | CI8: =CI10+CI53 -> 105751.16 | CJ8: =CJ10+CJ53 -> 105751.16 | CK8: =CK10+CK53 -> 105751.16 | CL8: =CL10+CL53 -> 105751.16 | CM8: =CM10+CM53 -> 105751.16 | CN8: =CN10+CN53 -> 105751.16 | CO8: =CO10+CO53 -> 105751.16 | ... CS8: =CS10+CS53 -> 105751.16 | CU8: =CU10+CU53 -> 114133.09 | CV8: =CV10+CV53 -> 114133.09 | CW8: =CW10+CW53 -> 114133.09 | CX8: =CX10+CX53 -> 114133.09 | CY8: =CY10+CY53 -> 114133.09 | CZ8: =CZ10+CZ53 -> 114133.09 | DA8: =DA10+DA53 -> 114133.09 | DB8: =DB10+DB53 -> 114133.09 | ... DF8: =DF10+DF53 -> 114133.09
A9: Item | B9: Conta | C9: 46235 | D9: 46266 | E9: 46296 | F9: 45962 | G9: 46357 | H9: 46388 | I9: 46419 | J9: 46447 | K9: 46478 | L9: 46508 | M9: 46539 | N9: 46569 | O9: 46600 | P9: 46631 | Q9: 46661 | R9: 46692 | S9: 46722 | T9: Reajuste 10% | U9: 46753 | V9: 46784 | W9: 46813 | X9: 46844 | Y9: 46874 | Z9: 46905 | AA9: 46935 | AB9: 46966 | AC9: 46997 | AD9: 47027 | AE9: 47058 | AF9: 47088 | AH9: 47119 | AI9: 47150 | AJ9: 47178 | AK9: 47209 | AL9: 47239 | AM9: 47270 | AN9: 47300 | AO9: 47331 | AP9: 47362 | AQ9: 47392 | AR9: 47423 | AS9: 47453 | AU9: 47484 | AV9: 47515 | AW9: 47543 | AX9: 47574 | AY9: 47604 | AZ9: 47635 | BA9: 47665 | BB9: 47696 | BC9: 47727 | BD9: 47757 | BE9: 47788 | BF9: 47818 | BH9: 47849 | BI9: 47880 | BJ9: 47908 | BK9: 47939 | BL9: 47969 | BM9: 48000 | BN9: 48030 | BO9: 48061 | BP9: 48092 | BQ9: 48122 | BR9: 48153 | BS9: 48183 | BU9: 48214 | BV9: 48245 | BW9: 48274 | BX9: 48305 | BY9: 48335 | BZ9: 48366 | CA9: 48396 | CB9: 48427 | CC9: 48458 | CD9: 48488 | CE9: 48519 | CF9: 48549 | CH9: 48580 | CI9: 48611 | CJ9: 48639 | CK9: 48670 | CL9: 48700 | CM9: 48731 | CN9: 48761 | CO9: 48792 | CP9: 48823 | CQ9: 48853 | CR9: 48884 | CS9: 48914 | CU9: 48945 | CV9: 48976 | CW9: 49004 | CX9: 49035 | CY9: 49065 | CZ9: 49096 | DA9: 49126 | DB9: 49157 | DC9: 49188 | DD9: 49218 | DE9: 49249 | DF9: 49279
A10: 1 | B10: Custos Fixos | C10: =C11+C15+C25+C30+C33+C38+C46+C50 -> 19000 | D10: =D11+D15+D25+D30+D33+D38+D46+D50 -> 28000 | E10: =E11+E15+E25+E30+E33+E38+E46+E50 -> 21480 | F10: =F11+F15+F25+F30+F33+F38+F46+F50 -> 44178.767 | G10: =G11+G15+G25+G30+G33+G38+G46+G50 -> 44178.767 | H10: =H11+H15+H25+H30+H33+H38+H46+H50 -> 44932.146 | I10: =I11+I15+I25+I30+I33+I38+I46+I50 -> 44932.146 | J10: =J11+J15+J25+J30+J33+J38+J46+J50 -> 44932.146 | ... S10: =S11+S15+S25+S30+S33+S38+S46+S50 -> 45232.146 | U10: =U11+U15+U25+U30+U33+U38+U46+U50 -> 50242.816 | V10: =V11+V15+V25+V30+V33+V38+V46+V50 -> 50242.816 | W10: =W11+W15+W25+W30+W33+W38+W46+W50 -> 50242.816 | X10: =X11+X15+X25+X30+X33+X38+X46+X50 -> 50242.816 | Y10: =Y11+Y15+Y25+Y30+Y33+Y38+Y46+Y50 -> 50242.816 | Z10: =Z11+Z15+Z25+Z30+Z33+Z38+Z46+Z50 -> 50242.816 | AA10: =AA11+AA15+AA25+AA30+AA33+AA38+AA46+AA50 -> 50242.816 | AB10: =AB11+AB15+AB25+AB30+AB33+AB38+AB46+AB50 -> 50242.816 | ... AF10: =AF11+AF15+AF25+AF30+AF33+AF38+AF46+AF50 -> 50242.816 | AH10: =AH11+AH15+AH25+AH30+AH33+AH38+AH46+AH50 -> 56330.855 | AI10: =AI11+AI15+AI25+AI30+AI33+AI38+AI46+AI50 -> 56330.855 | AJ10: =AJ11+AJ15+AJ25+AJ30+AJ33+AJ38+AJ46+AJ50 -> 56330.855 | AK10: =AK11+AK15+AK25+AK30+AK33+AK38+AK46+AK50 -> 56330.855 | AL10: =AL11+AL15+AL25+AL30+AL33+AL38+AL46+AL50 -> 56330.855 | AM10: =AM11+AM15+AM25+AM30+AM33+AM38+AM46+AM50 -> 56330.855 | AN10: =AN11+AN15+AN25+AN30+AN33+AN38+AN46+AN50 -> 56330.855 | AO10: =AO11+AO15+AO25+AO30+AO33+AO38+AO46+AO50 -> 56330.855 | ... AS10: =AS11+AS15+AS25+AS30+AS33+AS38+AS46+AS50 -> 56330.855 | AU10: =AU11+AU15+AU25+AU30+AU33+AU38+AU46+AU50 -> 61734.224 | AV10: =AV11+AV15+AV25+AV30+AV33+AV38+AV46+AV50 -> 61734.224 | AW10: =AW11+AW15+AW25+AW30+AW33+AW38+AW46+AW50 -> 61734.224 | AX10: =AX11+AX15+AX25+AX30+AX33+AX38+AX46+AX50 -> 61734.224 | AY10: =AY11+AY15+AY25+AY30+AY33+AY38+AY46+AY50 -> 61734.224 | AZ10: =AZ11+AZ15+AZ25+AZ30+AZ33+AZ38+AZ46+AZ50 -> 61734.224 | BA10: =BA11+BA15+BA25+BA30+BA33+BA38+BA46+BA50 -> 61734.224 | BB10: =BB11+BB15+BB25+BB30+BB33+BB38+BB46+BB50 -> 61734.224 | ... BF10: =BF11+BF15+BF25+BF30+BF33+BF38+BF46+BF50 -> 61734.224 | BH10: =BH11+BH15+BH25+BH30+BH33+BH38+BH46+BH50 -> 68643.333 | BI10: =BI11+BI15+BI25+BI30+BI33+BI38+BI46+BI50 -> 68643.333 | BJ10: =BJ11+BJ15+BJ25+BJ30+BJ33+BJ38+BJ46+BJ50 -> 68643.333 | BK10: =BK11+BK15+BK25+BK30+BK33+BK38+BK46+BK50 -> 68643.333 | BL10: =BL11+BL15+BL25+BL30+BL33+BL38+BL46+BL50 -> 68643.333 | BM10: =BM11+BM15+BM25+BM30+BM33+BM38+BM46+BM50 -> 68643.333 | BN10: =BN11+BN15+BN25+BN30+BN33+BN38+BN46+BN50 -> 68643.333 | BO10: =BO11+BO15+BO25+BO30+BO33+BO38+BO46+BO50 -> 68643.333 | ... BS10: =BS11+BS15+BS25+BS30+BS33+BS38+BS46+BS50 -> 68643.333 | BU10: =BU11+BU15+BU25+BU30+BU33+BU38+BU46+BU50 -> 74361.427 | BV10: =BV11+BV15+BV25+BV30+BV33+BV38+BV46+BV50 -> 74361.427 | BW10: =BW11+BW15+BW25+BW30+BW33+BW38+BW46+BW50 -> 74361.427 | BX10: =BX11+BX15+BX25+BX30+BX33+BX38+BX46+BX50 -> 74361.427 | BY10: =BY11+BY15+BY25+BY30+BY33+BY38+BY46+BY50 -> 74361.427 | BZ10: =BZ11+BZ15+BZ25+BZ30+BZ33+BZ38+BZ46+BZ50 -> 74361.427 | CA10: =CA11+CA15+CA25+CA30+CA33+CA38+CA46+CA50 -> 74361.427 | CB10: =CB11+CB15+CB25+CB30+CB33+CB38+CB46+CB50 -> 74361.427 | ... CF10: =CF11+CF15+CF25+CF30+CF33+CF38+CF46+CF50 -> 74361.427 | CH10: =CH11+CH15+CH25+CH30+CH33+CH38+CH46+CH50 -> 79825.651 | CI10: =CI11+CI15+CI25+CI30+CI33+CI38+CI46+CI50 -> 79825.651 | CJ10: =CJ11+CJ15+CJ25+CJ30+CJ33+CJ38+CJ46+CJ50 -> 79825.651 | CK10: =CK11+CK15+CK25+CK30+CK33+CK38+CK46+CK50 -> 79825.651 | CL10: =CL11+CL15+CL25+CL30+CL33+CL38+CL46+CL50 -> 79825.651 | CM10: =CM11+CM15+CM25+CM30+CM33+CM38+CM46+CM50 -> 79825.651 | CN10: =CN11+CN15+CN25+CN30+CN33+CN38+CN46+CN50 -> 79825.651 | CO10: =CO11+CO15+CO25+CO30+CO33+CO38+CO46+CO50 -> 79825.651 | ... CS10: =CS11+CS15+CS25+CS30+CS33+CS38+CS46+CS50 -> 79825.651 | CU10: =CU11+CU15+CU25+CU30+CU33+CU38+CU46+CU50 -> 86348.199 | CV10: =CV11+CV15+CV25+CV30+CV33+CV38+CV46+CV50 -> 86348.199 | CW10: =CW11+CW15+CW25+CW30+CW33+CW38+CW46+CW50 -> 86348.199 | CX10: =CX11+CX15+CX25+CX30+CX33+CX38+CX46+CX50 -> 86348.199 | CY10: =CY11+CY15+CY25+CY30+CY33+CY38+CY46+CY50 -> 86348.199 | CZ10: =CZ11+CZ15+CZ25+CZ30+CZ33+CZ38+CZ46+CZ50 -> 86348.199 | DA10: =DA11+DA15+DA25+DA30+DA33+DA38+DA46+DA50 -> 86348.199 | DB10: =DB11+DB15+DB25+DB30+DB33+DB38+DB46+DB50 -> 86348.199 | ... DF10: =DF11+DF15+DF25+DF30+DF33+DF38+DF46+DF50 -> 86348.199
A11: 1.0 | B11: Aluguel/Parcelmento Imóvel | C11: =C12+C13+C14 -> 19000 | D11: =D12+D13+D14 -> 19000 | E11: =E12+E13+E14 -> 19000 | F11: =F12+F13+F14 -> 19000 | G11: =G12+G13+G14 -> 19000 | H11: =H12+H13+H14 -> 19000 | I11: =I12+I13+I14 -> 19000 | J11: =J12+J13+J14 -> 19000 | ... S11: =S12+S13+S14 -> 19000 | U11: =U12+U13+U14 -> 20900 | V11: =V12+V13+V14 -> 20900 | W11: =W12+W13+W14 -> 20900 | X11: =X12+X13+X14 -> 20900 | Y11: =Y12+Y13+Y14 -> 20900 | Z11: =Z12+Z13+Z14 -> 20900 | AA11: =AA12+AA13+AA14 -> 20900 | AB11: =AB12+AB13+AB14 -> 20900 | ... AF11: =AF12+AF13+AF14 -> 20900 | AH11: =AH12+AH13+AH14 -> 22990 | AI11: =AI12+AI13+AI14 -> 22990 | AJ11: =AJ12+AJ13+AJ14 -> 22990 | AK11: =AK12+AK13+AK14 -> 22990 | AL11: =AL12+AL13+AL14 -> 22990 | AM11: =AM12+AM13+AM14 -> 22990 | AN11: =AN12+AN13+AN14 -> 22990 | AO11: =AO12+AO13+AO14 -> 22990 | ... AS11: =AS12+AS13+AS14 -> 22990 | AU11: =AU12+AU13+AU14 -> 25289 | AV11: =AV12+AV13+AV14 -> 25289 | AW11: =AW12+AW13+AW14 -> 25289 | AX11: =AX12+AX13+AX14 -> 25289 | AY11: =AY12+AY13+AY14 -> 25289 | AZ11: =AZ12+AZ13+AZ14 -> 25289 | BA11: =BA12+BA13+BA14 -> 25289 | BB11: =BB12+BB13+BB14 -> 25289 | ... BF11: =BF12+BF13+BF14 -> 25289 | BH11: =BH12+BH13+BH14 -> 27817.9 | BI11: =BI12+BI13+BI14 -> 27817.9 | BJ11: =BJ12+BJ13+BJ14 -> 27817.9 | BK11: =BK12+BK13+BK14 -> 27817.9 | BL11: =BL12+BL13+BL14 -> 27817.9 | BM11: =BM12+BM13+BM14 -> 27817.9 | BN11: =BN12+BN13+BN14 -> 27817.9 | BO11: =BO12+BO13+BO14 -> 27817.9 | ... BS11: =BS12+BS13+BS14 -> 27817.9 | BU11: =BU12+BU13+BU14 -> 30599.69 | BV11: =BV12+BV13+BV14 -> 30599.69 | BW11: =BW12+BW13+BW14 -> 30599.69 | BX11: =BX12+BX13+BX14 -> 30599.69 | BY11: =BY12+BY13+BY14 -> 30599.69 | BZ11: =BZ12+BZ13+BZ14 -> 30599.69 | CA11: =CA12+CA13+CA14 -> 30599.69 | CB11: =CB12+CB13+CB14 -> 30599.69 | ... CF11: =CF12+CF13+CF14 -> 30599.69 | CH11: =CH12+CH13+CH14 -> 33659.659 | CI11: =CI12+CI13+CI14 -> 33659.659 | CJ11: =CJ12+CJ13+CJ14 -> 33659.659 | CK11: =CK12+CK13+CK14 -> 33659.659 | CL11: =CL12+CL13+CL14 -> 33659.659 | CM11: =CM12+CM13+CM14 -> 33659.659 | CN11: =CN12+CN13+CN14 -> 33659.659 | CO11: =CO12+CO13+CO14 -> 33659.659 | ... CS11: =CS12+CS13+CS14 -> 33659.659 | CU11: =CU12+CU13+CU14 -> 37025.625 | CV11: =CV12+CV13+CV14 -> 37025.625 | CW11: =CW12+CW13+CW14 -> 37025.625 | CX11: =CX12+CX13+CX14 -> 37025.625 | CY11: =CY12+CY13+CY14 -> 37025.625 | CZ11: =CZ12+CZ13+CZ14 -> 37025.625 | DA11: =DA12+DA13+DA14 -> 37025.625 | DB11: =DB12+DB13+DB14 -> 37025.625 | ... DF11: =DF12+DF13+DF14 -> 37025.625
A12: 1.0.1 | B12: Aluguel/Parcelmento Imóvel | C12: =Financiamento!B2 -> 19000 | D12: =Financiamento!B2 -> 19000 | E12: =Financiamento!B2 -> 19000 | F12: =Financiamento!B2 -> 19000 | G12: =Financiamento!B2 -> 19000 | H12: =Financiamento!$B$2 -> 19000 | I12: =Financiamento!$B$2 -> 19000 | J12: =Financiamento!$B$2 -> 19000 | K12: =Financiamento!$B$2 -> 19000 | L12: =Financiamento!$B$2 -> 19000 | M12: =Financiamento!$B$2 -> 19000 | N12: =Financiamento!$B$2 -> 19000 | O12: =Financiamento!$B$2 -> 19000 | ... S12: =Financiamento!$B$2 -> 19000 | T12: 1.1 | U12: =Financiamento!$B$2*$T$12 -> 20900 | V12: =Financiamento!$B$2*$T$12 -> 20900 | W12: =Financiamento!$B$2*$T$12 -> 20900 | X12: =Financiamento!$B$2*$T$12 -> 20900 | Y12: =Financiamento!$B$2*$T$12 -> 20900 | Z12: =Financiamento!$B$2*$T$12 -> 20900 | AA12: =Financiamento!$B$2*$T$12 -> 20900 | AB12: =Financiamento!$B$2*$T$12 -> 20900 | ... AF12: =Financiamento!$B$2*$T$12 -> 20900 | AG12: 1.1 | AH12: =$AF$12*$AG$12 -> 22990 | AI12: =$AF$12*$AG$12 -> 22990 | AJ12: =$AF$12*$AG$12 -> 22990 | AK12: =$AF$12*$AG$12 -> 22990 | AL12: =$AF$12*$AG$12 -> 22990 | AM12: =$AF$12*$AG$12 -> 22990 | AN12: =$AF$12*$AG$12 -> 22990 | AO12: =$AF$12*$AG$12 -> 22990 | ... AS12: =$AF$12*$AG$12 -> 22990 | AT12: 1.1 | AU12: =$AS$12*$AT$12 -> 25289 | AV12: =$AS$12*$AT$12 -> 25289 | AW12: =$AS$12*$AT$12 -> 25289 | AX12: =$AS$12*$AT$12 -> 25289 | AY12: =$AS$12*$AT$12 -> 25289 | AZ12: =$AS$12*$AT$12 -> 25289 | BA12: =$AS$12*$AT$12 -> 25289 | BB12: =$AS$12*$AT$12 -> 25289 | ... BF12: =$AS$12*$AT$12 -> 25289 | BG12: 1.1 | BH12: =$BF$12*$BG$12 -> 27817.9 | BI12: =$BF$12*$BG$12 -> 27817.9 | BJ12: =$BF$12*$BG$12 -> 27817.9 | BK12: =$BF$12*$BG$12 -> 27817.9 | BL12: =$BF$12*$BG$12 -> 27817.9 | BM12: =$BF$12*$BG$12 -> 27817.9 | BN12: =$BF$12*$BG$12 -> 27817.9 | BO12: =$BF$12*$BG$12 -> 27817.9 | ... BS12: =$BF$12*$BG$12 -> 27817.9 | BT12: 1.1 | BU12: =$BS$12*$BT$12 -> 30599.69 | BV12: =$BS$12*$BT$12 -> 30599.69 | BW12: =$BS$12*$BT$12 -> 30599.69 | BX12: =$BS$12*$BT$12 -> 30599.69 | BY12: =$BS$12*$BT$12 -> 30599.69 | BZ12: =$BS$12*$BT$12 -> 30599.69 | CA12: =$BS$12*$BT$12 -> 30599.69 | CB12: =$BS$12*$BT$12 -> 30599.69 | ... CF12: =$BS$12*$BT$12 -> 30599.69 | CG12: 1.1 | CH12: =CF12*CG12 -> 33659.659 | CI12: =CH12 -> 33659.659 | CJ12: =CI12 -> 33659.659 | CK12: =CJ12 -> 33659.659 | CL12: =CK12 -> 33659.659 | CM12: =CL12 -> 33659.659 | CN12: =CM12 -> 33659.659 | CO12: =CN12 -> 33659.659 | CP12: =CO12 -> 33659.659 | ... CS12: =CR12 -> 33659.659 | CT12: 1.1 | CU12: =CS12*CT12 -> 37025.625 | CV12: =CU12 -> 37025.625 | CW12: =CV12 -> 37025.625 | CX12: =CW12 -> 37025.625 | CY12: =CX12 -> 37025.625 | CZ12: =CY12 -> 37025.625 | DA12: =CZ12 -> 37025.625 | DB12: =DA12 -> 37025.625 | DC12: =DB12 -> 37025.625 | ... DF12: =DE12 -> 37025.625
D13: 0 | E13: 0 | F13: 0 | G13: 0 | H13: 0 | I13: 0 | J13: 0 | K13: 0 | L13: 0 | M13: 0 | N13: 0 | O13: 0 | P13: 0 | Q13: 0 | R13: 0 | S13: 0 | U13: 0 | V13: 0 | W13: 0 | X13: 0 | Y13: 0 | Z13: 0 | AA13: 0 | AB13: 0 | AC13: 0 | AD13: 0 | AE13: 0 | AF13: 0 | AH13: 0 | AI13: 0 | AJ13: 0 | AK13: 0 | AL13: 0 | AM13: 0 | AN13: 0 | AO13: 0 | AP13: 0 | AQ13: 0 | AR13: 0 | AS13: 0 | AU13: 0 | AV13: 0 | AW13: 0 | AX13: 0 | AY13: 0 | AZ13: 0 | BA13: 0 | BB13: 0 | BC13: 0 | BD13: 0 | BE13: 0 | BF13: 0 | BH13: 0 | BI13: 0 | BJ13: 0 | BK13: 0 | BL13: 0 | BM13: 0 | BN13: 0 | BO13: 0 | BP13: 0 | BQ13: 0 | BR13: 0 | BS13: 0 | BU13: 0 | BV13: 0 | BW13: 0 | BX13: 0 | BY13: 0 | BZ13: 0 | CA13: 0 | CB13: 0 | CC13: 0 | CD13: 0 | CE13: 0 | CF13: 0
D14: 0 | E14: 0 | F14: 0 | G14: 0 | H14: 0 | I14: 0 | J14: 0 | K14: 0 | L14: 0 | M14: 0 | N14: 0 | O14: 0 | P14: 0 | Q14: 0 | R14: 0 | S14: 0 | U14: 0 | V14: 0 | W14: 0 | X14: 0 | Y14: 0 | Z14: 0 | AA14: 0 | AB14: 0 | AC14: 0 | AD14: 0 | AE14: 0 | AF14: 0 | AH14: 0 | AI14: 0 | AJ14: 0 | AK14: 0 | AL14: 0 | AM14: 0 | AN14: 0 | AO14: 0 | AP14: 0 | AQ14: 0 | AR14: 0 | AS14: 0 | AU14: 0 | AV14: 0 | AW14: 0 | AX14: 0 | AY14: 0 | AZ14: 0 | BA14: 0 | BB14: 0 | BC14: 0 | BD14: 0 | BE14: 0 | BF14: 0 | BH14: 0 | BI14: 0 | BJ14: 0 | BK14: 0 | BL14: 0 | BM14: 0 | BN14: 0 | BO14: 0 | BP14: 0 | BQ14: 0 | BR14: 0 | BS14: 0 | BU14: 0 | BV14: 0 | BW14: 0 | BX14: 0 | BY14: 0 | BZ14: 0 | CA14: 0 | CB14: 0 | CC14: 0 | CD14: 0 | CE14: 0 | CF14: 0
A15: 1.1 | B15: Salários | C15: =SUM(C16:C24) -> 0 | D15: =SUM(D16:D24) -> 0 | E15: =SUM(E16:E24) -> 0 | F15: =SUM(F16:F24) -> 8960 | G15: =SUM(G16:G24) -> 8960 | H15: =SUM(H16:H24) -> 8960 | I15: =SUM(I16:I24) -> 8960 | J15: =SUM(J16:J24) -> 8960 | ... S15: =SUM(S16:S24) -> 8960 | U15: =SUM(U16:U24) -> 9356 | V15: =SUM(V16:V24) -> 9356 | W15: =SUM(W16:W24) -> 9356 | X15: =SUM(X16:X24) -> 9356 | Y15: =SUM(Y16:Y24) -> 9356 | Z15: =SUM(Z16:Z24) -> 9356 | AA15: =SUM(AA16:AA24) -> 9356 | AB15: =SUM(AB16:AB24) -> 9356 | ... AF15: =SUM(AF16:AF24) -> 9356 | AH15: =SUM(AH16:AH24) -> 10291.6 | AI15: =SUM(AI16:AI24) -> 10291.6 | AJ15: =SUM(AJ16:AJ24) -> 10291.6 | AK15: =SUM(AK16:AK24) -> 10291.6 | AL15: =SUM(AL16:AL24) -> 10291.6 | AM15: =SUM(AM16:AM24) -> 10291.6 | AN15: =SUM(AN16:AN24) -> 10291.6 | AO15: =SUM(AO16:AO24) -> 10291.6 | ... AS15: =SUM(AS16:AS24) -> 10291.6 | AU15: =SUM(AU16:AU24) -> 10770.76 | AV15: =SUM(AV16:AV24) -> 10770.76 | AW15: =SUM(AW16:AW24) -> 10770.76 | AX15: =SUM(AX16:AX24) -> 10770.76 | AY15: =SUM(AY16:AY24) -> 10770.76 | AZ15: =SUM(AZ16:AZ24) -> 10770.76 | BA15: =SUM(BA16:BA24) -> 10770.76 | BB15: =SUM(BB16:BB24) -> 10770.76 | ... BF15: =SUM(BF16:BF24) -> 10770.76 | BH15: =SUM(BH16:BH24) -> 12377.62 | BI15: =SUM(BI16:BI24) -> 12377.62 | BJ15: =SUM(BJ16:BJ24) -> 12377.62 | BK15: =SUM(BK16:BK24) -> 12377.62 | BL15: =SUM(BL16:BL24) -> 12377.62 | BM15: =SUM(BM16:BM24) -> 12377.62 | BN15: =SUM(BN16:BN24) -> 12377.62 | BO15: =SUM(BO16:BO24) -> 12377.62 | ... BS15: =SUM(BS16:BS24) -> 12377.62 | BU15: =SUM(BU16:BU24) -> 12377.62 | BV15: =SUM(BV16:BV24) -> 12377.62 | BW15: =SUM(BW16:BW24) -> 12377.62 | BX15: =SUM(BX16:BX24) -> 12377.62 | BY15: =SUM(BY16:BY24) -> 12377.62 | BZ15: =SUM(BZ16:BZ24) -> 12377.62 | CA15: =SUM(CA16:CA24) -> 12377.62 | CB15: =SUM(CB16:CB24) -> 12377.62 | ... CF15: =SUM(CF16:CF24) -> 12377.62 | CH15: =SUM(CH16:CH24) -> 13615.382 | CI15: =SUM(CI16:CI24) -> 13615.382 | CJ15: =SUM(CJ16:CJ24) -> 13615.382 | CK15: =SUM(CK16:CK24) -> 13615.382 | CL15: =SUM(CL16:CL24) -> 13615.382 | CM15: =SUM(CM16:CM24) -> 13615.382 | CN15: =SUM(CN16:CN24) -> 13615.382 | CO15: =SUM(CO16:CO24) -> 13615.382 | ... CS15: =SUM(CS16:CS24) -> 13615.382 | CU15: =SUM(CU16:CU24) -> 14916.92 | CV15: =SUM(CV16:CV24) -> 14916.92 | CW15: =SUM(CW16:CW24) -> 14916.92 | CX15: =SUM(CX16:CX24) -> 14916.92 | CY15: =SUM(CY16:CY24) -> 14916.92 | CZ15: =SUM(CZ16:CZ24) -> 14916.92 | DA15: =SUM(DA16:DA24) -> 14916.92 | DB15: =SUM(DB16:DB24) -> 14916.92 | ... DF15: =SUM(DF16:DF24) -> 14916.92
A16: 1.1.1 | B16: Funcionários Limpeza | D16: 0 | E16: 0 | F16: =Equipe!$J$6 -> 3960 | G16: =Equipe!$J$6 -> 3960 | H16: =Equipe!$J$6 -> 3960 | I16: =Equipe!$J$6 -> 3960 | J16: =Equipe!$J$6 -> 3960 | K16: =Equipe!$J$6 -> 3960 | L16: =Equipe!$J$6 -> 3960 | M16: =Equipe!$J$6 -> 3960 | ... S16: =Equipe!$J$6 -> 3960 | U16: =Equipe!$J$16 -> 4356 | V16: =Equipe!$J$16 -> 4356 | W16: =Equipe!$J$16 -> 4356 | X16: =Equipe!$J$16 -> 4356 | Y16: =Equipe!$J$16 -> 4356 | Z16: =Equipe!$J$16 -> 4356 | AA16: =Equipe!$J$16 -> 4356 | AB16: =Equipe!$J$16 -> 4356 | ... AF16: =Equipe!$J$16 -> 4356 | AH16: =Equipe!$J$26 -> 4791.6 | AI16: =Equipe!$J$26 -> 4791.6 | AJ16: =Equipe!$J$26 -> 4791.6 | AK16: =Equipe!$J$26 -> 4791.6 | AL16: =Equipe!$J$26 -> 4791.6 | AM16: =Equipe!$J$26 -> 4791.6 | AN16: =Equipe!$J$26 -> 4791.6 | AO16: =Equipe!$J$26 -> 4791.6 | ... AS16: =Equipe!$J$26 -> 4791.6 | AU16: =Equipe!$J$36 -> 5270.76 | AV16: =Equipe!$J$36 -> 5270.76 | AW16: =Equipe!$J$36 -> 5270.76 | AX16: =Equipe!$J$36 -> 5270.76 | AY16: =Equipe!$J$36 -> 5270.76 | AZ16: =Equipe!$J$36 -> 5270.76 | BA16: =Equipe!$J$36 -> 5270.76 | BB16: =Equipe!$J$36 -> 5270.76 | ... BF16: =Equipe!$J$36 -> 5270.76 | BH16: =Equipe!$J$56 -> 6377.6196 | BI16: =Equipe!$J$56 -> 6377.6196 | BJ16: =Equipe!$J$56 -> 6377.6196 | BK16: =Equipe!$J$56 -> 6377.6196 | BL16: =Equipe!$J$56 -> 6377.6196 | BM16: =Equipe!$J$56 -> 6377.6196 | BN16: =Equipe!$J$56 -> 6377.6196 | BO16: =Equipe!$J$56 -> 6377.6196 | ... BS16: =Equipe!$J$56 -> 6377.6196 | BU16: =Equipe!$J$56 -> 6377.6196 | BV16: =Equipe!$J$56 -> 6377.6196 | BW16: =Equipe!$J$56 -> 6377.6196 | BX16: =Equipe!$J$56 -> 6377.6196 | BY16: =Equipe!$J$56 -> 6377.6196 | BZ16: =Equipe!$J$56 -> 6377.6196 | CA16: =Equipe!$J$56 -> 6377.6196 | CB16: =Equipe!$J$56 -> 6377.6196 | ... CF16: =Equipe!$J$56 -> 6377.6196 | CH16: =Equipe!J66 -> 7015.3816 | CI16: =CH16 -> 7015.3816 | CJ16: =CI16 -> 7015.3816 | CK16: =CJ16 -> 7015.3816 | CL16: =CK16 -> 7015.3816 | CM16: =CL16 -> 7015.3816 | CN16: =CM16 -> 7015.3816 | CO16: =CN16 -> 7015.3816 | CP16: =CO16 -> 7015.3816 | ... CS16: =CR16 -> 7015.3816 | CU16: =Equipe!J76 -> 7716.9197 | CV16: =CU16 -> 7716.9197 | CW16: =CV16 -> 7716.9197 | CX16: =CW16 -> 7716.9197 | CY16: =CX16 -> 7716.9197 | CZ16: =CY16 -> 7716.9197 | DA16: =CZ16 -> 7716.9197 | DB16: =DA16 -> 7716.9197 | DC16: =DB16 -> 7716.9197 | ... DF16: =DE16 -> 7716.9197
A17: 1.1.2 | B17: Funcionários Recepção | D17: 0 | E17: 0 | F17: =Equipe!$J$3 -> 0 | G17: =Equipe!$J$3 -> 0 | H17: =Equipe!$J$3 -> 0 | I17: =Equipe!$J$3 -> 0 | J17: =Equipe!$J$3 -> 0 | K17: =Equipe!$J$3 -> 0 | L17: =Equipe!$J$3 -> 0 | M17: =Equipe!$J$3 -> 0 | ... S17: =Equipe!$J$3 -> 0 | U17: =Equipe!$J$13 -> 0 | V17: =Equipe!$J$13 -> 0 | W17: =Equipe!$J$13 -> 0 | X17: =Equipe!$J$13 -> 0 | Y17: =Equipe!$J$13 -> 0 | Z17: =Equipe!$J$13 -> 0 | AA17: =Equipe!$J$13 -> 0 | AB17: =Equipe!$J$13 -> 0 | ... AF17: =Equipe!$J$13 -> 0 | AH17: =Equipe!$J$23 -> 0 | AI17: =Equipe!$J$23 -> 0 | AJ17: =Equipe!$J$23 -> 0 | AK17: =Equipe!$J$23 -> 0 | AL17: =Equipe!$J$23 -> 0 | AM17: =Equipe!$J$23 -> 0 | AN17: =Equipe!$J$23 -> 0 | AO17: =Equipe!$J$23 -> 0 | ... AS17: =Equipe!$J$23 -> 0 | AU17: =Equipe!$J$33 -> 0 | AV17: =Equipe!$J$33 -> 0 | AW17: =Equipe!$J$33 -> 0 | AX17: =Equipe!$J$33 -> 0 | AY17: =Equipe!$J$33 -> 0 | AZ17: =Equipe!$J$33 -> 0 | BA17: =Equipe!$J$33 -> 0 | BB17: =Equipe!$J$33 -> 0 | ... BF17: =Equipe!$J$33 -> 0 | BH17: =Equipe!$J$43 -> 0 | BI17: =Equipe!$J$43 -> 0 | BJ17: =Equipe!$J$43 -> 0 | BK17: =Equipe!$J$43 -> 0 | BL17: =Equipe!$J$43 -> 0 | BM17: =Equipe!$J$43 -> 0 | BN17: =Equipe!$J$43 -> 0 | BO17: =Equipe!$J$43 -> 0 | ... BS17: =Equipe!$J$43 -> 0 | BU17: =Equipe!$J$53 -> 0 | BV17: =Equipe!$J$53 -> 0 | BW17: =Equipe!$J$53 -> 0 | BX17: =Equipe!$J$53 -> 0 | BY17: =Equipe!$J$53 -> 0 | BZ17: =Equipe!$J$53 -> 0 | CA17: =Equipe!$J$53 -> 0 | CB17: =Equipe!$J$53 -> 0 | ... CF17: =Equipe!$J$53 -> 0 | CH17: =Equipe!J63 -> 0 | CI17: =CH17 -> 0 | CJ17: =CI17 -> 0 | CK17: =CJ17 -> 0 | CL17: =CK17 -> 0 | CM17: =CL17 -> 0 | CN17: =CM17 -> 0 | CO17: =CN17 -> 0 | CP17: =CO17 -> 0 | ... CS17: =CR17 -> 0 | CU17: =Equipe!I73 -> 0 | CV17: =CU17 -> 0 | CW17: =CV17 -> 0 | CX17: =CW17 -> 0 | CY17: =CX17 -> 0 | CZ17: =CY17 -> 0 | DA17: =CZ17 -> 0 | DB17: =DA17 -> 0 | DC17: =DB17 -> 0 | ... DF17: =DE17 -> 0
A18: 1.1.3 | B18: Funcionários Marketing | C18: =Equipe!$J$7 -> 0 | D18: =Equipe!$J$7 -> 0 | E18: =Equipe!$J$7 -> 0 | F18: =Equipe!$J$7 -> 0 | G18: =Equipe!$J$7 -> 0 | H18: =Equipe!$J$7 -> 0 | I18: =Equipe!$J$7 -> 0 | J18: =Equipe!$J$7 -> 0 | ... S18: =Equipe!$J$7 -> 0 | U18: =Equipe!$J$17 -> 0 | V18: =Equipe!$J$17 -> 0 | W18: =Equipe!$J$17 -> 0 | X18: =Equipe!$J$17 -> 0 | Y18: =Equipe!$J$17 -> 0 | Z18: =Equipe!$J$17 -> 0 | AA18: =Equipe!$J$17 -> 0 | AB18: =Equipe!$J$17 -> 0 | ... AF18: =Equipe!$J$17 -> 0 | AH18: =Equipe!$J$27 -> 0 | AI18: =Equipe!$J$27 -> 0 | AJ18: =Equipe!$J$27 -> 0 | AK18: =Equipe!$J$27 -> 0 | AL18: =Equipe!$J$27 -> 0 | AM18: =Equipe!$J$27 -> 0 | AN18: =Equipe!$J$27 -> 0 | AO18: =Equipe!$J$27 -> 0 | ... AS18: =Equipe!$J$27 -> 0 | AU18: =Equipe!$J$37 -> 0 | AV18: =Equipe!$J$37 -> 0 | AW18: =Equipe!$J$37 -> 0 | AX18: =Equipe!$J$37 -> 0 | AY18: =Equipe!$J$37 -> 0 | AZ18: =Equipe!$J$37 -> 0 | BA18: =Equipe!$J$37 -> 0 | BB18: =Equipe!$J$37 -> 0 | ... BF18: =Equipe!$J$37 -> 0 | BH18: =Equipe!$J$47 -> 0 | BI18: =Equipe!$J$47 -> 0 | BJ18: =Equipe!$J$47 -> 0 | BK18: =Equipe!$J$47 -> 0 | BL18: =Equipe!$J$47 -> 0 | BM18: =Equipe!$J$47 -> 0 | BN18: =Equipe!$J$47 -> 0 | BO18: =Equipe!$J$47 -> 0 | ... BS18: =Equipe!$J$47 -> 0 | BU18: =Equipe!$J$57 -> 0 | BV18: =Equipe!$J$57 -> 0 | BW18: =Equipe!$J$57 -> 0 | BX18: =Equipe!$J$57 -> 0 | BY18: =Equipe!$J$57 -> 0 | BZ18: =Equipe!$J$57 -> 0 | CA18: =Equipe!$J$57 -> 0 | CB18: =Equipe!$J$57 -> 0 | ... CF18: =Equipe!$J$57 -> 0 | CH18: =Equipe!J67 -> 0 | CI18: =CH18 -> 0 | CJ18: =CI18 -> 0 | CK18: =CJ18 -> 0 | CL18: =CK18 -> 0 | CM18: =CL18 -> 0 | CN18: =CM18 -> 0 | CO18: =CN18 -> 0 | CP18: =CO18 -> 0 | ... CS18: =CR18 -> 0 | CU18: =Equipe!I77 -> 0 | CV18: =CU18 -> 0 | CW18: =CV18 -> 0 | CX18: =CW18 -> 0 | CY18: =CX18 -> 0 | CZ18: =CY18 -> 0 | DA18: =CZ18 -> 0 | DB18: =DA18 -> 0 | DC18: =DB18 -> 0 | ... DF18: =DE18 -> 0
A19: 1.1.4 | B19: Atendimento Comercial | C19: =Equipe!$J$4 -> 0 | D19: =Equipe!$J$4 -> 0 | E19: =Equipe!$J$4 -> 0 | F19: =Equipe!$J$4 -> 0 | G19: =Equipe!$J$4 -> 0 | H19: =Equipe!$J$4 -> 0 | I19: =Equipe!$J$4 -> 0 | J19: =Equipe!$J$4 -> 0 | ... S19: =Equipe!$J$4 -> 0 | U19: =Equipe!$J$14 -> 0 | V19: =Equipe!$J$14 -> 0 | W19: =Equipe!$J$14 -> 0 | X19: =Equipe!$J$14 -> 0 | Y19: =Equipe!$J$14 -> 0 | Z19: =Equipe!$J$14 -> 0 | AA19: =Equipe!$J$14 -> 0 | AB19: =Equipe!$J$14 -> 0 | ... AF19: =Equipe!$J$14 -> 0 | AH19: =Equipe!$J$14 -> 0 | AI19: =Equipe!$J$14 -> 0 | AJ19: =Equipe!$J$14 -> 0 | AK19: =Equipe!$J$14 -> 0 | AL19: =Equipe!$J$14 -> 0 | AM19: =Equipe!$J$14 -> 0 | AN19: =Equipe!$J$14 -> 0 | AO19: =Equipe!$J$14 -> 0 | ... AS19: =Equipe!$J$14 -> 0 | AU19: =Equipe!$J$34 -> 0 | AV19: =Equipe!$J$34 -> 0 | AW19: =Equipe!$J$34 -> 0 | AX19: =Equipe!$J$34 -> 0 | AY19: =Equipe!$J$34 -> 0 | AZ19: =Equipe!$J$34 -> 0 | BA19: =Equipe!$J$34 -> 0 | BB19: =Equipe!$J$34 -> 0 | ... BF19: =Equipe!$J$34 -> 0 | BH19: =Equipe!$J$14 -> 0 | BI19: =Equipe!$J$14 -> 0 | BJ19: =Equipe!$J$14 -> 0 | BK19: =Equipe!$J$14 -> 0 | BL19: =Equipe!$J$14 -> 0 | BM19: =Equipe!$J$14 -> 0 | BN19: =Equipe!$J$14 -> 0 | BO19: =Equipe!$J$14 -> 0 | ... BS19: =Equipe!$J$14 -> 0 | BU19: =Equipe!$J$14 -> 0 | BV19: =Equipe!$J$14 -> 0 | BW19: =Equipe!$J$14 -> 0 | BX19: =Equipe!$J$14 -> 0 | BY19: =Equipe!$J$14 -> 0 | BZ19: =Equipe!$J$14 -> 0 | CA19: =Equipe!$J$14 -> 0 | CB19: =Equipe!$J$14 -> 0 | ... CF19: =Equipe!$J$14 -> 0 | CH19: =Equipe!J64 -> 0 | CI19: =CH19 -> 0 | CJ19: =CI19 -> 0 | CK19: =CJ19 -> 0 | CL19: =CK19 -> 0 | CM19: =CL19 -> 0 | CN19: =CM19 -> 0 | CO19: =CN19 -> 0 | CP19: =CO19 -> 0 | ... CS19: =CR19 -> 0 | CU19: =Equipe!I74 -> 0 | CV19: =CU19 -> 0 | CW19: =CV19 -> 0 | CX19: =CW19 -> 0 | CY19: =CX19 -> 0 | CZ19: =CY19 -> 0 | DA19: =CZ19 -> 0 | DB19: =DA19 -> 0 | DC19: =DB19 -> 0 | ... DF19: =DE19 -> 0
A20: 1.1.5 | B20: Funcionários Gerente | D20: 0 | E20: 0 | F20: =Equipe!$J$5 -> 0 | G20: =Equipe!$J$5 -> 0 | H20: =Equipe!$J$5 -> 0 | I20: =Equipe!$J$5 -> 0 | J20: =Equipe!$J$5 -> 0 | K20: =Equipe!$J$5 -> 0 | L20: =Equipe!$J$5 -> 0 | M20: =Equipe!$J$5 -> 0 | ... S20: =Equipe!$J$5 -> 0 | U20: =Equipe!$J$15 -> 0 | V20: =Equipe!$J$15 -> 0 | W20: =Equipe!$J$15 -> 0 | X20: =Equipe!$J$15 -> 0 | Y20: =Equipe!$J$15 -> 0 | Z20: =Equipe!$J$15 -> 0 | AA20: =Equipe!$J$15 -> 0 | AB20: =Equipe!$J$15 -> 0 | ... AF20: =Equipe!$J$15 -> 0 | AH20: =Equipe!$J$25 -> 0 | AI20: =Equipe!$J$25 -> 0 | AJ20: =Equipe!$J$25 -> 0 | AK20: =Equipe!$J$25 -> 0 | AL20: =Equipe!$J$25 -> 0 | AM20: =Equipe!$J$25 -> 0 | AN20: =Equipe!$J$25 -> 0 | AO20: =Equipe!$J$25 -> 0 | ... AS20: =Equipe!$J$25 -> 0 | AU20: =Equipe!$J$35 -> 0 | AV20: =Equipe!$J$35 -> 0 | AW20: =Equipe!$J$35 -> 0 | AX20: =Equipe!$J$35 -> 0 | AY20: =Equipe!$J$35 -> 0 | AZ20: =Equipe!$J$35 -> 0 | BA20: =Equipe!$J$35 -> 0 | BB20: =Equipe!$J$35 -> 0 | ... BF20: =Equipe!$J$35 -> 0 | BH20: =Equipe!$J$45 -> 0 | BI20: =Equipe!$J$45 -> 0 | BJ20: =Equipe!$J$45 -> 0 | BK20: =Equipe!$J$45 -> 0 | BL20: =Equipe!$J$45 -> 0 | BM20: =Equipe!$J$45 -> 0 | BN20: =Equipe!$J$45 -> 0 | BO20: =Equipe!$J$45 -> 0 | ... BS20: =Equipe!$J$45 -> 0 | BU20: =Equipe!$J$55 -> 0 | BV20: =Equipe!$J$55 -> 0 | BW20: =Equipe!$J$55 -> 0 | BX20: =Equipe!$J$55 -> 0 | BY20: =Equipe!$J$55 -> 0 | BZ20: =Equipe!$J$55 -> 0 | CA20: =Equipe!$J$55 -> 0 | CB20: =Equipe!$J$55 -> 0 | ... CF20: =Equipe!$J$55 -> 0 | CH20: =Equipe!J65 -> 0 | CI20: =CH20 -> 0 | CJ20: =CI20 -> 0 | CK20: =CJ20 -> 0 | CL20: =CK20 -> 0 | CM20: =CL20 -> 0 | CN20: =CM20 -> 0 | CO20: =CN20 -> 0 | CP20: =CO20 -> 0 | ... CS20: =CR20 -> 0 | CU20: =Equipe!I75 -> 0 | CV20: =CU20 -> 0 | CW20: =CV20 -> 0 | CX20: =CW20 -> 0 | CY20: =CX20 -> 0 | CZ20: =CY20 -> 0 | DA20: =CZ20 -> 0 | DB20: =DA20 -> 0 | DC20: =DB20 -> 0 | ... DF20: =DE20 -> 0
A21: 1.1.6 | B21: Educador Fisico | D21: 0 | E21: 0 | F21: =Equipe!$J$8 -> 0 | G21: =Equipe!$J$8 -> 0 | H21: =Equipe!$J$8 -> 0 | I21: =Equipe!$J$8 -> 0 | J21: =Equipe!$J$8 -> 0 | K21: =Equipe!$J$8 -> 0 | L21: =Equipe!$J$8 -> 0 | M21: =Equipe!$J$8 -> 0 | ... S21: =Equipe!$J$8 -> 0 | U21: =Equipe!$J$18 -> 0 | V21: =Equipe!$J$18 -> 0 | W21: =Equipe!$J$18 -> 0 | X21: =Equipe!$J$18 -> 0 | Y21: =Equipe!$J$18 -> 0 | Z21: =Equipe!$J$18 -> 0 | AA21: =Equipe!$J$18 -> 0 | AB21: =Equipe!$J$18 -> 0 | ... AF21: =Equipe!$J$18 -> 0 | AH21: =Equipe!$J$28 -> 0 | AI21: =Equipe!$J$28 -> 0 | AJ21: =Equipe!$J$28 -> 0 | AK21: =Equipe!$J$28 -> 0 | AL21: =Equipe!$J$28 -> 0 | AM21: =Equipe!$J$28 -> 0 | AN21: =Equipe!$J$28 -> 0 | AO21: =Equipe!$J$28 -> 0 | ... AS21: =Equipe!$J$28 -> 0 | AU21: =Equipe!$J$38 -> 0 | AV21: =Equipe!$J$38 -> 0 | AW21: =Equipe!$J$38 -> 0 | AX21: =Equipe!$J$38 -> 0 | AY21: =Equipe!$J$38 -> 0 | AZ21: =Equipe!$J$38 -> 0 | BA21: =Equipe!$J$38 -> 0 | BB21: =Equipe!$J$38 -> 0 | ... BF21: =Equipe!$J$38 -> 0 | BH21: =Equipe!$J$48 -> 0 | BI21: =Equipe!$J$48 -> 0 | BJ21: =Equipe!$J$48 -> 0 | BK21: =Equipe!$J$48 -> 0 | BL21: =Equipe!$J$48 -> 0 | BM21: =Equipe!$J$48 -> 0 | BN21: =Equipe!$J$48 -> 0 | BO21: =Equipe!$J$48 -> 0 | ... BS21: =Equipe!$J$48 -> 0 | BU21: =Equipe!$J$58 -> 0 | BV21: =Equipe!$J$58 -> 0 | BW21: =Equipe!$J$58 -> 0 | BX21: =Equipe!$J$58 -> 0 | BY21: =Equipe!$J$58 -> 0 | BZ21: =Equipe!$J$58 -> 0 | CA21: =Equipe!$J$58 -> 0 | CB21: =Equipe!$J$58 -> 0 | ... CF21: =Equipe!$J$58 -> 0 | CH21: =Equipe!J68 -> 0 | CI21: =CH21 -> 0 | CJ21: =CI21 -> 0 | CK21: =CJ21 -> 0 | CL21: =CK21 -> 0 | CM21: =CL21 -> 0 | CN21: =CM21 -> 0 | CO21: =CN21 -> 0 | CP21: =CO21 -> 0 | ... CS21: =CR21 -> 0 | CU21: =Equipe!I78 -> 0 | CV21: =CU21 -> 0 | CW21: =CV21 -> 0 | CX21: =CW21 -> 0 | CY21: =CX21 -> 0 | CZ21: =CY21 -> 0 | DA21: =CZ21 -> 0 | DB21: =DA21 -> 0 | DC21: =DB21 -> 0 | ... DF21: =DE21 -> 0
A22: 1.1.7 | B22: Pró-labore | D22: 0 | E22: 0 | F22: =Equipe!D10 -> 5000 | G22: =F22 -> 5000 | H22: =G22 -> 5000 | I22: =H22 -> 5000 | J22: =I22 -> 5000 | K22: =J22 -> 5000 | L22: =K22 -> 5000 | M22: =L22 -> 5000 | N22: =Equipe!$J$10 -> 5000 | O22: =Equipe!$J$10 -> 5000 | P22: =Equipe!$J$10 -> 5000 | Q22: =Equipe!$J$10 -> 5000 | R22: =Equipe!$J$10 -> 5000 | S22: =Equipe!$J$10 -> 5000 | U22: =Equipe!$J$20 -> 5000 | V22: =Equipe!$J$20 -> 5000 | W22: =Equipe!$J$20 -> 5000 | X22: =Equipe!$J$20 -> 5000 | Y22: =Equipe!$J$20 -> 5000 | Z22: =Equipe!$J$20 -> 5000 | AA22: =Equipe!$J$20 -> 5000 | AB22: =Equipe!$J$20 -> 5000 | ... AF22: =Equipe!$J$20 -> 5000 | AH22: =Equipe!$J$30 -> 5500 | AI22: =Equipe!$J$30 -> 5500 | AJ22: =Equipe!$J$30 -> 5500 | AK22: =Equipe!$J$30 -> 5500 | AL22: =Equipe!$J$30 -> 5500 | AM22: =Equipe!$J$30 -> 5500 | AN22: =Equipe!$J$30 -> 5500 | AO22: =Equipe!$J$30 -> 5500 | ... AS22: =Equipe!$J$30 -> 5500 | AU22: =Equipe!$J$40 -> 5500 | AV22: =Equipe!$J$40 -> 5500 | AW22: =Equipe!$J$40 -> 5500 | AX22: =Equipe!$J$40 -> 5500 | AY22: =Equipe!$J$40 -> 5500 | AZ22: =Equipe!$J$40 -> 5500 | BA22: =Equipe!$J$40 -> 5500 | BB22: =Equipe!$J$40 -> 5500 | ... BF22: =Equipe!$J$40 -> 5500 | BH22: =Equipe!$J$50 -> 6000 | BI22: =Equipe!$J$50 -> 6000 | BJ22: =Equipe!$J$50 -> 6000 | BK22: =Equipe!$J$50 -> 6000 | BL22: =Equipe!$J$50 -> 6000 | BM22: =Equipe!$J$50 -> 6000 | BN22: =Equipe!$J$50 -> 6000 | BO22: =Equipe!$J$50 -> 6000 | ... BS22: =Equipe!$J$50 -> 6000 | BU22: =Equipe!$J$60 -> 6000 | BV22: =Equipe!$J$60 -> 6000 | BW22: =Equipe!$J$60 -> 6000 | BX22: =Equipe!$J$60 -> 6000 | BY22: =Equipe!$J$60 -> 6000 | BZ22: =Equipe!$J$60 -> 6000 | CA22: =Equipe!$J$60 -> 6000 | CB22: =Equipe!$J$60 -> 6000 | ... CF22: =Equipe!$J$60 -> 6000 | CH22: =Equipe!D70 -> 6600 | CI22: =CH22 -> 6600 | CJ22: =CI22 -> 6600 | CK22: =CJ22 -> 6600 | CL22: =CK22 -> 6600 | CM22: =CL22 -> 6600 | CN22: =CM22 -> 6600 | CO22: =CN22 -> 6600 | CP22: =CO22 -> 6600 | ... CS22: =CR22 -> 6600 | CU22: =Equipe!D80 -> 7200 | CV22: =CU22 -> 7200 | CW22: =CV22 -> 7200 | CX22: =CW22 -> 7200 | CY22: =CX22 -> 7200 | CZ22: =CY22 -> 7200 | DA22: =CZ22 -> 7200 | DB22: =DA22 -> 7200 | DC22: =DB22 -> 7200 | ... DF22: =DE22 -> 7200
A23: 1.1.8 | B23: Encargos Sociais (FGTS, INSS) | D23: 0 | E23: 0 | F23: 0 | G23: 0 | H23: 0 | I23: 0 | J23: 0 | K23: 0 | L23: 0 | M23: 0 | N23: 0 | O23: 0 | P23: 0 | Q23: 0 | R23: 0 | S23: 0 | U23: 0 | V23: 0 | W23: 0 | X23: 0 | Y23: 0 | Z23: 0 | AA23: 0 | AB23: 0 | AC23: 0 | AD23: 0 | AE23: 0 | AF23: 0 | AH23: 0 | AI23: 0 | AJ23: 0 | AK23: 0 | AL23: 0 | AM23: 0 | AN23: 0 | AO23: 0 | AP23: 0 | AQ23: 0 | AR23: 0 | AS23: 0 | AU23: 0 | AV23: 0 | AW23: 0 | AX23: 0 | AY23: 0 | AZ23: 0 | BA23: 0 | BB23: 0 | BC23: 0 | BD23: 0 | BE23: 0 | BF23: 0 | BH23: 0 | BI23: 0 | BJ23: 0 | BK23: 0 | BL23: 0 | BM23: 0 | BN23: 0 | BO23: 0 | BP23: 0 | BQ23: 0 | BR23: 0 | BS23: 0 | BU23: 0 | BV23: 0 | BW23: 0 | BX23: 0 | BY23: 0 | BZ23: 0 | CA23: 0 | CB23: 0 | CC23: 0 | CD23: 0 | CE23: 0 | CF23: 0 | CH23: 0 | CI23: =CH23 -> 0 | CJ23: =CI23 -> 0 | CK23: =CJ23 -> 0 | CL23: =CK23 -> 0 | CM23: =CL23 -> 0 | CN23: =CM23 -> 0 | CO23: =CN23 -> 0 | CP23: =CO23 -> 0 | ... CS23: =CR23 -> 0 | CU23: 0 | CV23: 0 | CW23: 0 | CX23: 0 | CY23: 0 | CZ23: 0 | DA23: 0 | DB23: 0 | DC23: 0 | DD23: 0 | DE23: 0 | DF23: 0
A24: 1.1.9 | B24: Beneficios (VT, VR, Plano Saúde) | D24: 0 | E24: 0 | F24: 0 | G24: 0 | H24: 0 | I24: 0 | J24: 0 | K24: 0 | L24: 0 | M24: 0 | N24: 0 | O24: 0 | P24: 0 | Q24: 0 | R24: 0 | S24: 0 | U24: 0 | V24: 0 | W24: 0 | X24: 0 | Y24: 0 | Z24: 0 | AA24: 0 | AB24: 0 | AC24: 0 | AD24: 0 | AE24: 0 | AF24: 0 | AH24: 0 | AI24: 0 | AJ24: 0 | AK24: 0 | AL24: 0 | AM24: 0 | AN24: 0 | AO24: 0 | AP24: 0 | AQ24: 0 | AR24: 0 | AS24: 0 | AU24: 0 | AV24: 0 | AW24: 0 | AX24: 0 | AY24: 0 | AZ24: 0 | BA24: 0 | BB24: 0 | BC24: 0 | BD24: 0 | BE24: 0 | BF24: 0 | BH24: 0 | BI24: 0 | BJ24: 0 | BK24: 0 | BL24: 0 | BM24: 0 | BN24: 0 | BO24: 0 | BP24: 0 | BQ24: 0 | BR24: 0 | BS24: 0 | BU24: 0 | BV24: 0 | BW24: 0 | BX24: 0 | BY24: 0 | BZ24: 0 | CA24: 0 | CB24: 0 | CC24: 0 | CD24: 0 | CE24: 0 | CF24: 0 | CH24: 0 | CI24: =CH24 -> 0 | CJ24: =CI24 -> 0 | CK24: =CJ24 -> 0 | CL24: =CK24 -> 0 | CM24: =CL24 -> 0 | CN24: =CM24 -> 0 | CO24: =CN24 -> 0 | CP24: =CO24 -> 0 | ... CS24: =CR24 -> 0 | CU24: 0 | CV24: 0 | CW24: 0 | CX24: 0 | CY24: 0 | CZ24: 0 | DA24: 0 | DB24: 0 | DC24: 0 | DD24: 0 | DE24: 0 | DF24: 0
A25: 1.2 | B25: Despesas | C25: =SUM(C26:C29) -> 0 | D25: =SUM(D26:D29) -> 0 | E25: =SUM(E26:E29) -> 0 | F25: =SUM(F26:F29) -> 4754 | G25: =SUM(G26:G29) -> 4754 | H25: =SUM(H26:H29) -> 4754 | I25: =SUM(I26:I29) -> 4754 | J25: =SUM(J26:J29) -> 4754 | ... S25: =SUM(S26:S29) -> 4754 | U25: =SUM(U26:U29) -> 5300 | V25: =SUM(V26:V29) -> 5300 | W25: =SUM(W26:W29) -> 5300 | X25: =SUM(X26:X29) -> 5300 | Y25: =SUM(Y26:Y29) -> 5300 | Z25: =SUM(Z26:Z29) -> 5300 | AA25: =SUM(AA26:AA29) -> 5300 | AB25: =SUM(AB26:AB29) -> 5300 | ... AF25: =SUM(AF26:AF29) -> 5300 | AH25: =SUM(AH26:AH29) -> 5926.5 | AI25: =SUM(AI26:AI29) -> 5926.5 | AJ25: =SUM(AJ26:AJ29) -> 5926.5 | AK25: =SUM(AK26:AK29) -> 5926.5 | AL25: =SUM(AL26:AL29) -> 5926.5 | AM25: =SUM(AM26:AM29) -> 5926.5 | AN25: =SUM(AN26:AN29) -> 5926.5 | AO25: =SUM(AO26:AO29) -> 5926.5 | ... AS25: =SUM(AS26:AS29) -> 5926.5 | AU25: =SUM(AU26:AU29) -> 6375.15 | AV25: =SUM(AV26:AV29) -> 6375.15 | AW25: =SUM(AW26:AW29) -> 6375.15 | AX25: =SUM(AX26:AX29) -> 6375.15 | AY25: =SUM(AY26:AY29) -> 6375.15 | AZ25: =SUM(AZ26:AZ29) -> 6375.15 | BA25: =SUM(BA26:BA29) -> 6375.15 | BB25: =SUM(BB26:BB29) -> 6375.15 | ... BF25: =SUM(BF26:BF29) -> 6375.15 | BH25: =SUM(BH26:BH29) -> 6831.665 | BI25: =SUM(BI26:BI29) -> 6831.665 | BJ25: =SUM(BJ26:BJ29) -> 6831.665 | BK25: =SUM(BK26:BK29) -> 6831.665 | BL25: =SUM(BL26:BL29) -> 6831.665 | BM25: =SUM(BM26:BM29) -> 6831.665 | BN25: =SUM(BN26:BN29) -> 6831.665 | BO25: =SUM(BO26:BO29) -> 6831.665 | ... BS25: =SUM(BS26:BS29) -> 6831.665 | BU25: =SUM(BU26:BU29) -> 7296.8315 | BV25: =SUM(BV26:BV29) -> 7296.8315 | BW25: =SUM(BW26:BW29) -> 7296.8315 | BX25: =SUM(BX26:BX29) -> 7296.8315 | BY25: =SUM(BY26:BY29) -> 7296.8315 | BZ25: =SUM(BZ26:BZ29) -> 7296.8315 | CA25: =SUM(CA26:CA29) -> 7296.8315 | CB25: =SUM(CB26:CB29) -> 7296.8315 | ... CF25: =SUM(CF26:CF29) -> 7296.8315 | CH25: =SUM(CH26:CH29) -> 7401.5147 | CI25: =SUM(CI26:CI29) -> 7401.5147 | CJ25: =SUM(CJ26:CJ29) -> 7401.5147 | CK25: =SUM(CK26:CK29) -> 7401.5147 | CL25: =SUM(CL26:CL29) -> 7401.5147 | CM25: =SUM(CM26:CM29) -> 7401.5147 | CN25: =SUM(CN26:CN29) -> 7401.5147 | CO25: =SUM(CO26:CO29) -> 7401.5147 | ... CS25: =SUM(CS26:CS29) -> 7401.5147 | CU25: =SUM(CU26:CU29) -> 7701.6661 | CV25: =SUM(CV26:CV29) -> 7701.6661 | CW25: =SUM(CW26:CW29) -> 7701.6661 | CX25: =SUM(CX26:CX29) -> 7701.6661 | CY25: =SUM(CY26:CY29) -> 7701.6661 | CZ25: =SUM(CZ26:CZ29) -> 7701.6661 | DA25: =SUM(DA26:DA29) -> 7701.6661 | DB25: =SUM(DB26:DB29) -> 7701.6661 | ... DF25: =SUM(DF26:DF29) -> 7701.6661
A26: 1.2.1 | B26: Energia Elétrica | D26: 0 | E26: 0 | F26: ='Água e luz'!H3 -> 3648 | G26: =F26 -> 3648 | H26: =G26 -> 3648 | I26: =H26 -> 3648 | J26: =I26 -> 3648 | K26: =J26 -> 3648 | L26: =K26 -> 3648 | M26: =L26 -> 3648 | N26: =M26 -> 3648 | ... S26: =R26 -> 3648 | T26: 1.1 | U26: ='Água e luz'!H4 -> 3960 | V26: =U26 -> 3960 | W26: =V26 -> 3960 | X26: =W26 -> 3960 | Y26: =X26 -> 3960 | Z26: =Y26 -> 3960 | AA26: =Z26 -> 3960 | AB26: =AA26 -> 3960 | AC26: =AB26 -> 3960 | ... AF26: =AE26 -> 3960 | AG26: 1.1 | AH26: ='Água e luz'!H5 -> 4320 | AI26: =AH26 -> 4320 | AJ26: =AI26 -> 4320 | AK26: =AJ26 -> 4320 | AL26: =AK26 -> 4320 | AM26: =AL26 -> 4320 | AN26: =AM26 -> 4320 | AO26: =AN26 -> 4320 | AP26: =AO26 -> 4320 | ... AS26: =AR26 -> 4320 | AT26: 1.1 | AU26: ='Água e luz'!H6 -> 4560 | AV26: =AU26 -> 4560 | AW26: =AV26 -> 4560 | AX26: =AW26 -> 4560 | AY26: =AX26 -> 4560 | AZ26: =AY26 -> 4560 | BA26: =AZ26 -> 4560 | BB26: =BA26 -> 4560 | BC26: =BB26 -> 4560 | ... BF26: =BE26 -> 4560 | BG26: 1.1 | BH26: ='Água e luz'!H7 -> 4800 | BI26: =BH26 -> 4800 | BJ26: =BI26 -> 4800 | BK26: =BJ26 -> 4800 | BL26: =BK26 -> 4800 | BM26: =BL26 -> 4800 | BN26: =BM26 -> 4800 | BO26: =BN26 -> 4800 | BP26: =BO26 -> 4800 | ... BS26: =BR26 -> 4800 | BT26: 1.1 | BU26: ='Água e luz'!H8 -> 5040 | BV26: =BU26 -> 5040 | BW26: =BV26 -> 5040 | BX26: =BW26 -> 5040 | BY26: =BX26 -> 5040 | BZ26: =BY26 -> 5040 | CA26: =BZ26 -> 5040 | CB26: =CA26 -> 5040 | CC26: =CB26 -> 5040 | ... CF26: =CE26 -> 5040 | CG26: 1.1 | CH26: ='Água e luz'!H8 -> 5040 | CI26: =CH26 -> 5040 | CJ26: =CI26 -> 5040 | CK26: =CJ26 -> 5040 | CL26: =CK26 -> 5040 | CM26: =CL26 -> 5040 | CN26: =CM26 -> 5040 | CO26: =CN26 -> 5040 | CP26: =CO26 -> 5040 | ... CS26: =CR26 -> 5040 | CT26: 1.1 | CU26: ='Água e luz'!H9 -> 5160 | CV26: =CU26 -> 5160 | CW26: =CV26 -> 5160 | CX26: =CW26 -> 5160 | CY26: =CX26 -> 5160 | CZ26: =CY26 -> 5160 | DA26: =CZ26 -> 5160 | DB26: =DA26 -> 5160 | DC26: =DB26 -> 5160 | ... DF26: =DE26 -> 5160
A27: 1.2.2 | B27: Água | D27: 0 | E27: 0 | F27: ='Água e luz'!I3 -> 456 | G27: =F27 -> 456 | H27: =G27 -> 456 | I27: =H27 -> 456 | J27: =I27 -> 456 | K27: =J27 -> 456 | L27: =K27 -> 456 | M27: =L27 -> 456 | N27: =M27 -> 456 | ... S27: =R27 -> 456 | T27: 1.1 | U27: ='Água e luz'!I4 -> 625 | V27: =U27 -> 625 | W27: =V27 -> 625 | X27: =W27 -> 625 | Y27: =X27 -> 625 | Z27: =Y27 -> 625 | AA27: =Z27 -> 625 | AB27: =AA27 -> 625 | AC27: =AB27 -> 625 | ... AF27: =AE27 -> 625 | AG27: 1.1 | AH27: ='Água e luz'!I5 -> 820 | AI27: =AH27 -> 820 | AJ27: =AI27 -> 820 | AK27: =AJ27 -> 820 | AL27: =AK27 -> 820 | AM27: =AL27 -> 820 | AN27: =AM27 -> 820 | AO27: =AN27 -> 820 | AP27: =AO27 -> 820 | ... AS27: =AR27 -> 820 | AT27: 1.1 | AU27: ='Água e luz'!I6 -> 950 | AV27: =AU27 -> 950 | AW27: =AV27 -> 950 | AX27: =AW27 -> 950 | AY27: =AX27 -> 950 | AZ27: =AY27 -> 950 | BA27: =AZ27 -> 950 | BB27: =BA27 -> 950 | BC27: =BB27 -> 950 | ... BF27: =BE27 -> 950 | BG27: 1.1 | BH27: ='Água e luz'!I7 -> 1080 | BI27: =BH27 -> 1080 | BJ27: =BI27 -> 1080 | BK27: =BJ27 -> 1080 | BL27: =BK27 -> 1080 | BM27: =BL27 -> 1080 | BN27: =BM27 -> 1080 | BO27: =BN27 -> 1080 | BP27: =BO27 -> 1080 | ... BS27: =BR27 -> 1080 | BT27: 1.1 | BU27: ='Água e luz'!I8 -> 1210 | BV27: =BU27 -> 1210 | BW27: =BV27 -> 1210 | BX27: =BW27 -> 1210 | BY27: =BX27 -> 1210 | BZ27: =BY27 -> 1210 | CA27: =BZ27 -> 1210 | CB27: =CA27 -> 1210 | CC27: =CB27 -> 1210 | ... CF27: =CE27 -> 1210 | CG27: 1.1 | CH27: ='Água e luz'!I8 -> 1210 | CI27: =CH27 -> 1210 | CJ27: =CI27 -> 1210 | CK27: =CJ27 -> 1210 | CL27: =CK27 -> 1210 | CM27: =CL27 -> 1210 | CN27: =CM27 -> 1210 | CO27: =CN27 -> 1210 | CP27: =CO27 -> 1210 | ... CS27: =CR27 -> 1210 | CT27: 1.1 | CU27: ='Água e luz'!I9 -> 1275 | CV27: =CU27 -> 1275 | CW27: =CV27 -> 1275 | CX27: =CW27 -> 1275 | CY27: =CX27 -> 1275 | CZ27: =CY27 -> 1275 | DA27: =CZ27 -> 1275 | DB27: =DA27 -> 1275 | DC27: =DB27 -> 1275 | ... DF27: =DE27 -> 1275
A28: 1.2.3 | B28: Diversos | D28: 0 | E28: 0 | F28: 500 | G28: 500 | H28: 500 | I28: 500 | J28: 500 | K28: 500 | L28: 500 | M28: 500 | N28: 500 | O28: 500 | P28: 500 | Q28: 500 | R28: 500 | S28: 500 | T28: 1.1 | U28: =S28*T28 -> 550 | V28: =U28 -> 550 | W28: =V28 -> 550 | X28: =W28 -> 550 | Y28: =X28 -> 550 | Z28: =Y28 -> 550 | AA28: =Z28 -> 550 | AB28: =AA28 -> 550 | AC28: =AB28 -> 550 | ... AF28: =AE28 -> 550 | AG28: 1.1 | AH28: =AF28*AG28 -> 605 | AI28: =AH28 -> 605 | AJ28: =AI28 -> 605 | AK28: =AJ28 -> 605 | AL28: =AK28 -> 605 | AM28: =AL28 -> 605 | AN28: =AM28 -> 605 | AO28: =AN28 -> 605 | AP28: =AO28 -> 605 | ... AS28: =AR28 -> 605 | AT28: 1.1 | AU28: =AS28*AT28 -> 665.5 | AV28: =AU28 -> 665.5 | AW28: =AV28 -> 665.5 | AX28: =AW28 -> 665.5 | AY28: =AX28 -> 665.5 | AZ28: =AY28 -> 665.5 | BA28: =AZ28 -> 665.5 | BB28: =BA28 -> 665.5 | BC28: =BB28 -> 665.5 | ... BF28: =BE28 -> 665.5 | BG28: 1.1 | BH28: =BF28*BG28 -> 732.05 | BI28: =BH28 -> 732.05 | BJ28: =BI28 -> 732.05 | BK28: =BJ28 -> 732.05 | BL28: =BK28 -> 732.05 | BM28: =BL28 -> 732.05 | BN28: =BM28 -> 732.05 | BO28: =BN28 -> 732.05 | BP28: =BO28 -> 732.05 | ... BS28: =BR28 -> 732.05 | BT28: 1.1 | BU28: =BS28*BT28 -> 805.255 | BV28: =BU28 -> 805.255 | BW28: =BV28 -> 805.255 | BX28: =BW28 -> 805.255 | BY28: =BX28 -> 805.255 | BZ28: =BY28 -> 805.255 | CA28: =BZ28 -> 805.255 | CB28: =CA28 -> 805.255 | CC28: =CB28 -> 805.255 | ... CF28: =CE28 -> 805.255 | CG28: 1.1 | CH28: =CF28*CG28 -> 885.7805 | CI28: =CH28 -> 885.7805 | CJ28: =CI28 -> 885.7805 | CK28: =CJ28 -> 885.7805 | CL28: =CK28 -> 885.7805 | CM28: =CL28 -> 885.7805 | CN28: =CM28 -> 885.7805 | CO28: =CN28 -> 885.7805 | CP28: =CO28 -> 885.7805 | ... CS28: =CR28 -> 885.7805 | CT28: 1.1 | CU28: =CS28*CT28 -> 974.35855 | CV28: =CU28 -> 974.35855 | CW28: =CV28 -> 974.35855 | CX28: =CW28 -> 974.35855 | CY28: =CX28 -> 974.35855 | CZ28: =CY28 -> 974.35855 | DA28: =CZ28 -> 974.35855 | DB28: =DA28 -> 974.35855 | DC28: =DB28 -> 974.35855 | ... DF28: =DE28 -> 974.35855
A29: 1.2.4 | B29: Telefone e Internet | D29: 0 | E29: 0 | F29: 150 | G29: 150 | H29: 150 | I29: 150 | J29: 150 | K29: 150 | L29: 150 | M29: 150 | N29: 150 | O29: 150 | P29: 150 | Q29: 150 | R29: 150 | S29: 150 | T29: 1.1 | U29: =S29*T29 -> 165 | V29: =U29 -> 165 | W29: =V29 -> 165 | X29: =W29 -> 165 | Y29: =X29 -> 165 | Z29: =Y29 -> 165 | AA29: =Z29 -> 165 | AB29: =AA29 -> 165 | AC29: =AB29 -> 165 | ... AF29: =AE29 -> 165 | AG29: 1.1 | AH29: =AF29*AG29 -> 181.5 | AI29: =AH29 -> 181.5 | AJ29: =AI29 -> 181.5 | AK29: =AJ29 -> 181.5 | AL29: =AK29 -> 181.5 | AM29: =AL29 -> 181.5 | AN29: =AM29 -> 181.5 | AO29: =AN29 -> 181.5 | AP29: =AO29 -> 181.5 | ... AS29: =AR29 -> 181.5 | AT29: 1.1 | AU29: =AS29*AT29 -> 199.65 | AV29: =AU29 -> 199.65 | AW29: =AV29 -> 199.65 | AX29: =AW29 -> 199.65 | AY29: =AX29 -> 199.65 | AZ29: =AY29 -> 199.65 | BA29: =AZ29 -> 199.65 | BB29: =BA29 -> 199.65 | BC29: =BB29 -> 199.65 | ... BF29: =BE29 -> 199.65 | BG29: 1.1 | BH29: =BF29*BG29 -> 219.615 | BI29: =BH29 -> 219.615 | BJ29: =BI29 -> 219.615 | BK29: =BJ29 -> 219.615 | BL29: =BK29 -> 219.615 | BM29: =BL29 -> 219.615 | BN29: =BM29 -> 219.615 | BO29: =BN29 -> 219.615 | BP29: =BO29 -> 219.615 | ... BS29: =BR29 -> 219.615 | BT29: 1.1 | BU29: =BS29*BT29 -> 241.5765 | BV29: =BU29 -> 241.5765 | BW29: =BV29 -> 241.5765 | BX29: =BW29 -> 241.5765 | BY29: =BX29 -> 241.5765 | BZ29: =BY29 -> 241.5765 | CA29: =BZ29 -> 241.5765 | CB29: =CA29 -> 241.5765 | CC29: =CB29 -> 241.5765 | ... CF29: =CE29 -> 241.5765 | CG29: 1.1 | CH29: =CF29*CG29 -> 265.73415 | CI29: =CH29 -> 265.73415 | CJ29: =CI29 -> 265.73415 | CK29: =CJ29 -> 265.73415 | CL29: =CK29 -> 265.73415 | CM29: =CL29 -> 265.73415 | CN29: =CM29 -> 265.73415 | CO29: =CN29 -> 265.73415 | CP29: =CO29 -> 265.73415 | ... CS29: =CR29 -> 265.73415 | CT29: 1.1 | CU29: =CS29*CT29 -> 292.30757 | CV29: =CU29 -> 292.30757 | CW29: =CV29 -> 292.30757 | CX29: =CW29 -> 292.30757 | CY29: =CX29 -> 292.30757 | CZ29: =CY29 -> 292.30757 | DA29: =CZ29 -> 292.30757 | DB29: =DA29 -> 292.30757 | DC29: =DB29 -> 292.30757 | ... DF29: =DE29 -> 292.30757
A30: 1.3 | B30: Equipamentos | C30: =SUM(C31:C32) -> 0 | D30: =SUM(D31:D32) -> 0 | E30: =SUM(E31:E32) -> 0 | F30: =SUM(F31:F32) -> 0 | G30: =SUM(G31:G32) -> 0 | H30: =SUM(H31:H32) -> 0 | I30: =SUM(I31:I32) -> 0 | J30: =SUM(J31:J32) -> 0 | ... S30: =SUM(S31:S32) -> 300 | U30: =SUM(U31:U32) -> 330 | V30: =SUM(V31:V32) -> 330 | W30: =SUM(W31:W32) -> 330 | X30: =SUM(X31:X32) -> 330 | Y30: =SUM(Y31:Y32) -> 330 | Z30: =SUM(Z31:Z32) -> 330 | AA30: =SUM(AA31:AA32) -> 330 | AB30: =SUM(AB31:AB32) -> 330 | ... AF30: =SUM(AF31:AF32) -> 330 | AH30: =SUM(AH31:AH32) -> 363 | AI30: =SUM(AI31:AI32) -> 363 | AJ30: =SUM(AJ31:AJ32) -> 363 | AK30: =SUM(AK31:AK32) -> 363 | AL30: =SUM(AL31:AL32) -> 363 | AM30: =SUM(AM31:AM32) -> 363 | AN30: =SUM(AN31:AN32) -> 363 | AO30: =SUM(AO31:AO32) -> 363 | ... AS30: =SUM(AS31:AS32) -> 363 | AU30: =SUM(AU31:AU32) -> 399.3 | AV30: =SUM(AV31:AV32) -> 399.3 | AW30: =SUM(AW31:AW32) -> 399.3 | AX30: =SUM(AX31:AX32) -> 399.3 | AY30: =SUM(AY31:AY32) -> 399.3 | AZ30: =SUM(AZ31:AZ32) -> 399.3 | BA30: =SUM(BA31:BA32) -> 399.3 | BB30: =SUM(BB31:BB32) -> 399.3 | ... BF30: =SUM(BF31:BF32) -> 399.3 | BH30: =SUM(BH31:BH32) -> 439.23 | BI30: =SUM(BI31:BI32) -> 439.23 | BJ30: =SUM(BJ31:BJ32) -> 439.23 | BK30: =SUM(BK31:BK32) -> 439.23 | BL30: =SUM(BL31:BL32) -> 439.23 | BM30: =SUM(BM31:BM32) -> 439.23 | BN30: =SUM(BN31:BN32) -> 439.23 | BO30: =SUM(BO31:BO32) -> 439.23 | ... BS30: =SUM(BS31:BS32) -> 439.23 | BU30: =SUM(BU31:BU32) -> 483.153 | BV30: =SUM(BV31:BV32) -> 483.153 | BW30: =SUM(BW31:BW32) -> 483.153 | BX30: =SUM(BX31:BX32) -> 483.153 | BY30: =SUM(BY31:BY32) -> 483.153 | BZ30: =SUM(BZ31:BZ32) -> 483.153 | CA30: =SUM(CA31:CA32) -> 483.153 | CB30: =SUM(CB31:CB32) -> 483.153 | ... CF30: =SUM(CF31:CF32) -> 483.153 | CH30: =SUM(CH31:CH32) -> 531.4683 | CI30: =SUM(CI31:CI32) -> 531.4683 | CJ30: =SUM(CJ31:CJ32) -> 531.4683 | CK30: =SUM(CK31:CK32) -> 531.4683 | CL30: =SUM(CL31:CL32) -> 531.4683 | CM30: =SUM(CM31:CM32) -> 531.4683 | CN30: =SUM(CN31:CN32) -> 531.4683 | CO30: =SUM(CO31:CO32) -> 531.4683 | ... CS30: =SUM(CS31:CS32) -> 531.4683 | CU30: =SUM(CU31:CU32) -> 584.61513 | CV30: =SUM(CV31:CV32) -> 584.61513 | CW30: =SUM(CW31:CW32) -> 584.61513 | CX30: =SUM(CX31:CX32) -> 584.61513 | CY30: =SUM(CY31:CY32) -> 584.61513 | CZ30: =SUM(CZ31:CZ32) -> 584.61513 | DA30: =SUM(DA31:DA32) -> 584.61513 | DB30: =SUM(DB31:DB32) -> 584.61513 | ... DF30: =SUM(DF31:DF32) -> 584.61513
A31: 1.3.1 | B31: Depreciação Equip. de Produção | D31: 0 | E31: 0 | F31: 0 | G31: 0 | H31: 0 | I31: 0 | J31: 0 | K31: 0 | L31: 0 | M31: 0 | N31: 0 | O31: 0 | P31: 0 | Q31: 0 | R31: 0 | S31: 0 | T31: 1.1 | U31: =S31*T31 -> 0 | V31: =U31 -> 0 | W31: 0 | X31: 0 | Y31: 0 | Z31: 0 | AA31: 0 | AB31: 0 | AC31: 0 | AD31: 0 | AE31: 0 | AF31: 0 | AG31: 1.1 | AH31: =AF31*AG31 -> 0 | AI31: =AH31 -> 0 | AJ31: =AI31 -> 0 | AK31: =AJ31 -> 0 | AL31: =AK31 -> 0 | AM31: =AL31 -> 0 | AN31: =AM31 -> 0 | AO31: =AN31 -> 0 | AP31: =AO31 -> 0 | ... AS31: =AR31 -> 0 | AT31: 1.1 | AU31: =AS31*AT31 -> 0 | AV31: =AU31 -> 0 | AW31: 0 | AX31: 0 | AY31: 0 | AZ31: 0 | BA31: 0 | BB31: 0 | BC31: 0 | BD31: 0 | BE31: 0 | BF31: 0 | BG31: 1.1 | BH31: =BF31*BG31 -> 0 | BI31: =BH31 -> 0 | BJ31: 0 | BK31: 0 | BL31: 0 | BM31: 0 | BN31: 0 | BO31: 0 | BP31: 0 | BQ31: 0 | BR31: 0 | BS31: 0 | BT31: 1.1 | BU31: =BS31*BT31 -> 0 | BV31: =BU31 -> 0 | BW31: 0 | BX31: 0 | BY31: 0 | BZ31: 0 | CA31: 0 | CB31: 0 | CC31: 0 | CD31: 0 | CE31: 0 | CF31: 0 | CG31: 1.1 | CH31: 0 | CI31: 0 | CJ31: 0 | CK31: 0 | CL31: 0 | CM31: 0 | CN31: 0 | CO31: 0 | CP31: 0 | CQ31: 0 | CR31: 0 | CS31: 0 | CT31: 1.1 | CU31: 0 | CV31: 0 | CW31: 0 | CX31: 0 | CY31: 0 | CZ31: 0 | DA31: 0 | DB31: 0 | DC31: 0 | DD31: 0 | DE31: 0 | DF31: 0
A32: 1.3.2 | B32: Manuteção preventiva e corretiva | D32: 0 | E32: 0 | F32: 0 | G32: 0 | H32: 0 | I32: 0 | J32: 0 | K32: 0 | L32: 300 | M32: 300 | N32: 300 | O32: 300 | P32: 300 | Q32: 300 | R32: 300 | S32: 300 | T32: 1.1 | U32: =S32*T32 -> 330 | V32: =U32 -> 330 | W32: =V32 -> 330 | X32: =W32 -> 330 | Y32: =X32 -> 330 | Z32: =Y32 -> 330 | AA32: =Z32 -> 330 | AB32: =AA32 -> 330 | AC32: =AB32 -> 330 | ... AF32: =AE32 -> 330 | AG32: 1.1 | AH32: =AF32*AG32 -> 363 | AI32: =AH32 -> 363 | AJ32: =AI32 -> 363 | AK32: =AJ32 -> 363 | AL32: =AK32 -> 363 | AM32: =AL32 -> 363 | AN32: =AM32 -> 363 | AO32: =AN32 -> 363 | AP32: =AO32 -> 363 | ... AS32: =AR32 -> 363 | AT32: 1.1 | AU32: =AS32*AT32 -> 399.3 | AV32: =AU32 -> 399.3 | AW32: =AV32 -> 399.3 | AX32: =AW32 -> 399.3 | AY32: =AX32 -> 399.3 | AZ32: =AY32 -> 399.3 | BA32: =AZ32 -> 399.3 | BB32: =BA32 -> 399.3 | BC32: =BB32 -> 399.3 | ... BF32: =BE32 -> 399.3 | BG32: 1.1 | BH32: =BF32*BG32 -> 439.23 | BI32: =BH32 -> 439.23 | BJ32: =BI32 -> 439.23 | BK32: =BJ32 -> 439.23 | BL32: =BK32 -> 439.23 | BM32: =BL32 -> 439.23 | BN32: =BM32 -> 439.23 | BO32: =BN32 -> 439.23 | BP32: =BO32 -> 439.23 | ... BS32: =BR32 -> 439.23 | BT32: 1.1 | BU32: =BS32*BT32 -> 483.153 | BV32: =BU32 -> 483.153 | BW32: =BV32 -> 483.153 | BX32: =BW32 -> 483.153 | BY32: =BX32 -> 483.153 | BZ32: =BY32 -> 483.153 | CA32: =BZ32 -> 483.153 | CB32: =CA32 -> 483.153 | CC32: =CB32 -> 483.153 | ... CF32: =CE32 -> 483.153 | CG32: 1.1 | CH32: =CF32*CG32 -> 531.4683 | CI32: =CH32 -> 531.4683 | CJ32: =CI32 -> 531.4683 | CK32: =CJ32 -> 531.4683 | CL32: =CK32 -> 531.4683 | CM32: =CL32 -> 531.4683 | CN32: =CM32 -> 531.4683 | CO32: =CN32 -> 531.4683 | CP32: =CO32 -> 531.4683 | ... CS32: =CR32 -> 531.4683 | CT32: 1.1 | CU32: =CS32*CT32 -> 584.61513 | CV32: =CU32 -> 584.61513 | CW32: =CV32 -> 584.61513 | CX32: =CW32 -> 584.61513 | CY32: =CX32 -> 584.61513 | CZ32: =CY32 -> 584.61513 | DA32: =CZ32 -> 584.61513 | DB32: =DA32 -> 584.61513 | DC32: =DB32 -> 584.61513 | ... DF32: =DE32 -> 584.61513
