Workbook

Sheet Orçamento
A1: Item | B1: Receita | C1: 47849 | D1: 47880 | E1: 47908 | F1: 47939 | G1: 47969 | H1: 48000 | I1: 48030 | J1: 48061 | K1: 48092 | L1: 48122 | M1: 48153 | N1: 48183 | T1: Total Acumulado Ano 1 | U1: 48214 | V1: 48245 | W1: 48274 | X1: 48305 | Y1: 48335 | Z1: 48366 | AA1: 48396 | AB1: 48427 | AC1: 48458 | AD1: 48488 | AE1: 48519 | AF1: 48549 | AG1: Total Acumulado Ano 2 | AH1: 48580 | AI1: 48611 | AJ1: 48639 | AK1: 48670 | AL1: 48700 | AM1: 48731 | AN1: 48761 | AO1: 48792 | AP1: 48823 | AQ1: 48853 | AR1: 48884 | AS1: 48914 | AT1: Total Acumulado Ano 3 | AU1: 48945 | AV1: 48976 | AW1: 49004 | AX1: 49035 | AY1: 49065 | AZ1: 49096 | BA1: 49126 | BB1: 49157 | BC1: 49188 | BD1: 49218 | BE1: 49249 | BF1: 49279 | BG1: Total Acumulado Ano 4 | BH1: 49310 | BI1: 49341 | BJ1: 49369 | BK1: 49400 | BL1: 49430 | BM1: 49461 | BN1: 49491 | BO1: 49522 | BP1: 49553 | BQ1: 49583 | BR1: 49614 | BS1: 49644 | BT1: Total Acumulado Ano 5 | BU1: 49675 | BV1: 49706 | BW1: 49735 | BX1: 49766 | BY1: 49796 | BZ1: 49827 | CA1: 49857 | CB1: 49888 | CC1: 49919 | CD1: 49949 | CE1: 49980 | CF1: 50010 | CG1: Total Acumulado Ano 6 | CH1: Total acumulado pós custo capital
A2: 1 | B2: RECEITATtOTAL | C2: 0 | D2: 0 | E2: 0 | F2: =('Cálcul. trabalhado'!I3)/2 -> 2453.8125 | G2: =F2*2 -> 4907.625 | H2: ='Cálcul. trabalhado'!I4 -> 26432.75 | I2: =H2 -> 26432.75 | J2: =I2 -> 26432.75 | K2: =J2 -> 26432.75 | L2: =K2 -> 26432.75 | M2: =L2 -> 26432.75 | N2: =M2 -> 26432.75 | T2: =SUM(F2:S2) -> 192390.69 | U2: ='Cálcul. trabalhado'!I5 -> 55271.875 | V2: =U2 -> 55271.875 | W2: =V2 -> 55271.875 | X2: =W2 -> 55271.875 | Y2: =X2 -> 55271.875 | Z2: =Y2 -> 55271.875 | AA2: =Z2 -> 55271.875 | AB2: =AA2 -> 55271.875 | AC2: =AB2 -> 55271.875 | ... AF2: =AE2 -> 55271.875 | AG2: =SUM(T2:AF2) -> 855653.19 | AH2: ='Cálcul. trabalhado'!I6 -> 88435 | AI2: =AH2 -> 88435 | AJ2: =AI2 -> 88435 | AK2: =AJ2 -> 88435 | AL2: =AK2 -> 88435 | AM2: =AL2 -> 88435 | AN2: =AM2 -> 88435 | AO2: =AN2 -> 88435 | AP2: =AO2 -> 88435 | ... AS2: =AR2 -> 88435 | AT2: =SUM(AG2:AS2) -> 1916873.2 | AU2: ='Cálcul. trabalhado'!I7 -> 110543.75 | AV2: =AU2 -> 110543.75 | AW2: =AV2 -> 110543.75 | AX2: =AW2 -> 110543.75 | AY2: =AX2 -> 110543.75 | AZ2: =AY2 -> 110543.75 | BA2: =AZ2 -> 110543.75 | BB2: =BA2 -> 110543.75 | BC2: =BB2 -> 110543.75 | ... BF2: =BE2 -> 110543.75 | BG2: =SUM(AT2:BF2) -> 3243398.2 | BH2: ='Cálcul. trabalhado'!I8 -> 132652.5 | BI2: =BH2 -> 132652.5 | BJ2: =BI2 -> 132652.5 | BK2: =BJ2 -> 132652.5 | BL2: =BK2 -> 132652.5 | BM2: =BL2 -> 132652.5 | BN2: =BM2 -> 132652.5 | BO2: =BN2 -> 132652.5 | BP2: =BO2 -> 132652.5 | ... BS2: =BR2 -> 132652.5 | BT2: =SUM(BG2:BS2) -> 4835228.2 | BU2: ='Cálcul. trabalhado'!I9 -> 154761.25 | BV2: =BU2 -> 154761.25 | BW2: =BV2 -> 154761.25 | BX2: =BW2 -> 154761.25 | BY2: =BX2 -> 154761.25 | BZ2: =BY2 -> 154761.25 | CA2: =BZ2 -> 154761.25 | CB2: =CA2 -> 154761.25 | CC2: =CB2 -> 154761.25 | ... CF2: =CE2 -> 154761.25 | CG2: =SUM(BT2:CF2) -> 6692363.2
B5: Resultado | C5: =C2-C8 -> -19000 | D5: =D2-D8 -> -19000 | E5: =E2-E8 -> -789410.26 | F5: =F2-F8 -> -29114.983 | G5: =G2-G8 -> -26808.399 | H5: =H2-H8 -> -7416.5613 | I5: =I2-I8 -> -7416.5613 | J5: =J2-J8 -> -7416.5613 | ... N5: =N2-N8 -> -7716.5613 | T5: =SUM(C5:S5) -> -936149.57 | U5: =U2-U8 -> 15050.347 | V5: =V2-V8 -> 15050.347 | W5: =W2-W8 -> 9340.7622 | X5: =X2-X8 -> 9340.7622 | Y5: =Y2-Y8 -> 9340.7622 | Z5: =Z2-Z8 -> 9340.7622 | AA5: =AA2-AA8 -> 9340.7622 | AB5: =AB2-AB8 -> 9340.7622 | ... AF5: =AF2-AF8 -> 9340.7622 | AG5: =SUM(T5:AF5) -> -812641.26 | AH5: =AH2-AH8 -> 32228.109 | AI5: =AI2-AI8 -> 32228.109 | AJ5: =AJ2-AJ8 -> 32228.109 | AK5: =AK2-AK8 -> 32228.109 | AL5: =AL2-AL8 -> 32228.109 | AM5: =AM2-AM8 -> 32228.109 | AN5: =AN2-AN8 -> 32228.109 | AO5: =AO2-AO8 -> 32228.109 | ... AS5: =AS2-AS8 -> 32228.109 | AT5: =SUM(AG5:AS5) -> -425903.94 | AU5: =AU2-AU8 -> 46174.731 | AV5: =AV2-AV8 -> 46174.731 | AW5: =AW2-AW8 -> 46174.731 | AX5: =AX2-AX8 -> 46174.731 | AY5: =AY2-AY8 -> 46174.731 | AZ5: =AZ2-AZ8 -> 46174.731 | BA5: =BA2-BA8 -> 46174.731 | BB5: =BB2-BB8 -> 46174.731 | ... BF5: =BF2-BF8 -> 46174.731 | BG5: =SUM(AT5:BF5) -> 128192.83 | BH5: =BH2-BH8 -> 59785.977 | BI5: =BI2-BI8 -> 59785.977 | BJ5: =BJ2-BJ8 -> 59785.977 | BK5: =BK2-BK8 -> 59785.977 | BL5: =BL2-BL8 -> 59785.977 | BM5: =BM2-BM8 -> 59785.977 | BN5: =BN2-BN8 -> 59785.977 | BO5: =BO2-BO8 -> 59785.977 | ... BS5: =BS2-BS8 -> 59785.977 | BT5: =SUM(BG5:BS5) -> 845624.56 | BU5: =BU2-BU8 -> 73036.289 | BV5: =BV2-BV8 -> 73036.289 | BW5: =BW2-BW8 -> 73036.289 | BX5: =BX2-BX8 -> 73036.289 | BY5: =BY2-BY8 -> 73036.289 | BZ5: =BZ2-BZ8 -> 73036.289 | CA5: =CA2-CA8 -> 73036.289 | CB5: =CB2-CB8 -> 73036.289 | ... CF5: =CF2-CF8 -> 73036.289 | CG5: =SUM(BT5:CF5) -> 1722060 | CH5: ='Custo investimento '!D31 -> 652609.33
B6: Margem | F6: =F5/F2 -> -11.865203 | G6: =G5/G2 -> -5.4626014 | H6: =H5/H2 -> -0.28058228 | I6: =I5/I2 -> -0.28058228 | J6: =J5/J2 -> -0.28058228 | K6: =K5/K2 -> -0.28058228 | L6: =L5/L2 -> -0.29193184 | M6: =M5/M2 -> -0.29193184 | N6: =N5/N2 -> -0.29193184 | U6: =U5/U2 -> 0.27229666 | V6: =V5/V2 -> 0.27229666 | W6: =W5/W2 -> 0.16899666 | X6: =X5/X2 -> 0.16899666 | Y6: =Y5/Y2 -> 0.16899666 | Z6: =Z5/Z2 -> 0.16899666 | AA6: =AA5/AA2 -> 0.16899666 | AB6: =AB5/AB2 -> 0.16899666 | ... AF6: =AF5/AF2 -> 0.16899666 | AH6: =AH5/AH2 -> 0.36442709 | AI6: =AI5/AI2 -> 0.36442709 | AJ6: =AJ5/AJ2 -> 0.36442709 | AK6: =AK5/AK2 -> 0.36442709 | AL6: =AL5/AL2 -> 0.36442709 | AM6: =AM5/AM2 -> 0.36442709 | AN6: =AN5/AN2 -> 0.36442709 | AO6: =AO5/AO2 -> 0.36442709 | ... AS6: =AS5/AS2 -> 0.36442709 | AU6: =AU5/AU2 -> 0.41770549 | AV6: =AV5/AV2 -> 0.41770549 | AW6: =AW5/AW2 -> 0.41770549 | AX6: =AX5/AX2 -> 0.41770549 | AY6: =AY5/AY2 -> 0.41770549 | AZ6: =AZ5/AZ2 -> 0.41770549 | BA6: =BA5/BA2 -> 0.41770549 | BB6: =BB5/BB2 -> 0.41770549 | ... BF6: =BF5/BF2 -> 0.41770549 | BH6: =BH5/BH2 -> 0.45069619 | BI6: =BI5/BI2 -> 0.45069619 | BJ6: =BJ5/BJ2 -> 0.45069619 | BK6: =BK5/BK2 -> 0.45069619 | BL6: =BL5/BL2 -> 0.45069619 | BM6: =BM5/BM2 -> 0.45069619 | BN6: =BN5/BN2 -> 0.45069619 | BO6: =BO5/BO2 -> 0.45069619 | ... BS6: =BS5/BS2 -> 0.45069619 | BU6: =BU5/BU2 -> 0.47192878 | BV6: =BV5/BV2 -> 0.47192878 | BW6: =BW5/BW2 -> 0.47192878 | BX6: =BX5/BX2 -> 0.47192878 | BY6: =BY5/BY2 -> 0.47192878 | BZ6: =BZ5/BZ2 -> 0.47192878 | CA6: =CA5/CA2 -> 0.47192878 | CB6: =CB5/CB2 -> 0.47192878 | ... CF6: =CF5/CF2 -> 0.47192878
B8: Total Fixo + Variável | C8: =C10+C53 -> 19000 | D8: =D10+D53 -> 19000 | E8: =E10+E53 -> 789410.26 | F8: =F10+F53 -> 31568.796 | G8: =G10+G53 -> 31716.024 | H8: =H10+H53 -> 33849.311 | I8: =I10+I53 -> 33849.311 | J8: =J10+J53 -> 33849.311 | ... N8: =N10+N53 -> 34149.311 | U8: =U10+U53 -> 40221.528 | V8: =V10+V53 -> 40221.528 | W8: =W10+W53 -> 45931.113 | X8: =X10+X53 -> 45931.113 | Y8: =Y10+Y53 -> 45931.113 | Z8: =Z10+Z53 -> 45931.113 | AA8: =AA10+AA53 -> 45931.113 | AB8: =AB10+AB53 -> 45931.113 | ... AF8: =AF10+AF53 -> 45931.113 | AH8: =AH10+AH53 -> 56206.891 | AI8: =AI10+AI53 -> 56206.891 | AJ8: =AJ10+AJ53 -> 56206.891 | AK8: =AK10+AK53 -> 56206.891 | AL8: =AL10+AL53 -> 56206.891 | AM8: =AM10+AM53 -> 56206.891 | AN8: =AN10+AN53 -> 56206.891 | AO8: =AO10+AO53 -> 56206.891 | ... AS8: =AS10+AS53 -> 56206.891 | AU8: =AU10+AU53 -> 64369.019 | AV8: =AV10+AV53 -> 64369.019 | AW8: =AW10+AW53 -> 64369.019 | AX8: =AX10+AX53 -> 64369.019 | AY8: =AY10+AY53 -> 64369.019 | AZ8: =AZ10+AZ53 -> 64369.019 | BA8: =BA10+BA53 -> 64369.019 | BB8: =BB10+BB53 -> 64369.019 | ... BF8: =BF10+BF53 -> 64369.019 | BH8: =BH10+BH53 -> 72866.523 | BI8: =BI10+BI53 -> 72866.523 | BJ8: =BJ10+BJ53 -> 72866.523 | BK8: =BK10+BK53 -> 72866.523 | BL8: =BL10+BL53 -> 72866.523 | BM8: =BM10+BM53 -> 72866.523 | BN8: =BN10+BN53 -> 72866.523 | BO8: =BO10+BO53 -> 72866.523 | ... BS8: =BS10+BS53 -> 72866.523 | BU8: =BU10+BU53 -> 81724.961 | BV8: =BV10+BV53 -> 81724.961 | BW8: =BW10+BW53 -> 81724.961 | BX8: =BX10+BX53 -> 81724.961 | BY8: =BY10+BY53 -> 81724.961 | BZ8: =BZ10+BZ53 -> 81724.961 | CA8: =CA10+CA53 -> 81724.961 | CB8: =CB10+CB53 -> 81724.961 | ... CF8: =CF10+CF53 -> 81724.961
A9: Item | B9: Conta | C9: 11324 | D9: 11355 | E9: 11383 | F9: 11414 | G9: 11444 | H9: 11475 | I9: 11505 | J9: 11536 | K9: 11567 | L9: 11597 | M9: 11628 | N9: 11658 | T9: Reajuste 10% | U9: 48214 | V9: 48245 | W9: 48274 | X9: 48305 | Y9: 48335 | Z9: 48366 | AA9: 48396 | AB9: 48427 | AC9: 48458 | AD9: 48488 | AE9: 48519 | AF9: 48549 | AH9: 48580 | AI9: 48611 | AJ9: 48639 | AK9: 48670 | AL9: 48700 | AM9: 48731 | AN9: 48761 | AO9: 48792 | AP9: 48823 | AQ9: 48853 | AR9: 48884 | AS9: 48914 | AU9: 48945 | AV9: 48976 | AW9: 49004 | AX9: 49035 | AY9: 49065 | AZ9: 49096 | BA9: 49126 | BB9: 49157 | BC9: 49188 | BD9: 49218 | BE9: 49249 | BF9: 49279 | BH9: 49310 | BI9: 49341 | BJ9: 49369 | BK9: 49400 | BL9: 49430 | BM9: 49461 | BN9: 49491 | BO9: 49522 | BP9: 49553 | BQ9: 49583 | BR9: 49614 | BS9: 49644 | BU9: 49675 | BV9: 49706 | BW9: 49735 | BX9: 49766 | BY9: 49796 | BZ9: 49827 | CA9: 49857 | CB9: 49888 | CC9: 49919 | CD9: 49949 | CE9: 49980 | CF9: 50010
A10: 1 | B10: Custos Fixos | C10: =C11+C15+C25+C30+C33+C38+C46+C50 -> 19000 | D10: =D11+D15+D25+D30+D33+D38+D46+D50 -> 19000 | E10: =E11+E15+E25+E30+E33+E38+E46+E50 -> 19000 | F10: =F11+F15+F25+F30+F33+F38+F46+F50 -> 31378.767 | G10: =G11+G15+G25+G30+G33+G38+G46+G50 -> 31378.767 | H10: =H11+H15+H25+H30+H33+H38+H46+H50 -> 32132.146 | I10: =I11+I15+I25+I30+I33+I38+I46+I50 -> 32132.146 | J10: =J11+J15+J25+J30+J33+J38+J46+J50 -> 32132.146 | ... N10: =N11+N15+N25+N30+N33+N38+N46+N50 -> 32432.146 | U10: =U11+U15+U25+U30+U33+U38+U46+U50 -> 36662.816 | V10: =V11+V15+V25+V30+V33+V38+V46+V50 -> 36662.816 | W10: =W11+W15+W25+W30+W33+W38+W46+W50 -> 36662.816 | X10: =X11+X15+X25+X30+X33+X38+X46+X50 -> 36662.816 | Y10: =Y11+Y15+Y25+Y30+Y33+Y38+Y46+Y50 -> 36662.816 | Z10: =Z11+Z15+Z25+Z30+Z33+Z38+Z46+Z50 -> 36662.816 | AA10: =AA11+AA15+AA25+AA30+AA33+AA38+AA46+AA50 -> 36662.816 | AB10: =AB11+AB15+AB25+AB30+AB33+AB38+AB46+AB50 -> 36662.816 | ... AF10: =AF11+AF15+AF25+AF30+AF33+AF38+AF46+AF50 -> 36662.816 | AH10: =AH11+AH15+AH25+AH30+AH33+AH38+AH46+AH50 -> 41392.855 | AI10: =AI11+AI15+AI25+AI30+AI33+AI38+AI46+AI50 -> 41392.855 | AJ10: =AJ11+AJ15+AJ25+AJ30+AJ33+AJ38+AJ46+AJ50 -> 41392.855 | AK10: =AK11+AK15+AK25+AK30+AK33+AK38+AK46+AK50 -> 41392.855 | AL10: =AL11+AL15+AL25+AL30+AL33+AL38+AL46+AL50 -> 41392.855 | AM10: =AM11+AM15+AM25+AM30+AM33+AM38+AM46+AM50 -> 41392.855 | AN10: =AN11+AN15+AN25+AN30+AN33+AN38+AN46+AN50 -> 41392.855 | AO10: =AO11+AO15+AO25+AO30+AO33+AO38+AO46+AO50 -> 41392.855 | ... AS10: =AS11+AS15+AS25+AS30+AS33+AS38+AS46+AS50 -> 41392.855 | AU10: =AU11+AU15+AU25+AU30+AU33+AU38+AU46+AU50 -> 45852.424 | AV10: =AV11+AV15+AV25+AV30+AV33+AV38+AV46+AV50 -> 45852.424 | AW10: =AW11+AW15+AW25+AW30+AW33+AW38+AW46+AW50 -> 45852.424 | AX10: =AX11+AX15+AX25+AX30+AX33+AX38+AX46+AX50 -> 45852.424 | AY10: =AY11+AY15+AY25+AY30+AY33+AY38+AY46+AY50 -> 45852.424 | AZ10: =AZ11+AZ15+AZ25+AZ30+AZ33+AZ38+AZ46+AZ50 -> 45852.424 | BA10: =BA11+BA15+BA25+BA30+BA33+BA38+BA46+BA50 -> 45852.424 | BB10: =BB11+BB15+BB25+BB30+BB33+BB38+BB46+BB50 -> 45852.424 | ... BF10: =BF11+BF15+BF25+BF30+BF33+BF38+BF46+BF50 -> 45852.424 | BH10: =BH11+BH15+BH25+BH30+BH33+BH38+BH46+BH50 -> 50643.57 | BI10: =BI11+BI15+BI25+BI30+BI33+BI38+BI46+BI50 -> 50643.57 | BJ10: =BJ11+BJ15+BJ25+BJ30+BJ33+BJ38+BJ46+BJ50 -> 50643.57 | BK10: =BK11+BK15+BK25+BK30+BK33+BK38+BK46+BK50 -> 50643.57 | BL10: =BL11+BL15+BL25+BL30+BL33+BL38+BL46+BL50 -> 50643.57 | BM10: =BM11+BM15+BM25+BM30+BM33+BM38+BM46+BM50 -> 50643.57 | BN10: =BN11+BN15+BN25+BN30+BN33+BN38+BN46+BN50 -> 50643.57 | BO10: =BO11+BO15+BO25+BO30+BO33+BO38+BO46+BO50 -> 50643.57 | ... BS10: =BS11+BS15+BS25+BS30+BS33+BS38+BS46+BS50 -> 50643.57 | BU10: =BU11+BU15+BU25+BU30+BU33+BU38+BU46+BU50 -> 55799.449 | BV10: =BV11+BV15+BV25+BV30+BV33+BV38+BV46+BV50 -> 55799.449 | BW10: =BW11+BW15+BW25+BW30+BW33+BW38+BW46+BW50 -> 55799.449 | BX10: =BX11+BX15+BX25+BX30+BX33+BX38+BX46+BX50 -> 55799.449 | BY10: =BY11+BY15+BY25+BY30+BY33+BY38+BY46+BY50 -> 55799.449 | BZ10: =BZ11+BZ15+BZ25+BZ30+BZ33+BZ38+BZ46+BZ50 -> 55799.449 | CA10: =CA11+CA15+CA25+CA30+CA33+CA38+CA46+CA50 -> 55799.449 | CB10: =CB11+CB15+CB25+CB30+CB33+CB38+CB46+CB50 -> 55799.449 | ... CF10: =CF11+CF15+CF25+CF30+CF33+CF38+CF46+CF50 -> 55799.449
A11: 1.0 | B11: Aluguel/Parcelmento Imóvel | C11: =C12+C13+C14 -> 19000 | D11: =D12+D13+D14 -> 19000 | E11: =E12+E13+E14 -> 19000 | F11: =F12+F13+F14 -> 19000 | G11: =G12+G13+G14 -> 19000 | H11: =H12+H13+H14 -> 19000 | I11: =I12+I13+I14 -> 19000 | J11: =J12+J13+J14 -> 19000 | ... N11: =N12+N13+N14 -> 19000 | U11: =U12+U13+U14 -> 20900 | V11: =V12+V13+V14 -> 20900 | W11: =W12+W13+W14 -> 20900 | X11: =X12+X13+X14 -> 20900 | Y11: =Y12+Y13+Y14 -> 20900 | Z11: =Z12+Z13+Z14 -> 20900 | AA11: =AA12+AA13+AA14 -> 20900 | AB11: =AB12+AB13+AB14 -> 20900 | ... AF11: =AF12+AF13+AF14 -> 20900 | AH11: =AH12+AH13+AH14 -> 22990 | AI11: =AI12+AI13+AI14 -> 22990 | AJ11: =AJ12+AJ13+AJ14 -> 22990 | AK11: =AK12+AK13+AK14 -> 22990 | AL11: =AL12+AL13+AL14 -> 22990 | AM11: =AM12+AM13+AM14 -> 22990 | AN11: =AN12+AN13+AN14 -> 22990 | AO11: =AO12+AO13+AO14 -> 22990 | ... AS11: =AS12+AS13+AS14 -> 22990 | AU11: =AU12+AU13+AU14 -> 25289 | AV11: =AV12+AV13+AV14 -> 25289 | AW11: =AW12+AW13+AW14 -> 25289 | AX11: =AX12+AX13+AX14 -> 25289 | AY11: =AY12+AY13+AY14 -> 25289 | AZ11: =AZ12+AZ13+AZ14 -> 25289 | BA11: =BA12+BA13+BA14 -> 25289 | BB11: =BB12+BB13+BB14 -> 25289 | ... BF11: =BF12+BF13+BF14 -> 25289 | BH11: =BH12+BH13+BH14 -> 27817.9 | BI11: =BI12+BI13+BI14 -> 27817.9 | BJ11: =BJ12+BJ13+BJ14 -> 27817.9 | BK11: =BK12+BK13+BK14 -> 27817.9 | BL11: =BL12+BL13+BL14 -> 27817.9 | BM11: =BM12+BM13+BM14 -> 27817.9 | BN11: =BN12+BN13+BN14 -> 27817.9 | BO11: =BO12+BO13+BO14 -> 27817.9 | ... BS11: =BS12+BS13+BS14 -> 27817.9 | BU11: =BU12+BU13+BU14 -> 30599.69 | BV11: =BV12+BV13+BV14 -> 30599.69 | BW11: =BW12+BW13+BW14 -> 30599.69 | BX11: =BX12+BX13+BX14 -> 30599.69 | BY11: =BY12+BY13+BY14 -> 30599.69 | BZ11: =BZ12+BZ13+BZ14 -> 30599.69 | CA11: =CA12+CA13+CA14 -> 30599.69 | CB11: =CB12+CB13+CB14 -> 30599.69 | ... CF11: =CF12+CF13+CF14 -> 30599.69
A12: 1.0.1 | B12: Aluguel/Parcelmento Imóvel | C12: =Financiamento!B2 -> 19000 | D12: =Financiamento!B2 -> 19000 | E12: =Financiamento!B2 -> 19000 | F12: =Financiamento!B2 -> 19000 | G12: =Financiamento!B2 -> 19000 | H12: =Financiamento!$B$2 -> 19000 | I12: =Financiamento!$B$2 -> 19000 | J12: =Financiamento!$B$2 -> 19000 | K12: =Financiamento!$B$2 -> 19000 | L12: =Financiamento!$B$2 -> 19000 | M12: =Financiamento!$B$2 -> 19000 | N12: =Financiamento!$B$2 -> 19000 | T12: 1.1 | U12: =Financiamento!$B$2*$T$12 -> 20900 | V12: =Financiamento!$B$2*$T$12 -> 20900 | W12: =Financiamento!$B$2*$T$12 -> 20900 | X12: =Financiamento!$B$2*$T$12 -> 20900 | Y12: =Financiamento!$B$2*$T$12 -> 20900 | Z12: =Financiamento!$B$2*$T$12 -> 20900 | AA12: =Financiamento!$B$2*$T$12 -> 20900 | AB12: =Financiamento!$B$2*$T$12 -> 20900 | ... AF12: =Financiamento!$B$2*$T$12 -> 20900 | AG12: 1.1 | AH12: =$AF$12*$AG$12 -> 22990 | AI12: =$AF$12*$AG$12 -> 22990 | AJ12: =$AF$12*$AG$12 -> 22990 | AK12: =$AF$12*$AG$12 -> 22990 | AL12: =$AF$12*$AG$12 -> 22990 | AM12: =$AF$12*$AG$12 -> 22990 | AN12: =$AF$12*$AG$12 -> 22990 | AO12: =$AF$12*$AG$12 -> 22990 | ... AS12: =$AF$12*$AG$12 -> 22990 | AT12: 1.1 | AU12: =$AS$12*$AT$12 -> 25289 | AV12: =$AS$12*$AT$12 -> 25289 | AW12: =$AS$12*$AT$12 -> 25289 | AX12: =$AS$12*$AT$12 -> 25289 | AY12: =$AS$12*$AT$12 -> 25289 | AZ12: =$AS$12*$AT$12 -> 25289 | BA12: =$AS$12*$AT$12 -> 25289 | BB12: =$AS$12*$AT$12 -> 25289 | ... BF12: =$AS$12*$AT$12 -> 25289 | BG12: 1.1 | BH12: =$BF$12*$BG$12 -> 27817.9 | BI12: =$BF$12*$BG$12 -> 27817.9 | BJ12: =$BF$12*$BG$12 -> 27817.9 | BK12: =$BF$12*$BG$12 -> 27817.9 | BL12: =$BF$12*$BG$12 -> 27817.9 | BM12: =$BF$12*$BG$12 -> 27817.9 | BN12: =$BF$12*$BG$12 -> 27817.9 | BO12: =$BF$12*$BG$12 -> 27817.9 | ... BS12: =$BF$12*$BG$12 -> 27817.9 | BT12: 1.1 | BU12: =$BS$12*$BT$12 -> 30599.69 | BV12: =$BS$12*$BT$12 -> 30599.69 | BW12: =$BS$12*$BT$12 -> 30599.69 | BX12: =$BS$12*$BT$12 -> 30599.69 | BY12: =$BS$12*$BT$12 -> 30599.69 | BZ12: =$BS$12*$BT$12 -> 30599.69 | CA12: =$BS$12*$BT$12 -> 30599.69 | CB12: =$BS$12*$BT$12 -> 30599.69 | ... CF12: =$BS$12*$BT$12 -> 30599.69
D13: 0 | E13: 0 | F13: 0 | G13: 0 | H13: 0 | I13: 0 | J13: 0 | K13: 0 | L13: 0 | M13: 0 | N13: 0 | U13: 0 | V13: 0 | W13: 0 | X13: 0 | Y13: 0 | Z13: 0 | AA13: 0 | AB13: 0 | AC13: 0 | AD13: 0 | AE13: 0 | AF13: 0 | AH13: 0 | AI13: 0 | AJ13: 0 | AK13: 0 | AL13: 0 | AM13: 0 | AN13: 0 | AO13: 0 | AP13: 0 | AQ13: 0 | AR13: 0 | AS13: 0 | AU13: 0 | AV13: 0 | AW13: 0 | AX13: 0 | AY13: 0 | AZ13: 0 | BA13: 0 | BB13: 0 | BC13: 0 | BD13: 0 | BE13: 0 | BF13: 0 | BH13: 0 | BI13: 0 | BJ13: 0 | BK13: 0 | BL13: 0 | BM13: 0 | BN13: 0 | BO13: 0 | BP13: 0 | BQ13: 0 | BR13: 0 | BS13: 0 | BU13: 0 | BV13: 0 | BW13: 0 | BX13: 0 | BY13: 0 | BZ13: 0 | CA13: 0 | CB13: 0 | CC13: 0 | CD13: 0 | CE13: 0 | CF13: 0
D14: 0 | E14: 0 | F14: 0 | G14: 0 | H14: 0 | I14: 0 | J14: 0 | K14: 0 | L14: 0 | M14: 0 | N14: 0 | U14: 0 | V14: 0 | W14: 0 | X14: 0 | Y14: 0 | Z14: 0 | AA14: 0 | AB14: 0 | AC14: 0 | AD14: 0 | AE14: 0 | AF14: 0 | AH14: 0 | AI14: 0 | AJ14: 0 | AK14: 0 | AL14: 0 | AM14: 0 | AN14: 0 | AO14: 0 | AP14: 0 | AQ14: 0 | AR14: 0 | AS14: 0 | AU14: 0 | AV14: 0 | AW14: 0 | AX14: 0 | AY14: 0 | AZ14: 0 | BA14: 0 | BB14: 0 | BC14: 0 | BD14: 0 | BE14: 0 | BF14: 0 | BH14: 0 | BI14: 0 | BJ14: 0 | BK14: 0 | BL14: 0 | BM14: 0 | BN14: 0 | BO14: 0 | BP14: 0 | BQ14: 0 | BR14: 0 | BS14: 0 | BU14: 0 | BV14: 0 | BW14: 0 | BX14: 0 | BY14: 0 | BZ14: 0 | CA14: 0 | CB14: 0 | CC14: 0 | CD14: 0 | CE14: 0 | CF14: 0
A15: 1.1 | B15: Salários | C15: =SUM(C16:C24) -> 0 | D15: =SUM(D16:D24) -> 0 | E15: =SUM(E16:E24) -> 0 | F15: =SUM(F16:F24) -> 3960 | G15: =SUM(G16:G24) -> 3960 | H15: =SUM(H16:H24) -> 3960 | I15: =SUM(I16:I24) -> 3960 | J15: =SUM(J16:J24) -> 3960 | ... N15: =SUM(N16:N24) -> 3960 | U15: =SUM(U16:U24) -> 4356 | V15: =SUM(V16:V24) -> 4356 | W15: =SUM(W16:W24) -> 4356 | X15: =SUM(X16:X24) -> 4356 | Y15: =SUM(Y16:Y24) -> 4356 | Z15: =SUM(Z16:Z24) -> 4356 | AA15: =SUM(AA16:AA24) -> 4356 | AB15: =SUM(AB16:AB24) -> 4356 | ... AF15: =SUM(AF16:AF24) -> 4356 | AH15: =SUM(AH16:AH24) -> 4791.6 | AI15: =SUM(AI16:AI24) -> 4791.6 | AJ15: =SUM(AJ16:AJ24) -> 4791.6 | AK15: =SUM(AK16:AK24) -> 4791.6 | AL15: =SUM(AL16:AL24) -> 4791.6 | AM15: =SUM(AM16:AM24) -> 4791.6 | AN15: =SUM(AN16:AN24) -> 4791.6 | AO15: =SUM(AO16:AO24) -> 4791.6 | ... AS15: =SUM(AS16:AS24) -> 4791.6 | AU15: =SUM(AU16:AU24) -> 5270.76 | AV15: =SUM(AV16:AV24) -> 5270.76 | AW15: =SUM(AW16:AW24) -> 5270.76 | AX15: =SUM(AX16:AX24) -> 5270.76 | AY15: =SUM(AY16:AY24) -> 5270.76 | AZ15: =SUM(AZ16:AZ24) -> 5270.76 | BA15: =SUM(BA16:BA24) -> 5270.76 | BB15: =SUM(BB16:BB24) -> 5270.76 | ... BF15: =SUM(BF16:BF24) -> 5270.76 | BH15: =SUM(BH16:BH24) -> 5797.836 | BI15: =SUM(BI16:BI24) -> 5797.836 | BJ15: =SUM(BJ16:BJ24) -> 5797.836 | BK15: =SUM(BK16:BK24) -> 5797.836 | BL15: =SUM(BL16:BL24) -> 5797.836 | BM15: =SUM(BM16:BM24) -> 5797.836 | BN15: =SUM(BN16:BN24) -> 5797.836 | BO15: =SUM(BO16:BO24) -> 5797.836 | ... BS15: =SUM(BS16:BS24) -> 5797.836 | BU15: =SUM(BU16:BU24) -> 6377.6196 | BV15: =SUM(BV16:BV24) -> 6377.6196 | BW15: =SUM(BW16:BW24) -> 6377.6196 | BX15: =SUM(BX16:BX24) -> 6377.6196 | BY15: =SUM(BY16:BY24) -> 6377.6196 | BZ15: =SUM(BZ16:BZ24) -> 6377.6196 | CA15: =SUM(CA16:CA24) -> 6377.6196 | CB15: =SUM(CB16:CB24) -> 6377.6196 | ... CF15: =SUM(CF16:CF24) -> 6377.6196
A16: 1.1.1 | B16: Funcionários Limpeza | D16: 0 | E16: 0 | F16: =Equipe!$J$6 -> 3960 | G16: =Equipe!$J$6 -> 3960 | H16: =Equipe!$J$6 -> 3960 | I16: =Equipe!$J$6 -> 3960 | J16: =Equipe!$J$6 -> 3960 | K16: =Equipe!$J$6 -> 3960 | L16: =Equipe!$J$6 -> 3960 | M16: =Equipe!$J$6 -> 3960 | N16: =Equipe!$J$6 -> 3960 | U16: =Equipe!$J$16 -> 4356 | V16: =Equipe!$J$16 -> 4356 | W16: =Equipe!$J$16 -> 4356 | X16: =Equipe!$J$16 -> 4356 | Y16: =Equipe!$J$16 -> 4356 | Z16: =Equipe!$J$16 -> 4356 | AA16: =Equipe!$J$16 -> 4356 | AB16: =Equipe!$J$16 -> 4356 | ... AF16: =Equipe!$J$16 -> 4356 | AH16: =Equipe!$J$26 -> 4791.6 | AI16: =Equipe!$J$26 -> 4791.6 | AJ16: =Equipe!$J$26 -> 4791.6 | AK16: =Equipe!$J$26 -> 4791.6 | AL16: =Equipe!$J$26 -> 4791.6 | AM16: =Equipe!$J$26 -> 4791.6 | AN16: =Equipe!$J$26 -> 4791.6 | AO16: =Equipe!$J$26 -> 4791.6 | ... AS16: =Equipe!$J$26 -> 4791.6 | AU16: =Equipe!$J$36 -> 5270.76 | AV16: =Equipe!$J$36 -> 5270.76 | AW16: =Equipe!$J$36 -> 5270.76 | AX16: =Equipe!$J$36 -> 5270.76 | AY16: =Equipe!$J$36 -> 5270.76 | AZ16: =Equipe!$J$36 -> 5270.76 | BA16: =Equipe!$J$36 -> 5270.76 | BB16: =Equipe!$J$36 -> 5270.76 | ... BF16: =Equipe!$J$36 -> 5270.76 | BH16: =Equipe!$J$46 -> 5797.836 | BI16: =Equipe!$J$46 -> 5797.836 | BJ16: =Equipe!$J$46 -> 5797.836 | BK16: =Equipe!$J$46 -> 5797.836 | BL16: =Equipe!$J$46 -> 5797.836 | BM16: =Equipe!$J$46 -> 5797.836 | BN16: =Equipe!$J$46 -> 5797.836 | BO16: =Equipe!$J$46 -> 5797.836 | ... BS16: =Equipe!$J$46 -> 5797.836 | BU16: =Equipe!$J$56 -> 6377.6196 | BV16: =Equipe!$J$56 -> 6377.6196 | BW16: =Equipe!$J$56 -> 6377.6196 | BX16: =Equipe!$J$56 -> 6377.6196 | BY16: =Equipe!$J$56 -> 6377.6196 | BZ16: =Equipe!$J$56 -> 6377.6196 | CA16: =Equipe!$J$56 -> 6377.6196 | CB16: =Equipe!$J$56 -> 6377.6196 | ... CF16: =Equipe!$J$56 -> 6377.6196
A17: 1.1.2 | B17: Funcionários Recepção | D17: 0 | E17: 0 | F17: =Equipe!$J$3 -> 0 | G17: =Equipe!$J$3 -> 0 | H17: =Equipe!$J$3 -> 0 | I17: =Equipe!$J$3 -> 0 | J17: =Equipe!$J$3 -> 0 | K17: =Equipe!$J$3 -> 0 | L17: =Equipe!$J$3 -> 0 | M17: =Equipe!$J$3 -> 0 | N17: =Equipe!$J$3 -> 0 | U17: =Equipe!$J$13 -> 0 | V17: =Equipe!$J$13 -> 0 | W17: =Equipe!$J$13 -> 0 | X17: =Equipe!$J$13 -> 0 | Y17: =Equipe!$J$13 -> 0 | Z17: =Equipe!$J$13 -> 0 | AA17: =Equipe!$J$13 -> 0 | AB17: =Equipe!$J$13 -> 0 | ... AF17: =Equipe!$J$13 -> 0 | AH17: =Equipe!$J$23 -> 0 | AI17: =Equipe!$J$23 -> 0 | AJ17: =Equipe!$J$23 -> 0 | AK17: =Equipe!$J$23 -> 0 | AL17: =Equipe!$J$23 -> 0 | AM17: =Equipe!$J$23 -> 0 | AN17: =Equipe!$J$23 -> 0 | AO17: =Equipe!$J$23 -> 0 | ... AS17: =Equipe!$J$23 -> 0 | AU17: =Equipe!$J$33 -> 0 | AV17: =Equipe!$J$33 -> 0 | AW17: =Equipe!$J$33 -> 0 | AX17: =Equipe!$J$33 -> 0 | AY17: =Equipe!$J$33 -> 0 | AZ17: =Equipe!$J$33 -> 0 | BA17: =Equipe!$J$33 -> 0 | BB17: =Equipe!$J$33 -> 0 | ... BF17: =Equipe!$J$33 -> 0 | BH17: =Equipe!$J$43 -> 0 | BI17: =Equipe!$J$43 -> 0 | BJ17: =Equipe!$J$43 -> 0 | BK17: =Equipe!$J$43 -> 0 | BL17: =Equipe!$J$43 -> 0 | BM17: =Equipe!$J$43 -> 0 | BN17: =Equipe!$J$43 -> 0 | BO17: =Equipe!$J$43 -> 0 | ... BS17: =Equipe!$J$43 -> 0 | BU17: =Equipe!$J$53 -> 0 | BV17: =Equipe!$J$53 -> 0 | BW17: =Equipe!$J$53 -> 0 | BX17: =Equipe!$J$53 -> 0 | BY17: =Equipe!$J$53 -> 0 | BZ17: =Equipe!$J$53 -> 0 | CA17: =Equipe!$J$53 -> 0 | CB17: =Equipe!$J$53 -> 0 | ... CF17: =Equipe!$J$53 -> 0
A18: 1.1.3 | B18: Funcionários Marketing | C18: =Equipe!$J$7 -> 0 | D18: =Equipe!$J$7 -> 0 | E18: =Equipe!$J$7 -> 0 | F18: =Equipe!$J$7 -> 0 | G18: =Equipe!$J$7 -> 0 | H18: =Equipe!$J$7 -> 0 | I18: =Equipe!$J$7 -> 0 | J18: =Equipe!$J$7 -> 0 | ... N18: =Equipe!$J$7 -> 0 | U18: =Equipe!$J$17 -> 0 | V18: =Equipe!$J$17 -> 0 | W18: =Equipe!$J$17 -> 0 | X18: =Equipe!$J$17 -> 0 | Y18: =Equipe!$J$17 -> 0 | Z18: =Equipe!$J$17 -> 0 | AA18: =Equipe!$J$17 -> 0 | AB18: =Equipe!$J$17 -> 0 | ... AF18: =Equipe!$J$17 -> 0 | AH18: =Equipe!$J$27 -> 0 | AI18: =Equipe!$J$27 -> 0 | AJ18: =Equipe!$J$27 -> 0 | AK18: =Equipe!$J$27 -> 0 | AL18: =Equipe!$J$27 -> 0 | AM18: =Equipe!$J$27 -> 0 | AN18: =Equipe!$J$27 -> 0 | AO18: =Equipe!$J$27 -> 0 | ... AS18: =Equipe!$J$27 -> 0 | AU18: =Equipe!$J$37 -> 0 | AV18: =Equipe!$J$37 -> 0 | AW18: =Equipe!$J$37 -> 0 | AX18: =Equipe!$J$37 -> 0 | AY18: =Equipe!$J$37 -> 0 | AZ18: =Equipe!$J$37 -> 0 | BA18: =Equipe!$J$37 -> 0 | BB18: =Equipe!$J$37 -> 0 | ... BF18: =Equipe!$J$37 -> 0 | BH18: =Equipe!$J$47 -> 0 | BI18: =Equipe!$J$47 -> 0 | BJ18: =Equipe!$J$47 -> 0 | BK18: =Equipe!$J$47 -> 0 | BL18: =Equipe!$J$47 -> 0 | BM18: =Equipe!$J$47 -> 0 | BN18: =Equipe!$J$47 -> 0 | BO18: =Equipe!$J$47 -> 0 | ... BS18: =Equipe!$J$47 -> 0 | BU18: =Equipe!$J$57 -> 0 | BV18: =Equipe!$J$57 -> 0 | BW18: =Equipe!$J$57 -> 0 | BX18: =Equipe!$J$57 -> 0 | BY18: =Equipe!$J$57 -> 0 | BZ18: =Equipe!$J$57 -> 0 | CA18: =Equipe!$J$57 -> 0 | CB18: =Equipe!$J$57 -> 0 | ... CF18: =Equipe!$J$57 -> 0
A19: 1.1.4 | B19: Atendimento Comercial | C19: =Equipe!$J$4 -> 0 | D19: =Equipe!$J$4 -> 0 | E19: =Equipe!$J$4 -> 0 | F19: =Equipe!$J$4 -> 0 | G19: =Equipe!$J$4 -> 0 | H19: =Equipe!$J$4 -> 0 | I19: =Equipe!$J$4 -> 0 | J19: =Equipe!$J$4 -> 0 | ... N19: =Equipe!$J$4 -> 0 | U19: =Equipe!$J$14 -> 0 | V19: =Equipe!$J$14 -> 0 | W19: =Equipe!$J$14 -> 0 | X19: =Equipe!$J$14 -> 0 | Y19: =Equipe!$J$14 -> 0 | Z19: =Equipe!$J$14 -> 0 | AA19: =Equipe!$J$14 -> 0 | AB19: =Equipe!$J$14 -> 0 | ... AF19: =Equipe!$J$14 -> 0 | AH19: =Equipe!$J$14 -> 0 | AI19: =Equipe!$J$14 -> 0 | AJ19: =Equipe!$J$14 -> 0 | AK19: =Equipe!$J$14 -> 0 | AL19: =Equipe!$J$14 -> 0 | AM19: =Equipe!$J$14 -> 0 | AN19: =Equipe!$J$14 -> 0 | AO19: =Equipe!$J$14 -> 0 | ... AS19: =Equipe!$J$14 -> 0 | AU19: =Equipe!$J$34 -> 0 | AV19: =Equipe!$J$34 -> 0 | AW19: =Equipe!$J$34 -> 0 | AX19: =Equipe!$J$34 -> 0 | AY19: =Equipe!$J$34 -> 0 | AZ19: =Equipe!$J$34 -> 0 | BA19: =Equipe!$J$34 -> 0 | BB19: =Equipe!$J$34 -> 0 | ... BF19: =Equipe!$J$34 -> 0 | BH19: =Equipe!$J$14 -> 0 | BI19: =Equipe!$J$14 -> 0 | BJ19: =Equipe!$J$14 -> 0 | BK19: =Equipe!$J$14 -> 0 | BL19: =Equipe!$J$14 -> 0 | BM19: =Equipe!$J$14 -> 0 | BN19: =Equipe!$J$14 -> 0 | BO19: =Equipe!$J$14 -> 0 | ... BS19: =Equipe!$J$14 -> 0 | BU19: =Equipe!$J$14 -> 0 | BV19: =Equipe!$J$14 -> 0 | BW19: =Equipe!$J$14 -> 0 | BX19: =Equipe!$J$14 -> 0 | BY19: =Equipe!$J$14 -> 0 | BZ19: =Equipe!$J$14 -> 0 | CA19: =Equipe!$J$14 -> 0 | CB19: =Equipe!$J$14 -> 0 | ... CF19: =Equipe!$J$14 -> 0
A20: 1.1.5 | B20: Funcionários Gerente | D20: 0 | E20: 0 | F20: =Equipe!$J$5 -> 0 | G20: =Equipe!$J$5 -> 0 | H20: =Equipe!$J$5 -> 0 | I20: =Equipe!$J$5 -> 0 | J20: =Equipe!$J$5 -> 0 | K20: =Equipe!$J$5 -> 0 | L20: =Equipe!$J$5 -> 0 | M20: =Equipe!$J$5 -> 0 | N20: =Equipe!$J$5 -> 0 | U20: =Equipe!$J$15 -> 0 | V20: =Equipe!$J$15 -> 0 | W20: =Equipe!$J$15 -> 0 | X20: =Equipe!$J$15 -> 0 | Y20: =Equipe!$J$15 -> 0 | Z20: =Equipe!$J$15 -> 0 | AA20: =Equipe!$J$15 -> 0 | AB20: =Equipe!$J$15 -> 0 | ... AF20: =Equipe!$J$15 -> 0 | AH20: =Equipe!$J$25 -> 0 | AI20: =Equipe!$J$25 -> 0 | AJ20: =Equipe!$J$25 -> 0 | AK20: =Equipe!$J$25 -> 0 | AL20: =Equipe!$J$25 -> 0 | AM20: =Equipe!$J$25 -> 0 | AN20: =Equipe!$J$25 -> 0 | AO20: =Equipe!$J$25 -> 0 | ... AS20: =Equipe!$J$25 -> 0 | AU20: =Equipe!$J$35 -> 0 | AV20: =Equipe!$J$35 -> 0 | AW20: =Equipe!$J$35 -> 0 | AX20: =Equipe!$J$35 -> 0 | AY20: =Equipe!$J$35 -> 0 | AZ20: =Equipe!$J$35 -> 0 | BA20: =Equipe!$J$35 -> 0 | BB20: =Equipe!$J$35 -> 0 | ... BF20: =Equipe!$J$35 -> 0 | BH20: =Equipe!$J$45 -> 0 | BI20: =Equipe!$J$45 -> 0 | BJ20: =Equipe!$J$45 -> 0 | BK20: =Equipe!$J$45 -> 0 | BL20: =Equipe!$J$45 -> 0 | BM20: =Equipe!$J$45 -> 0 | BN20: =Equipe!$J$45 -> 0 | BO20: =Equipe!$J$45 -> 0 | ... BS20: =Equipe!$J$45 -> 0 | BU20: =Equipe!$J$55 -> 0 | BV20: =Equipe!$J$55 -> 0 | BW20: =Equipe!$J$55 -> 0 | BX20: =Equipe!$J$55 -> 0 | BY20: =Equipe!$J$55 -> 0 | BZ20: =Equipe!$J$55 -> 0 | CA20: =Equipe!$J$55 -> 0 | CB20: =Equipe!$J$55 -> 0 | ... CF20: =Equipe!$J$55 -> 0
A21: 1.1.6 | B21: Educador Fisico | D21: 0 | E21: 0 | F21: =Equipe!$J$8 -> 0 | G21: =Equipe!$J$8 -> 0 | H21: =Equipe!$J$8 -> 0 | I21: =Equipe!$J$8 -> 0 | J21: =Equipe!$J$8 -> 0 | K21: =Equipe!$J$8 -> 0 | L21: =Equipe!$J$8 -> 0 | M21: =Equipe!$J$8 -> 0 | N21: =Equipe!$J$8 -> 0 | U21: =Equipe!$J$18 -> 0 | V21: =Equipe!$J$18 -> 0 | W21: =Equipe!$J$18 -> 0 | X21: =Equipe!$J$18 -> 0 | Y21: =Equipe!$J$18 -> 0 | Z21: =Equipe!$J$18 -> 0 | AA21: =Equipe!$J$18 -> 0 | AB21: =Equipe!$J$18 -> 0 | ... AF21: =Equipe!$J$18 -> 0 | AH21: =Equipe!$J$28 -> 0 | AI21: =Equipe!$J$28 -> 0 | AJ21: =Equipe!$J$28 -> 0 | AK21: =Equipe!$J$28 -> 0 | AL21: =Equipe!$J$28 -> 0 | AM21: =Equipe!$J$28 -> 0 | AN21: =Equipe!$J$28 -> 0 | AO21: =Equipe!$J$28 -> 0 | ... AS21: =Equipe!$J$28 -> 0 | AU21: =Equipe!$J$38 -> 0 | AV21: =Equipe!$J$38 -> 0 | AW21: =Equipe!$J$38 -> 0 | AX21: =Equipe!$J$38 -> 0 | AY21: =Equipe!$J$38 -> 0 | AZ21: =Equipe!$J$38 -> 0 | BA21: =Equipe!$J$38 -> 0 | BB21: =Equipe!$J$38 -> 0 | ... BF21: =Equipe!$J$38 -> 0 | BH21: =Equipe!$J$48 -> 0 | BI21: =Equipe!$J$48 -> 0 | BJ21: =Equipe!$J$48 -> 0 | BK21: =Equipe!$J$48 -> 0 | BL21: =Equipe!$J$48 -> 0 | BM21: =Equipe!$J$48 -> 0 | BN21: =Equipe!$J$48 -> 0 | BO21: =Equipe!$J$48 -> 0 | ... BS21: =Equipe!$J$48 -> 0 | BU21: =Equipe!$J$58 -> 0 | BV21: =Equipe!$J$58 -> 0 | BW21: =Equipe!$J$58 -> 0 | BX21: =Equipe!$J$58 -> 0 | BY21: =Equipe!$J$58 -> 0 | BZ21: =Equipe!$J$58 -> 0 | CA21: =Equipe!$J$58 -> 0 | CB21: =Equipe!$J$58 -> 0 | ... CF21: =Equipe!$J$58 -> 0
A22: 1.1.7 | B22: Pró-labore | D22: 0 | E22: 0 | F22: 0 | H22: =Equipe!J10 -> 0 | I22: =Equipe!J10 -> 0 | J22: =Equipe!J10 -> 0 | K22: =Equipe!J10 -> 0 | L22: =Equipe!J10 -> 0 | M22: =Equipe!J10 -> 0 | N22: =Equipe!$J$10 -> 0 | U22: =Equipe!$J$20 -> 0 | V22: =Equipe!$J$20 -> 0 | W22: =Equipe!$J$20 -> 0 | X22: =Equipe!$J$20 -> 0 | Y22: =Equipe!$J$20 -> 0 | Z22: =Equipe!$J$20 -> 0 | AA22: =Equipe!$J$20 -> 0 | AB22: =Equipe!$J$20 -> 0 | ... AF22: =Equipe!$J$20 -> 0 | AH22: =Equipe!$J$30 -> 0 | AI22: =Equipe!$J$30 -> 0 | AJ22: =Equipe!$J$30 -> 0 | AK22: =Equipe!$J$30 -> 0 | AL22: =Equipe!$J$30 -> 0 | AM22: =Equipe!$J$30 -> 0 | AN22: =Equipe!$J$30 -> 0 | AO22: =Equipe!$J$30 -> 0 | ... AS22: =Equipe!$J$30 -> 0 | AU22: =Equipe!$J$40 -> 0 | AV22: =Equipe!$J$40 -> 0 | AW22: =Equipe!$J$40 -> 0 | AX22: =Equipe!$J$40 -> 0 | AY22: =Equipe!$J$40 -> 0 | AZ22: =Equipe!$J$40 -> 0 | BA22: =Equipe!$J$40 -> 0 | BB22: =Equipe!$J$40 -> 0 | ... BF22: =Equipe!$J$40 -> 0 | BH22: =Equipe!$J$50 -> 0 | BI22: =Equipe!$J$50 -> 0 | BJ22: =Equipe!$J$50 -> 0 | BK22: =Equipe!$J$50 -> 0 | BL22: =Equipe!$J$50 -> 0 | BM22: =Equipe!$J$50 -> 0 | BN22: =Equipe!$J$50 -> 0 | BO22: =Equipe!$J$50 -> 0 | ... BS22: =Equipe!$J$50 -> 0 | BU22: =Equipe!$J$60 -> 0 | BV22: =Equipe!$J$60 -> 0 | BW22: =Equipe!$J$60 -> 0 | BX22: =Equipe!$J$60 -> 0 | BY22: =Equipe!$J$60 -> 0 | BZ22: =Equipe!$J$60 -> 0 | CA22: =Equipe!$J$60 -> 0 | CB22: =Equipe!$J$60 -> 0 | ... CF22: =Equipe!$J$60 -> 0
A23: 1.1.8 | B23: Encargos Sociais (FGTS, INSS) | D23: 0 | E23: 0 | F23: 0 | G23: 0 | H23: 0 | I23: 0 | J23: 0 | K23: 0 | L23: 0 | M23: 0 | N23: 0 | U23: 0 | V23: 0 | W23: 0 | X23: 0 | Y23: 0 | Z23: 0 | AA23: 0 | AB23: 0 | AC23: 0 | AD23: 0 | AE23: 0 | AF23: 0 | AH23: 0 | AI23: 0 | AJ23: 0 | AK23: 0 | AL23: 0 | AM23: 0 | AN23: 0 | AO23: 0 | AP23: 0 | AQ23: 0 | AR23: 0 | AS23: 0 | AU23: 0 | AV23: 0 | AW23: 0 | AX23: 0 | AY23: 0 | AZ23: 0 | BA23: 0 | BB23: 0 | BC23: 0 | BD23: 0 | BE23: 0 | BF23: 0 | BH23: 0 | BI23: 0 | BJ23: 0 | BK23: 0 | BL23: 0 | BM23: 0 | BN23: 0 | BO23: 0 | BP23: 0 | BQ23: 0 | BR23: 0 | BS23: 0 | BU23: 0 | BV23: 0 | BW23: 0 | BX23: 0 | BY23: 0 | BZ23: 0 | CA23: 0 | CB23: 0 | CC23: 0 | CD23: 0 | CE23: 0 | CF23: 0
A24: 1.1.9 | B24: Beneficios (VT, VR, Plano Saúde) | D24: 0 | E24: 0 | F24: 0 | G24: 0 | H24: 0 | I24: 0 | J24: 0 | K24: 0 | L24: 0 | M24: 0 | N24: 0 | U24: 0 | V24: 0 | W24: 0 | X24: 0 | Y24: 0 | Z24: 0 | AA24: 0 | AB24: 0 | AC24: 0 | AD24: 0 | AE24: 0 | AF24: 0 | AH24: 0 | AI24: 0 | AJ24: 0 | AK24: 0 | AL24: 0 | AM24: 0 | AN24: 0 | AO24: 0 | AP24: 0 | AQ24: 0 | AR24: 0 | AS24: 0 | AU24: 0 | AV24: 0 | AW24: 0 | AX24: 0 | AY24: 0 | AZ24: 0 | BA24: 0 | BB24: 0 | BC24: 0 | BD24: 0 | BE24: 0 | BF24: 0 | BH24: 0 | BI24: 0 | BJ24: 0 | BK24: 0 | BL24: 0 | BM24: 0 | BN24: 0 | BO24: 0 | BP24: 0 | BQ24: 0 | BR24: 0 | BS24: 0 | BU24: 0 | BV24: 0 | BW24: 0 | BX24: 0 | BY24: 0 | BZ24: 0 | CA24: 0 | CB24: 0 | CC24: 0 | CD24: 0 | CE24: 0 | CF24: 0
A25: 1.2 | B25: Despesas | C25: =SUM(C26:C29) -> 0 | D25: =SUM(D26:D29) -> 0 | E25: =SUM(E26:E29) -> 0 | F25: =SUM(F26:F29) -> 4754 | G25: =SUM(G26:G29) -> 4754 | H25: =SUM(H26:H29) -> 4754 | I25: =SUM(I26:I29) -> 4754 | J25: =SUM(J26:J29) -> 4754 | ... N25: =SUM(N26:N29) -> 4754 | U25: =SUM(U26:U29) -> 5300 | V25: =SUM(V26:V29) -> 5300 | W25: =SUM(W26:W29) -> 5300 | X25: =SUM(X26:X29) -> 5300 | Y25: =SUM(Y26:Y29) -> 5300 | Z25: =SUM(Z26:Z29) -> 5300 | AA25: =SUM(AA26:AA29) -> 5300 | AB25: =SUM(AB26:AB29) -> 5300 | ... AF25: =SUM(AF26:AF29) -> 5300 | AH25: =SUM(AH26:AH29) -> 5926.5 | AI25: =SUM(AI26:AI29) -> 5926.5 | AJ25: =SUM(AJ26:AJ29) -> 5926.5 | AK25: =SUM(AK26:AK29) -> 5926.5 | AL25: =SUM(AL26:AL29) -> 5926.5 | AM25: =SUM(AM26:AM29) -> 5926.5 | AN25: =SUM(AN26:AN29) -> 5926.5 | AO25: =SUM(AO26:AO29) -> 5926.5 | ... AS25: =SUM(AS26:AS29) -> 5926.5 | AU25: =SUM(AU26:AU29) -> 6375.15 | AV25: =SUM(AV26:AV29) -> 6375.15 | AW25: =SUM(AW26:AW29) -> 6375.15 | AX25: =SUM(AX26:AX29) -> 6375.15 | AY25: =SUM(AY26:AY29) -> 6375.15 | AZ25: =SUM(AZ26:AZ29) -> 6375.15 | BA25: =SUM(BA26:BA29) -> 6375.15 | BB25: =SUM(BB26:BB29) -> 6375.15 | ... BF25: =SUM(BF26:BF29) -> 6375.15 | BH25: =SUM(BH26:BH29) -> 6831.665 | BI25: =SUM(BI26:BI29) -> 6831.665 | BJ25: =SUM(BJ26:BJ29) -> 6831.665 | BK25: =SUM(BK26:BK29) -> 6831.665 | BL25: =SUM(BL26:BL29) -> 6831.665 | BM25: =SUM(BM26:BM29) -> 6831.665 | BN25: =SUM(BN26:BN29) -> 6831.665 | BO25: =SUM(BO26:BO29) -> 6831.665 | ... BS25: =SUM(BS26:BS29) -> 6831.665 | BU25: =SUM(BU26:BU29) -> 7296.8315 | BV25: =SUM(BV26:BV29) -> 7296.8315 | BW25: =SUM(BW26:BW29) -> 7296.8315 | BX25: =SUM(BX26:BX29) -> 7296.8315 | BY25: =SUM(BY26:BY29) -> 7296.8315 | BZ25: =SUM(BZ26:BZ29) -> 7296.8315 | CA25: =SUM(CA26:CA29) -> 7296.8315 | CB25: =SUM(CB26:CB29) -> 7296.8315 | ... CF25: =SUM(CF26:CF29) -> 7296.8315
A26: 1.2.1 | B26: Energia Elétrica | D26: 0 | E26: 0 | F26: ='Água e luz'!H3 -> 3648 | G26: =F26 -> 3648 | H26: =G26 -> 3648 | I26: =H26 -> 3648 | J26: =I26 -> 3648 | K26: =J26 -> 3648 | L26: =K26 -> 3648 | M26: =L26 -> 3648 | N26: =M26 -> 3648 | T26: 1.1 | U26: ='Água e luz'!H4 -> 3960 | V26: =U26 -> 3960 | W26: =V26 -> 3960 | X26: =W26 -> 3960 | Y26: =X26 -> 3960 | Z26: =Y26 -> 3960 | AA26: =Z26 -> 3960 | AB26: =AA26 -> 3960 | AC26: =AB26 -> 3960 | ... AF26: =AE26 -> 3960 | AG26: 1.1 | AH26: ='Água e luz'!H5 -> 4320 | AI26: =AH26 -> 4320 | AJ26: =AI26 -> 4320 | AK26: =AJ26 -> 4320 | AL26: =AK26 -> 4320 | AM26: =AL26 -> 4320 | AN26: =AM26 -> 4320 | AO26: =AN26 -> 4320 | AP26: =AO26 -> 4320 | ... AS26: =AR26 -> 4320 | AT26: 1.1 | AU26: ='Água e luz'!H6 -> 4560 | AV26: =AU26 -> 4560 | AW26: =AV26 -> 4560 | AX26: =AW26 -> 4560 | AY26: =AX26 -> 4560 | AZ26: =AY26 -> 4560 | BA26: =AZ26 -> 4560 | BB26: =BA26 -> 4560 | BC26: =BB26 -> 4560 | ... BF26: =BE26 -> 4560 | BG26: 1.1 | BH26: ='Água e luz'!H7 -> 4800 | BI26: =BH26 -> 4800 | BJ26: =BI26 -> 4800 | BK26: =BJ26 -> 4800 | BL26: =BK26 -> 4800 | BM26: =BL26 -> 4800 | BN26: =BM26 -> 4800 | BO26: =BN26 -> 4800 | BP26: =BO26 -> 4800 | ... BS26: =BR26 -> 4800 | BT26: 1.1 | BU26: ='Água e luz'!H8 -> 5040 | BV26: =BU26 -> 5040 | BW26: =BV26 -> 5040 | BX26: =BW26 -> 5040 | BY26: =BX26 -> 5040 | BZ26: =BY26 -> 5040 | CA26: =BZ26 -> 5040 | CB26: =CA26 -> 5040 | CC26: =CB26 -> 5040 | ... CF26: =CE26 -> 5040
A27: 1.2.2 | B27: Água | D27: 0 | E27: 0 | F27: ='Água e luz'!I3 -> 456 | G27: =F27 -> 456 | H27: =G27 -> 456 | I27: =H27 -> 456 | J27: =I27 -> 456 | K27: =J27 -> 456 | L27: =K27 -> 456 | M27: =L27 -> 456 | N27: =M27 -> 456 | T27: 1.1 | U27: ='Água e luz'!I4 -> 625 | V27: =U27 -> 625 | W27: =V27 -> 625 | X27: =W27 -> 625 | Y27: =X27 -> 625 | Z27: =Y27 -> 625 | AA27: =Z27 -> 625 | AB27: =AA27 -> 625 | AC27: =AB27 -> 625 | ... AF27: =AE27 -> 625 | AG27: 1.1 | AH27: ='Água e luz'!I5 -> 820 | AI27: =AH27 -> 820 | AJ27: =AI27 -> 820 | AK27: =AJ27 -> 820 | AL27: =AK27 -> 820 | AM27: =AL27 -> 820 | AN27: =AM27 -> 820 | AO27: =AN27 -> 820 | AP27: =AO27 -> 820 | ... AS27: =AR27 -> 820 | AT27: 1.1 | AU27: ='Água e luz'!I6 -> 950 | AV27: =AU27 -> 950 | AW27: =AV27 -> 950 | AX27: =AW27 -> 950 | AY27: =AX27 -> 950 | AZ27: =AY27 -> 950 | BA27: =AZ27 -> 950 | BB27: =BA27 -> 950 | BC27: =BB27 -> 950 | ... BF27: =BE27 -> 950 | BG27: 1.1 | BH27: ='Água e luz'!I7 -> 1080 | BI27: =BH27 -> 1080 | BJ27: =BI27 -> 1080 | BK27: =BJ27 -> 1080 | BL27: =BK27 -> 1080 | BM27: =BL27 -> 1080 | BN27: =BM27 -> 1080 | BO27: =BN27 -> 1080 | BP27: =BO27 -> 1080 | ... BS27: =BR27 -> 1080 | BT27: 1.1 | BU27: ='Água e luz'!I8 -> 1210 | BV27: =BU27 -> 1210 | BW27: =BV27 -> 1210 | BX27: =BW27 -> 1210 | BY27: =BX27 -> 1210 | BZ27: =BY27 -> 1210 | CA27: =BZ27 -> 1210 | CB27: =CA27 -> 1210 | CC27: =CB27 -> 1210 | ... CF27: =CE27 -> 1210
A28: 1.2.3 | B28: Diversos | D28: 0 | E28: 0 | F28: 500 | G28: 500 | H28: 500 | I28: 500 | J28: 500 | K28: 500 | L28: 500 | M28: 500 | N28: 500 | T28: 1.1 | U28: =N28*T28 -> 550 | V28: =U28 -> 550 | W28: =V28 -> 550 | X28: =W28 -> 550 | Y28: =X28 -> 550 | Z28: =Y28 -> 550 | AA28: =Z28 -> 550 | AB28: =AA28 -> 550 | AC28: =AB28 -> 550 | ... AF28: =AE28 -> 550 | AG28: 1.1 | AH28: =AF28*AG28 -> 605 | AI28: =AH28 -> 605 | AJ28: =AI28 -> 605 | AK28: =AJ28 -> 605 | AL28: =AK28 -> 605 | AM28: =AL28 -> 605 | AN28: =AM28 -> 605 | AO28: =AN28 -> 605 | AP28: =AO28 -> 605 | ... AS28: =AR28 -> 605 | AT28: 1.1 | AU28: =AS28*AT28 -> 665.5 | AV28: =AU28 -> 665.5 | AW28: =AV28 -> 665.5 | AX28: =AW28 -> 665.5 | AY28: =AX28 -> 665.5 | AZ28: =AY28 -> 665.5 | BA28: =AZ28 -> 665.5 | BB28: =BA28 -> 665.5 | BC28: =BB28 -> 665.5 | ... BF28: =BE28 -> 665.5 | BG28: 1.1 | BH28: =BF28*BG28 -> 732.05 | BI28: =BH28 -> 732.05 | BJ28: =BI28 -> 732.05 | BK28: =BJ28 -> 732.05 | BL28: =BK28 -> 732.05 | BM28: =BL28 -> 732.05 | BN28: =BM28 -> 732.05 | BO28: =BN28 -> 732.05 | BP28: =BO28 -> 732.05 | ... BS28: =BR28 -> 732.05 | BT28: 1.1 | BU28: =BS28*BT28 -> 805.255 | BV28: =BU28 -> 805.255 | BW28: =BV28 -> 805.255 | BX28: =BW28 -> 805.255 | BY28: =BX28 -> 805.255 | BZ28: =BY28 -> 805.255 | CA28: =BZ28 -> 805.255 | CB28: =CA28 -> 805.255 | CC28: =CB28 -> 805.255 | ... CF28: =CE28 -> 805.255
A29: 1.2.4 | B29: Telefone e Internet | D29: 0 | E29: 0 | F29: 150 | G29: 150 | H29: 150 | I29: 150 | J29: 150 | K29: 150 | L29: 150 | M29: 150 | N29: 150 | T29: 1.1 | U29: =N29*T29 -> 165 | V29: =U29 -> 165 | W29: =V29 -> 165 | X29: =W29 -> 165 | Y29: =X29 -> 165 | Z29: =Y29 -> 165 | AA29: =Z29 -> 165 | AB29: =AA29 -> 165 | AC29: =AB29 -> 165 | ... AF29: =AE29 -> 165 | AG29: 1.1 | AH29: =AF29*AG29 -> 181.5 | AI29: =AH29 -> 181.5 | AJ29: =AI29 -> 181.5 | AK29: =AJ29 -> 181.5 | AL29: =AK29 -> 181.5 | AM29: =AL29 -> 181.5 | AN29: =AM29 -> 181.5 | AO29: =AN29 -> 181.5 | AP29: =AO29 -> 181.5 | ... AS29: =AR29 -> 181.5 | AT29: 1.1 | AU29: =AS29*AT29 -> 199.65 | AV29: =AU29 -> 199.65 | AW29: =AV29 -> 199.65 | AX29: =AW29 -> 199.65 | AY29: =AX29 -> 199.65 | AZ29: =AY29 -> 199.65 | BA29: =AZ29 -> 199.65 | BB29: =BA29 -> 199.65 | BC29: =BB29 -> 199.65 | ... BF29: =BE29 -> 199.65 | BG29: 1.1 | BH29: =BF29*BG29 -> 219.615 | BI29: =BH29 -> 219.615 | BJ29: =BI29 -> 219.615 | BK29: =BJ29 -> 219.615 | BL29: =BK29 -> 219.615 | BM29: =BL29 -> 219.615 | BN29: =BM29 -> 219.615 | BO29: =BN29 -> 219.615 | BP29: =BO29 -> 219.615 | ... BS29: =BR29 -> 219.615 | BT29: 1.1 | BU29: =BS29*BT29 -> 241.5765 | BV29: =BU29 -> 241.5765 | BW29: =BV29 -> 241.5765 | BX29: =BW29 -> 241.5765 | BY29: =BX29 -> 241.5765 | BZ29: =BY29 -> 241.5765 | CA29: =BZ29 -> 241.5765 | CB29: =CA29 -> 241.5765 | CC29: =CB29 -> 241.5765 | ... CF29: =CE29 -> 241.5765
A30: 1.3 | B30: Equipamentos | C30: =SUM(C31:C32) -> 0 | D30: =SUM(D31:D32) -> 0 | E30: =SUM(E31:E32) -> 0 | F30: =SUM(F31:F32) -> 0 | G30: =SUM(G31:G32) -> 0 | H30: =SUM(H31:H32) -> 0 | I30: =SUM(I31:I32) -> 0 | J30: =SUM(J31:J32) -> 0 | ... N30: =SUM(N31:N32) -> 300 | U30: =SUM(U31:U32) -> 330 | V30: =SUM(V31:V32) -> 330 | W30: =SUM(W31:W32) -> 330 | X30: =SUM(X31:X32) -> 330 | Y30: =SUM(Y31:Y32) -> 330 | Z30: =SUM(Z31:Z32) -> 330 | AA30: =SUM(AA31:AA32) -> 330 | AB30: =SUM(AB31:AB32) -> 330 | ... AF30: =SUM(AF31:AF32) -> 330 | AH30: =SUM(AH31:AH32) -> 363 | AI30: =SUM(AI31:AI32) -> 363 | AJ30: =SUM(AJ31:AJ32) -> 363 | AK30: =SUM(AK31:AK32) -> 363 | AL30: =SUM(AL31:AL32) -> 363 | AM30: =SUM(AM31:AM32) -> 363 | AN30: =SUM(AN31:AN32) -> 363 | AO30: =SUM(AO31:AO32) -> 363 | ... AS30: =SUM(AS31:AS32) -> 363 | AU30: =SUM(AU31:AU32) -> 399.3 | AV30: =SUM(AV31:AV32) -> 399.3 | AW30: =SUM(AW31:AW32) -> 399.3 | AX30: =SUM(AX31:AX32) -> 399.3 | AY30: =SUM(AY31:AY32) -> 399.3 | AZ30: =SUM(AZ31:AZ32) -> 399.3 | BA30: =SUM(BA31:BA32) -> 399.3 | BB30: =SUM(BB31:BB32) -> 399.3 | ... BF30: =SUM(BF31:BF32) -> 399.3 | BH30: =SUM(BH31:BH32) -> 439.23 | BI30: =SUM(BI31:BI32) -> 439.23 | BJ30: =SUM(BJ31:BJ32) -> 439.23 | BK30: =SUM(BK31:BK32) -> 439.23 | BL30: =SUM(BL31:BL32) -> 439.23 | BM30: =SUM(BM31:BM32) -> 439.23 | BN30: =SUM(BN31:BN32) -> 439.23 | BO30: =SUM(BO31:BO32) -> 439.23 | ... BS30: =SUM(BS31:BS32) -> 439.23 | BU30: =SUM(BU31:BU32) -> 483.153 | BV30: =SUM(BV31:BV32) -> 483.153 | BW30: =SUM(BW31:BW32) -> 483.153 | BX30: =SUM(BX31:BX32) -> 483.153 | BY30: =SUM(BY31:BY32) -> 483.153 | BZ30: =SUM(BZ31:BZ32) -> 483.153 | CA30: =SUM(CA31:CA32) -> 483.153 | CB30: =SUM(CB31:CB32) -> 483.153 | ... CF30: =SUM(CF31:CF32) -> 483.153
A31: 1.3.1 | B31: Depreciação Equip. de Produção | D31: 0 | E31: 0 | F31: 0 | G31: 0 | H31: 0 | I31: 0 | J31: 0 | K31: 0 | L31: 0 | M31: 0 | N31: 0 | T31: 1.1 | U31: =N31*T31 -> 0 | V31: =U31 -> 0 | W31: 0 | X31: 0 | Y31: 0 | Z31: 0 | AA31: 0 | AB31: 0 | AC31: 0 | AD31: 0 | AE31: 0 | AF31: 0 | AG31: 1.1 | AH31: =AF31*AG31 -> 0 | AI31: =AH31 -> 0 | AJ31: =AI31 -> 0 | AK31: =AJ31 -> 0 | AL31: =AK31 -> 0 | AM31: =AL31 -> 0 | AN31: =AM31 -> 0 | AO31: =AN31 -> 0 | AP31: =AO31 -> 0 | ... AS31: =AR31 -> 0 | AT31: 1.1 | AU31: =AS31*AT31 -> 0 | AV31: =AU31 -> 0 | AW31: 0 | AX31: 0 | AY31: 0 | AZ31: 0 | BA31: 0 | BB31: 0 | BC31: 0 | BD31: 0 | BE31: 0 | BF31: 0 | BG31: 1.1 | BH31: =BF31*BG31 -> 0 | BI31: =BH31 -> 0 | BJ31: 0 | BK31: 0 | BL31: 0 | BM31: 0 | BN31: 0 | BO31: 0 | BP31: 0 | BQ31: 0 | BR31: 0 | BS31: 0 | BT31: 1.1 | BU31: =BS31*BT31 -> 0 | BV31: =BU31 -> 0 | BW31: 0 | BX31: 0 | BY31: 0 | BZ31: 0 | CA31: 0 | CB31: 0 | CC31: 0 | CD31: 0 | CE31: 0 | CF31: 0
A32: 1.3.2 | B32: Manuteção preventiva e corretiva | D32: 0 | E32: 0 | F32: 0 | G32: 0 | H32: 0 | I32: 0 | J32: 0 | K32: 0 | L32: 300 | M32: 300 | N32: 300 | T32: 1.1 | U32: =N32*T32 -> 330 | V32: =U32 -> 330 | W32: =V32 -> 330 | X32: =W32 -> 330 | Y32: =X32 -> 330 | Z32: =Y32 -> 330 | AA32: =Z32 -> 330 | AB32: =AA32 -> 330 | AC32: =AB32 -> 330 | ... AF32: =AE32 -> 330 | AG32: 1.1 | AH32: =AF32*AG32 -> 363 | AI32: =AH32 -> 363 | AJ32: =AI32 -> 363 | AK32: =AJ32 -> 363 | AL32: =AK32 -> 363 | AM32: =AL32 -> 363 | AN32: =AM32 -> 363 | AO32: =AN32 -> 363 | AP32: =AO32 -> 363 | ... AS32: =AR32 -> 363 | AT32: 1.1 | AU32: =AS32*AT32 -> 399.3 | AV32: =AU32 -> 399.3 | AW32: =AV32 -> 399.3 | AX32: =AW32 -> 399.3 | AY32: =AX32 -> 399.3 | AZ32: =AY32 -> 399.3 | BA32: =AZ32 -> 399.3 | BB32: =BA32 -> 399.3 | BC32: =BB32 -> 399.3 | ... BF32: =BE32 -> 399.3 | BG32: 1.1 | BH32: =BF32*BG32 -> 439.23 | BI32: =BH32 -> 439.23 | BJ32: =BI32 -> 439.23 | BK32: =BJ32 -> 439.23 | BL32: =BK32 -> 439.23 | BM32: =BL32 -> 439.23 | BN32: =BM32 -> 439.23 | BO32: =BN32 -> 439.23 | BP32: =BO32 -> 439.23 | ... BS32: =BR32 -> 439.23 | BT32: 1.1 | BU32: =BS32*BT32 -> 483.153 | BV32: =BU32 -> 483.153 | BW32: =BV32 -> 483.153 | BX32: =BW32 -> 483.153 | BY32: =BX32 -> 483.153 | BZ32: =BY32 -> 483.153 | CA32: =BZ32 -> 483.153 | CB32: =CA32 -> 483.153 | CC32: =CB32 -> 483.153 | ... CF32: =CE32 -> 483.153
A33: 1.4 | B33: Marketing e Publicidade | C33: =SUM(C34:C37) -> 0 | D33: =SUM(D34:D37) -> 0 | E33: =SUM(E34:E37) -> 0 | F33: =SUM(F34:F37) -> 0 | G33: =SUM(G34:G37) -> 0 | H33: =SUM(H34:H37) -> 0 | I33: =SUM(I34:I37) -> 0 | J33: =SUM(J34:J37) -> 0 | ... N33: =SUM(N34:N37) -> 0 | U33: =SUM(U34:U37) -> 0 | V33: =SUM(V34:V37) -> 0 | W33: =SUM(W34:W37) -> 0 | X33: =SUM(X34:X37) -> 0 | Y33: =SUM(Y34:Y37) -> 0 | Z33: =SUM(Z34:Z37) -> 0 | AA33: =SUM(AA34:AA37) -> 0 | AB33: =SUM(AB34:AB37) -> 0 | ... AF33: =SUM(AF34:AF37) -> 0 | AH33: =SUM(AH34:AH37) -> 0 | AI33: =SUM(AI34:AI37) -> 0 | AJ33: =SUM(AJ34:AJ37) -> 0 | AK33: =SUM(AK34:AK37) -> 0 | AL33: =SUM(AL34:AL37) -> 0 | AM33: =SUM(AM34:AM37) -> 0 | AN33: =SUM(AN34:AN37) -> 0 | AO33: =SUM(AO34:AO37) -> 0 | ... AS33: =SUM(AS34:AS37) -> 0 | AU33: =SUM(AU34:AU37) -> 0 | AV33: =SUM(AV34:AV37) -> 0 | AW33: =SUM(AW34:AW37) -> 0 | AX33: =SUM(AX34:AX37) -> 0 | AY33: =SUM(AY34:AY37) -> 0 | AZ33: =SUM(AZ34:AZ37) -> 0 | BA33: =SUM(BA34:BA37) -> 0 | BB33: =SUM(BB34:BB37) -> 0 | ... BF33: =SUM(BF34:BF37) -> 0 | BH33: =SUM(BH34:BH37) -> 0 | BI33: =SUM(BI34:BI37) -> 0 | BJ33: =SUM(BJ34:BJ37) -> 0 | BK33: =SUM(BK34:BK37) -> 0 | BL33: =SUM(BL34:BL37) -> 0 | BM33: =SUM(BM34:BM37) -> 0 | BN33: =SUM(BN34:BN37) -> 0 | BO33: =SUM(BO34:BO37) -> 0 | ... BS33: =SUM(BS34:BS37) -> 0 | BU33: =SUM(BU34:BU37) -> 0 | BV33: =SUM(BV34:BV37) -> 0 | BW33: =SUM(BW34:BW37) -> 0 | BX33: =SUM(BX34:BX37) -> 0 | BY33: =SUM(BY34:BY37) -> 0 | BZ33: =SUM(BZ34:BZ37) -> 0 | CA33: =SUM(CA34:CA37) -> 0 | CB33: =SUM(CB34:CB37) -> 0 | ... CF33: =SUM(CF34:CF37) -> 0
A34: 1.4.1 | B34: Material da Identidade Visual | E34: 0 | T34: 1.1 | U34: =N34*T34 -> 0 | V34: =U34 -> 0 | W34: =V34 -> 0 | X34: =W34 -> 0 | Y34: =X34 -> 0 | Z34: =Y34 -> 0 | AA34: =Z34 -> 0 | AB34: =AA34 -> 0 | AC34: =AB34 -> 0 | AD34: =AC34 -> 0 | AF34: =AE34 -> 0 | AG34: 1.1 | AH34: =AF34*AG34 -> 0 | AI34: =AH34 -> 0 | AJ34: =AI34 -> 0 | AK34: =AJ34 -> 0 | AL34: =AK34 -> 0 | AM34: =AL34 -> 0 | AN34: =AM34 -> 0 | AO34: =AN34 -> 0 | AP34: =AO34 -> 0 | ... AS34: =AR34 -> 0 | AT34: 1.1 | AU34: =AS34*AT34 -> 0 | AV34: =AU34 -> 0 | AW34: =AV34 -> 0 | AX34: =AW34 -> 0 | AY34: =AX34 -> 0 | AZ34: =AY34 -> 0 | BA34: =AZ34 -> 0 | BB34: =BA34 -> 0 | BC34: =BB34 -> 0 | ... BF34: =BE34 -> 0 | BG34: 1.1 | BH34: =BF34*BG34 -> 0 | BI34: =BH34 -> 0 | BJ34: =BI34 -> 0 | BK34: =BJ34 -> 0 | BL34: =BK34 -> 0 | BM34: =BL34 -> 0 | BN34: =BM34 -> 0 | BO34: =BN34 -> 0 | BP34: =BO34 -> 0 | ... BS34: =BR34 -> 0 | BT34: 1.1 | BU34: =BS34*BT34 -> 0 | BV34: =BU34 -> 0 | BW34: =BV34 -> 0 | BX34: =BW34 -> 0 | BY34: =BX34 -> 0 | BZ34: =BY34 -> 0 | CA34: =BZ34 -> 0 | CB34: =CA34 -> 0 | CC34: =CB34 -> 0 | ... CF34: =CE34 -> 0
A35: 1.4.2 | B35: Marketing Digital | D35: 0 | E35: 0 | T35: 1.1 | U35: =N35*T35 -> 0 | V35: =U35 -> 0 | W35: =V35 -> 0 | X35: =W35 -> 0 | Y35: =X35 -> 0 | Z35: =Y35 -> 0 | AA35: =Z35 -> 0 | AB35: =AA35 -> 0 | AC35: =AB35 -> 0 | AD35: =AC35 -> 0 | AF35: =AE35 -> 0 | AG35: 1.1 | AH35: =AF35*AG35 -> 0 | AI35: =AH35 -> 0 | AJ35: =AI35 -> 0 | AK35: =AJ35 -> 0 | AL35: =AK35 -> 0 | AM35: =AL35 -> 0 | AN35: =AM35 -> 0 | AO35: =AN35 -> 0 | AP35: =AO35 -> 0 | ... AS35: =AR35 -> 0 | AT35: 1.1 | AU35: =AS35*AT35 -> 0 | AV35: =AU35 -> 0 | AW35: =AV35 -> 0 | AX35: =AW35 -> 0 | AY35: =AX35 -> 0 | AZ35: =AY35 -> 0 | BA35: =AZ35 -> 0 | BB35: =BA35 -> 0 | BC35: =BB35 -> 0 | ... BF35: =BE35 -> 0 | BG35: 1.1 | BH35: =BF35*BG35 -> 0 | BI35: =BH35 -> 0 | BJ35: =BI35 -> 0 | BK35: =BJ35 -> 0 | BL35: =BK35 -> 0 | BM35: =BL35 -> 0 | BN35: =BM35 -> 0 | BO35: =BN35 -> 0 | BP35: =BO35 -> 0 | ... BS35: =BR35 -> 0 | BT35: 1.1 | BU35: =BS35*BT35 -> 0 | BV35: =BU35 -> 0 | BW35: =BV35 -> 0 | BX35: =BW35 -> 0 | BY35: =BX35 -> 0 | BZ35: =BY35 -> 0 | CA35: =BZ35 -> 0 | CB35: =CA35 -> 0 | CC35: =CB35 -> 0 | ... CF35: =CE35 -> 0
A36: 1.4.3 | B36: Material publicitário de Eventos | D36: 0 | E36: 0 | F36: 0 | G36: 0 | H36: 0 | I36: 0 | J36: 0 | K36: 0 | L36: 0 | M36: 0 | N36: 0 | T36: 1.1 | U36: =N36*T36 -> 0 | V36: =U36 -> 0 | W36: =V36 -> 0 | X36: =W36 -> 0 | Y36: =X36 -> 0 | Z36: =Y36 -> 0 | AA36: =Z36 -> 0 | AB36: =AA36 -> 0 | AC36: =AB36 -> 0 | ... AF36: =AE36 -> 0 | AG36: 1.1 | AH36: =AF36*AG36 -> 0 | AI36: =AH36 -> 0 | AJ36: =AI36 -> 0 | AK36: =AJ36 -> 0 | AL36: =AK36 -> 0 | AM36: =AL36 -> 0 | AN36: =AM36 -> 0 | AO36: =AN36 -> 0 | AP36: =AO36 -> 0 | ... AS36: =AR36 -> 0 | AT36: 1.1 | AU36: =AS36*AT36 -> 0 | AV36: =AU36 -> 0 | AW36: =AV36 -> 0 | AX36: =AW36 -> 0 | AY36: =AX36 -> 0 | AZ36: =AY36 -> 0 | BA36: =AZ36 -> 0 | BB36: =BA36 -> 0 | BC36: =BB36 -> 0 | ... BF36: =BE36 -> 0 | BG36: 1.1 | BH36: =BF36*BG36 -> 0 | BI36: =BH36 -> 0 | BJ36: =BI36 -> 0 | BK36: =BJ36 -> 0 | BL36: =BK36 -> 0 | BM36: =BL36 -> 0 | BN36: =BM36 -> 0 | BO36: =BN36 -> 0 | BP36: =BO36 -> 0 | ... BS36: =BR36 -> 0 | BT36: 1.1 | BU36: =BS36*BT36 -> 0 | BV36: =BU36 -> 0 | BW36: =BV36 -> 0 | BX36: =BW36 -> 0 | BY36: =BX36 -> 0 | BZ36: =BY36 -> 0 | CA36: =BZ36 -> 0 | CB36: =CA36 -> 0 | CC36: =CB36 -> 0 | ... CF36: =CE36 -> 0
A37: 1.4.4 | B37: Cortesias e Brindes | D37: 0 | E37: 0 | T37: 1.1 | U37: =N37*T37 -> 0 | V37: =U37 -> 0 | W37: =V37 -> 0 | X37: =W37 -> 0 | Y37: =X37 -> 0 | Z37: =Y37 -> 0 | AA37: =Z37 -> 0 | AB37: =AA37 -> 0 | AC37: =AB37 -> 0 | AD37: =AC37 -> 0 | AF37: =AE37 -> 0 | AG37: 1.1 | AH37: =AF37*AG37 -> 0 | AI37: =AH37 -> 0 | AJ37: =AI37 -> 0 | AK37: =AJ37 -> 0 | AL37: =AK37 -> 0 | AM37: =AL37 -> 0 | AN37: =AM37 -> 0 | AO37: =AN37 -> 0 | AP37: =AO37 -> 0 | ... AS37: =AR37 -> 0 | AT37: 1.1 | AU37: =AS37*AT37 -> 0 | AV37: =AU37 -> 0 | AW37: =AV37 -> 0 | AX37: =AW37 -> 0 | AY37: =AX37 -> 0 | AZ37: =AY37 -> 0 | BA37: =AZ37 -> 0 | BB37: =BA37 -> 0 | BC37: =BB37 -> 0 | ... BF37: =BE37 -> 0 | BG37: 1.1 | BH37: =BF37*BG37 -> 0 | BI37: =BH37 -> 0 | BJ37: =BI37 -> 0 | BK37: =BJ37 -> 0 | BL37: =BK37 -> 0 | BM37: =BL37 -> 0 | BN37: =BM37 -> 0 | BO37: =BN37 -> 0 | BP37: =BO37 -> 0 | ... BS37: =BR37 -> 0 | BT37: 1.1 | BU37: =BS37*BT37 -> 0 | BV37: =BU37 -> 0 | BW37: =BV37 -> 0 | BX37: =BW37 -> 0 | BY37: =BX37 -> 0 | BZ37: =BY37 -> 0 | CA37: =BZ37 -> 0 | CB37: =CA37 -> 0 | CC37: =CB37 -> 0 | ... CF37: =CE37 -> 0
A38: 1.5 | B38: Desp Administrativos | C38: =SUM(C39:C45) -> 0 | D38: =SUM(D39:D45) -> 0 | E38: =SUM(E39:E45) -> 0 | F38: =SUM(F39:F45) -> 600 | G38: =SUM(G39:G45) -> 600 | H38: =SUM(H39:H45) -> 600 | I38: =SUM(I39:I45) -> 600 | J38: =SUM(J39:J45) -> 600 | ... N38: =SUM(N39:N45) -> 600 | U38: =SUM(U39:U45) -> 660 | V38: =SUM(V39:V45) -> 660 | W38: =SUM(W39:W45) -> 660 | X38: =SUM(X39:X45) -> 660 | Y38: =SUM(Y39:Y45) -> 660 | Z38: =SUM(Z39:Z45) -> 660 | AA38: =SUM(AA39:AA45) -> 660 | AB38: =SUM(AB39:AB45) -> 660 | ... AF38: =SUM(AF39:AF45) -> 660 | AH38: =SUM(AH39:AH45) -> 726 | AI38: =SUM(AI39:AI45) -> 726 | AJ38: =SUM(AJ39:AJ45) -> 726 | AK38: =SUM(AK39:AK45) -> 726 | AL38: =SUM(AL39:AL45) -> 726 | AM38: =SUM(AM39:AM45) -> 726 | AN38: =SUM(AN39:AN45) -> 726 | AO38: =SUM(AO39:AO45) -> 726 | ... AS38: =SUM(AS39:AS45) -> 726 | AU38: =SUM(AU39:AU45) -> 798.6 | AV38: =SUM(AV39:AV45) -> 798.6 | AW38: =SUM(AW39:AW45) -> 798.6 | AX38: =SUM(AX39:AX45) -> 798.6 | AY38: =SUM(AY39:AY45) -> 798.6 | AZ38: =SUM(AZ39:AZ45) -> 798.6 | BA38: =SUM(BA39:BA45) -> 798.6 | BB38: =SUM(BB39:BB45) -> 798.6 | ... BF38: =SUM(BF39:BF45) -> 798.6 | BH38: =SUM(BH39:BH45) -> 878.46 | BI38: =SUM(BI39:BI45) -> 878.46 | BJ38: =SUM(BJ39:BJ45) -> 878.46 | BK38: =SUM(BK39:BK45) -> 878.46 | BL38: =SUM(BL39:BL45) -> 878.46 | BM38: =SUM(BM39:BM45) -> 878.46 | BN38: =SUM(BN39:BN45) -> 878.46 | BO38: =SUM(BO39:BO45) -> 878.46 | ... BS38: =SUM(BS39:BS45) -> 878.46 | BU38: =SUM(BU39:BU45) -> 966.306 | BV38: =SUM(BV39:BV45) -> 966.306 | BW38: =SUM(BW39:BW45) -> 966.306 | BX38: =SUM(BX39:BX45) -> 966.306 | BY38: =SUM(BY39:BY45) -> 966.306 | BZ38: =SUM(BZ39:BZ45) -> 966.306 | CA38: =SUM(CA39:CA45) -> 966.306 | CB38: =SUM(CB39:CB45) -> 966.306 | ... CF38: =SUM(CF39:CF45) -> 966.306
A39: 1.5.1 | B39: Material de Escritório | D39: 0 | E39: 0 | F39: 100 | G39: 100 | H39: 100 | I39: 100 | J39: 100 | K39: 100 | L39: 100 | M39: 100 | N39: 100 | T39: 1.1 | U39: =N39*T39 -> 110 | V39: =U39 -> 110 | W39: =V39 -> 110 | X39: =W39 -> 110 | Y39: =X39 -> 110 | Z39: =Y39 -> 110 | AA39: =Z39 -> 110 | AB39: =AA39 -> 110 | AC39: =AB39 -> 110 | ... AF39: =AE39 -> 110 | AG39: 1.1 | AH39: =AF39*AG39 -> 121 | AI39: =AH39 -> 121 | AJ39: =AI39 -> 121 | AK39: =AJ39 -> 121 | AL39: =AK39 -> 121 | AM39: =AL39 -> 121 | AN39: =AM39 -> 121 | AO39: =AN39 -> 121 | AP39: =AO39 -> 121 | ... AS39: =AR39 -> 121 | AT39: 1.1 | AU39: =AS39*AT39 -> 133.1 | AV39: =AU39 -> 133.1 | AW39: =AV39 -> 133.1 | AX39: =AW39 -> 133.1 | AY39: =AX39 -> 133.1 | AZ39: =AY39 -> 133.1 | BA39: =AZ39 -> 133.1 | BB39: =BA39 -> 133.1 | BC39: =BB39 -> 133.1 | ... BF39: =BE39 -> 133.1 | BG39: 1.1 | BH39: =BF39*BG39 -> 146.41 | BI39: =BH39 -> 146.41 | BJ39: =BI39 -> 146.41 | BK39: =BJ39 -> 146.41 | BL39: =BK39 -> 146.41 | BM39: =BL39 -> 146.41 | BN39: =BM39 -> 146.41 | BO39: =BN39 -> 146.41 | BP39: =BO39 -> 146.41 | ... BS39: =BR39 -> 146.41 | BT39: 1.1 | BU39: =BS39*BT39 -> 161.051 | BV39: =BU39 -> 161.051 | BW39: =BV39 -> 161.051 | BX39: =BW39 -> 161.051 | BY39: =BX39 -> 161.051 | BZ39: =BY39 -> 161.051 | CA39: =BZ39 -> 161.051 | CB39: =CA39 -> 161.051 | CC39: =CB39 -> 161.051 | ... CF39: =CE39 -> 161.051
A40: 1.5.2 | B40: Higiene, limpeza , reparos e manut. escritório | D40: 0 | E40: 0 | F40: 500 | G40: 500 | H40: 500 | I40: 500 | J40: 500 | K40: 500 | L40: 500 | M40: 500 | N40: 500 | T40: 1.1 | U40: =N40*T40 -> 550 | V40: =U40 -> 550 | W40: =V40 -> 550 | X40: =W40 -> 550 | Y40: =X40 -> 550 | Z40: =Y40 -> 550 | AA40: =Z40 -> 550 | AB40: =AA40 -> 550 | AC40: =AB40 -> 550 | ... AF40: =AE40 -> 550 | AG40: 1.1 | AH40: =AF40*AG40 -> 605 | AI40: =AH40 -> 605 | AJ40: =AI40 -> 605 | AK40: =AJ40 -> 605 | AL40: =AK40 -> 605 | AM40: =AL40 -> 605 | AN40: =AM40 -> 605 | AO40: =AN40 -> 605 | AP40: =AO40 -> 605 | ... AS40: =AR40 -> 605 | AT40: 1.1 | AU40: =AS40*AT40 -> 665.5 | AV40: =AU40 -> 665.5 | AW40: =AV40 -> 665.5 | AX40: =AW40 -> 665.5 | AY40: =AX40 -> 665.5 | AZ40: =AY40 -> 665.5 | BA40: =AZ40 -> 665.5 | BB40: =BA40 -> 665.5 | BC40: =BB40 -> 665.5 | ... BF40: =BE40 -> 665.5 | BG40: 1.1 | BH40: =BF40*BG40 -> 732.05 | BI40: =BH40 -> 732.05 | BJ40: =BI40 -> 732.05 | BK40: =BJ40 -> 732.05 | BL40: =BK40 -> 732.05 | BM40: =BL40 -> 732.05 | BN40: =BM40 -> 732.05 | BO40: =BN40 -> 732.05 | BP40: =BO40 -> 732.05 | ... BS40: =BR40 -> 732.05 | BT40: 1.1 | BU40: =BS40*BT40 -> 805.255 | BV40: =BU40 -> 805.255 | BW40: =BV40 -> 805.255 | BX40: =BW40 -> 805.255 | BY40: =BX40 -> 805.255 | BZ40: =BY40 -> 805.255 | CA40: =BZ40 -> 805.255 | CB40: =CA40 -> 805.255 | CC40: =CB40 -> 805.255 | ... CF40: =CE40 -> 805.255
A41: 1.5.3 | B41: Software de Gestão | D41: 0 | E41: 0 | F41: 0 | G41: 0 | H41: 0 | I41: 0 | J41: 0 | K41: 0 | L41: 0 | M41: 0 | N41: 0 | T41: 1.1 | U41: =N41*T41 -> 0 | V41: =U41 -> 0 | W41: =V41 -> 0 | X41: =W41 -> 0 | Y41: =X41 -> 0 | Z41: =Y41 -> 0 | AA41: =Z41 -> 0 | AB41: =AA41 -> 0 | AC41: =AB41 -> 0 | ... AF41: =AE41 -> 0 | AG41: 1.1 | AH41: =AF41*AG41 -> 0 | AI41: =AH41 -> 0 | AJ41: =AI41 -> 0 | AK41: =AJ41 -> 0 | AL41: =AK41 -> 0 | AM41: =AL41 -> 0 | AN41: =AM41 -> 0 | AO41: =AN41 -> 0 | AP41: =AO41 -> 0 | ... AS41: =AR41 -> 0 | AT41: 1.1 | AU41: =AS41*AT41 -> 0 | AV41: =AU41 -> 0 | AW41: =AV41 -> 0 | AX41: =AW41 -> 0 | AY41: =AX41 -> 0 | AZ41: =AY41 -> 0 | BA41: =AZ41 -> 0 | BB41: =BA41 -> 0 | BC41: =BB41 -> 0 | ... BF41: =BE41 -> 0 | BG41: 1.1 | BH41: =BF41*BG41 -> 0 | BI41: =BH41 -> 0 | BJ41: =BI41 -> 0 | BK41: =BJ41 -> 0 | BL41: =BK41 -> 0 | BM41: =BL41 -> 0 | BN41: =BM41 -> 0 | BO41: =BN41 -> 0 | BP41: =BO41 -> 0 | ... BS41: =BR41 -> 0 | BT41: 1.1 | BU41: =BS41*BT41 -> 0 | BV41: =BU41 -> 0 | BW41: =BV41 -> 0 | BX41: =BW41 -> 0 | BY41: =BX41 -> 0 | BZ41: =BY41 -> 0 | CA41: =BZ41 -> 0 | CB41: =CA41 -> 0 | CC41: =CB41 -> 0 | ... CF41: =CE41 -> 0
A42: 1.5.4 | B42: Jurídico | D42: 0 | E42: 0 | F42: 0 | G42: 0 | H42: 0 | I42: 0 | J42: 0 | K42: 0 | L42: 0 | M42: 0 | N42: 0 | T42: 1.1 | U42: =N42*T42 -> 0 | V42: =U42 -> 0 | W42: =V42 -> 0 | X42: =W42 -> 0 | Y42: =X42 -> 0 | Z42: =Y42 -> 0 | AA42: =Z42 -> 0 | AB42: =AA42 -> 0 | AC42: =AB42 -> 0 | ... AF42: =AE42 -> 0 | AG42: 1.1 | AH42: =AF42*AG42 -> 0 | AI42: =AH42 -> 0 | AJ42: =AI42 -> 0 | AK42: =AJ42 -> 0 | AL42: =AK42 -> 0 | AM42: =AL42 -> 0 | AN42: =AM42 -> 0 | AO42: =AN42 -> 0 | AP42: =AO42 -> 0 | ... AS42: =AR42 -> 0 | AT42: 1.1 | AU42: =AS42*AT42 -> 0 | AV42: =AU42 -> 0 | AW42: =AV42 -> 0 | AX42: =AW42 -> 0 | AY42: =AX42 -> 0 | AZ42: =AY42 -> 0 | BA42: =AZ42 -> 0 | BB42: =BA42 -> 0 | BC42: =BB42 -> 0 | ... BF42: =BE42 -> 0 | BG42: 1.1 | BH42: =BF42*BG42 -> 0 | BI42: =BH42 -> 0 | BJ42: =BI42 -> 0 | BK42: =BJ42 -> 0 | BL42: =BK42 -> 0 | BM42: =BL42 -> 0 | BN42: =BM42 -> 0 | BO42: =BN42 -> 0 | BP42: =BO42 -> 0 | ... BS42: =BR42 -> 0 | BT42: 1.1 | BU42: =BS42*BT42 -> 0 | BV42: =BU42 -> 0 | BW42: =BV42 -> 0 | BX42: =BW42 -> 0 | BY42: =BX42 -> 0 | BZ42: =BY42 -> 0 | CA42: =BZ42 -> 0 | CB42: =CA42 -> 0 | CC42: =CB42 -> 0 | ... CF42: =CE42 -> 0
A43: 1.5.5 | B43: Contabilidade | T43: 1.1 | U43: =N43*T43 -> 0 | V43: =U43 -> 0 | W43: =V43 -> 0 | X43: =W43 -> 0 | Y43: =X43 -> 0 | Z43: =Y43 -> 0 | AA43: =Z43 -> 0 | AB43: =AA43 -> 0 | AC43: =AB43 -> 0 | ... AF43: =AE43 -> 0 | AG43: 1.1 | AH43: =AF43*AG43 -> 0 | AI43: =AH43 -> 0 | AJ43: =AI43 -> 0 | AK43: =AJ43 -> 0 | AL43: =AK43 -> 0 | AM43: =AL43 -> 0 | AN43: =AM43 -> 0 | AO43: =AN43 -> 0 | AP43: =AO43 -> 0 | ... AS43: =AR43 -> 0 | AT43: 1.1 | AU43: =AS43*AT43 -> 0 | AV43: =AU43 -> 0 | AW43: =AV43 -> 0 | AX43: =AW43 -> 0 | AY43: =AX43 -> 0 | AZ43: =AY43 -> 0 | BA43: =AZ43 -> 0 | BB43: =BA43 -> 0 | BC43: =BB43 -> 0 | ... BF43: =BE43 -> 0 | BG43: 1.1 | BH43: =BF43*BG43 -> 0 | BI43: =BH43 -> 0 | BJ43: =BI43 -> 0 | BK43: =BJ43 -> 0 | BL43: =BK43 -> 0 | BM43: =BL43 -> 0 | BN43: =BM43 -> 0 | BO43: =BN43 -> 0 | BP43: =BO43 -> 0 | ... BS43: =BR43 -> 0 | BT43: 1.1 | BU43: =BS43*BT43 -> 0 | BV43: =BU43 -> 0 | BW43: =BV43 -> 0 | BX43: =BW43 -> 0 | BY43: =BX43 -> 0 | BZ43: =BY43 -> 0 | CA43: =BZ43 -> 0 | CB43: =CA43 -> 0 | CC43: =CB43 -> 0 | ... CF43: =CE43 -> 0
...

Sheet Custo investimento 
A1: Investimento - Unidade 8
A2: Equipamentos | D2: =Financiamento!C7+Financiamento!C8 -> 472410.26 | I2: Runway (meses) | J2: 3
A3: Projeto arquiteto | D3: =Financiamento!C10 -> 28000 | I3: Caixa necessário | J3: =J2*J4 -> 86395.639
A4: Reforma | D4: 250000 | I4: Burn rate médio mensal | J4: =AVERAGE(Orçamento!C10:N10) -> 28798.546
A5: Automação Ar Cond. | D5: 20000
A6: Caixa 12 meses | D6: =J3+J9 -> 195134.95
A7: Total | D7: =SUM(D2:E6) -> 965545.21
I8: Período (meses) | J8: 9
B9: Origem do custo financeiro | I9: Caixa necessário | J9: =-(J8*J10) -> 108739.31
I10: Resultado médio mens. | J10: =AVERAGE(Orçamento!F5:N5) -> -12082.146
B11: Máquinas (FINAME) | D11: =D2 -> 472410.26
B12: Taxa de juros FINAME | D12: 0.011
B14: Obra + projeto + automação | D14: =D3+D4+D5 -> 298000
B15: Taxa de juros Obra | D15: 0.018
B17: Capital de giro (Breakeven) | D17: =D6 -> 195134.95
B18: Taxa de juros capital de giro | D18: =2.2% -> 0.022
B20: Fração das máquinas no CAPEX | D20: =D11/$D$7 -> 0.48926788
B21: Fração das obras no CAPEX | D21: =D14/$D$7 -> 0.30863392
B22: Fração do capital de giro no CAPEX | D22: =D17/$D$7 -> 0.2020982
B24: Taxa média de juros sobre o CAPEX | C24: a.m | D24: =D20*D12 + D21*D15 + D22*D18 -> 0.015383518
B26: Prazo médio de pagamentos (6 anos) | C26: Meses | D26: 72
B27: Custo financeiro mensal (simulado) | D27: =$D$7*$D$24 -> 14853.482
B28: Custo financeiro total do período | D28: =D27*D26 -> 1069450.7
B30: Resultado líquido projetado da unidade | D30: =Orçamento!CG5 -> 1722060
B31: Resultado após custo do capital | D31: =D30-D28 -> 652609.33

Sheet Financiamento
A1: Imóvel | B1: Aluguel (0,85%) | C1: M2 | D1: R$ M2 | E1: R$ Total | F1: Parcela | G1: Entrada 30% | H1: Finan. Imóvel
B2: 19000 | C2: 250 | D2: 10000 | E2: =C2*D2 -> 2500000 | F2: =F29 -> 41083.254 | G2: =E2*30% -> 750000 | H2: =E2-G2 -> 1750000
A3: Reforma Imóvel | D3: 500 | E3: =D3*C2 -> 125000
A5: Equipamentos | B5: =SUM(B6:B9) -> 3 | C5: R$ Unit | D5: Total | E5: Entrada % | F5: Entrada R$ | G5: Saldo a Pagar | H5: parcelas
B6: 0 | C6: 0 | D6: =C6*B6 -> 0 | E6: 0.3 | F6: =E6*D6 -> 0 | G6: =D6-F6 -> 0
B7: 1 | C7: ='Orçamento máquinas'!W40 -> 411358.66 | D7: =C7*B7 -> 411358.66 | E7: 0.3 | F7: =E7*D7 -> 123407.6 | G7: =D7-F7 -> 287951.06 | H7: =D29 -> 23995.922
B8: 1 | C8: 61051.6 | D8: =C8*B8 -> 61051.6 | E8: 0.3 | F8: =E8*D8 -> 18315.48 | G8: =D8-F8 -> 42736.12 | H8: =E29 -> 3561.3433
